Workbook

Sheet 읽는 방법
A1: 미국 50개사 ROIC vs WACC 10% — 읽는 방법
A2: 무엇을 담았는지
A3: 질문 | B3: ROIC가 자본비용(WACC)보다 높은지, 그게 10년간 꾸준했는지
A4: WACC | B4: 전 종목 10% 고정 — 지시사항. 기업별로 다르게 잡으면 ROIC 비교가 아니라 베타 비교가 되므로 같은 문턱을 적용했습니다.
A5: 대상 | B5: 50개 미국 상장사, 기업별 최근 10개 회계연도 (FY2016~FY2026 범위). 결산월이 달라 같은 창을 강제하지 않았습니다.
A6: 자료 기준일 | B6: 2026-10-29 — 이 날짜에 SEC에서 받은 공시 기준입니다. 최신 회계연도는 FY2026.
A7: 자료 출처 | B7: SEC XBRL companyfacts API. 1차 조사가 공시 본문을 읽은 것과 달리 이번 조사는 태그 데이터를 직접 받았습니다 — 같은 정의, 다른 경로. 두 결과가 어긋나면 한쪽이 틀렸다는 뜻이고, '구 조사 대조' 시트가 어느 쪽인지 가립니다.
A9: ROIC를 어떻게 계산했는지
A10: 분자 NOPAT | B10: 영업이익 × (1 − 실효세율). 실효세율 = 법인세비용 ÷ 세전이익, 5%~40%로 제한.
A11: 분모 투하자본 | B11: 자기자본(비지배지분 포함) + 이자부채입금 − 현금 및 단기투자자산. 2007년 주주서한의 '사업 운영에 필요한 자본' 기준으로, 국채 포트폴리오는 사업 자본이 아니므로 뺍니다.
A12: 분모 평균 | B12: 기초·기말 평균. 단 어느 한쪽이 0 이하인 해는 평균이 0 근처로 내려가 비율이 폭발하므로 기말값 단독 사용.
A13: 금융업 | B13: SIC 6000~6799은 ROIC 미산출. 은행에게 차입은 자금조달이 아니라 원재료여서, 자기자본+차입금−현금은 아무것도 측정하지 않습니다.
A15: 믿을 수 있는 정도
A16: HIGH | B16: 기업이 보고한 영업이익 소계를 그대로 사용 (332개 연도), 또는 손익계산서 항목을 쌓아 세전이익으로 역검증 통과.
A17: MEDIUM | B17: 항목을 쌓아 만든 소계가 세전이익과 5% 이내로 맞은 경우.
A18: LOW | B18: 영업이익 소계를 아예 보고하지 않아 세전이익에서 거꾸로 추정한 경우 (릴리·머크·J&J·IBM·엑슨·셰브론·GE). 두 가지 추정 방식을 모두 계산해 10% 문턱 판정이 일치하는지 '계산 명세' 시트에 기록했습니다.
A19: 분모가 작은 해 | B19: 아리스타·램리서치처럼 현금이 자기자본을 거의 상계해 순투하자본이 매출의 10% 미만이 되는 해는 노란색. 비율은 민감해지지만 10% 문턱 판정은 유효.
A21: 검증
A22: 자동 검사 | B22: verify_roic.py에서 9,867건 통과. 항등식(투하자본·NOPAT·ROIC·평균 규칙), 트립와이어(차감 현금 ≤ 유동자산, 차입금 ≤ 총부채), 공시 원문에서 손으로 읽은 앵커 19건.
A23: 변이 검정 | B23: 값을 고의로 훼손한 10가지 시나리오 전부 탐지. 틀린 데이터에서도 통과하는 검사는 검사가 아닙니다.
A25: 1차 조사에서 바로잡은 것
A26: 대조 결과 | B26: 380개 기업-연도 중 221건은 1%p 이내 일치, 159건 불일치, 7건은 10% 문턱 판정까지 바뀜.
A27: 가장 큰 원인 | B27: 1차 조사가 공시된 장기차입금을 누락한 27개 기업-연도. 오라클 10년, 코카콜라 7년, 브로드컴 4년, 비자 3년. 오라클 FY2024 ROIC가 761%로 나온 이유입니다.
A28: 정정 범위 | B28: 319개 기업-연도의 ROIC·영업이익·세율·투하자본을 교체. 원본은 analysis.json.pre-roic-correction에 보존.
A29: 가치평가 파급 | B29: 순현금 입력값까지 어긋난 기업 5곳을 '정정 내역' 시트에 기록. 오라클은 시가총액의 24%에 해당하는 오차라 DCF 결론이 바뀔 수 있지만, 가치평가 재계산은 이번 작업 범위가 아니어서 표시만 했습니다.
A31: 기업 이름 | B31: 표에는 한글명과 티커만 적었습니다. 영문 정식 명칭과 SEC 등록명은 '기업 목록' 시트에 있고, '계산 명세' 시트 마지막 열에도 등록명이 있습니다.
A33: 수식 | B33: 파생 셀은 전부 같은 통합문서 안의 셀을 참조하는 수식입니다. '계산 명세' 시트의 공시 입력값만 바꾸면 모든 시트가 따라 바뀝니다. 수식이 아닌 값은 공시에서 가져온 원자료뿐입니다.

Sheet 기업 목록
A1: 기업 목록 — 티커 · 한글명 · 영문 정식 명칭
A2: SEC가 반환하는 이름은 등록명(COSTCO WHOLESALE CORP /NEW, APPLIED MATERIALS INC /DE 등)이라 표에 그대로 쓰지 않았습니다. 등록명은 '계산 명세' 시트 마지막 열에 그대로 남겨두었습니다.
A3: 티커 | B3: 한글명 | C3: 영문 정식 명칭 | D3: SEC 등록명 | E3: 구분 | F3: 비고
A4: ANET | B4: 아리스타 네트웍스 | C4: Arista Networks | D4: Arista Networks, Inc. | E4: ROIC 순위 대상 | F4: —
A5: NVDA | B5: 엔비디아 | C5: NVIDIA | D5: NVIDIA CORP | E5: ROIC 순위 대상 | F5: 1월 결산 — 본문의 회계연도 표기 참고
A6: MA | B6: 마스터카드 | C6: Mastercard | D6: Mastercard Inc | E6: ROIC 순위 대상 | F6: —
A7: AAPL | B7: 애플 | C7: Apple | D7: Apple Inc. | E7: ROIC 순위 대상 | F7: —
A8: MSFT | B8: 마이크로소프트 | C8: Microsoft | D8: MICROSOFT CORP | E8: ROIC 순위 대상 | F8: —
A9: LRCX | B9: 램리서치 | C9: Lam Research | D9: LAM RESEARCH CORP | E9: ROIC 순위 대상 | F9: —
A10: PM | B10: 필립모리스 인터내셔널 | C10: Philip Morris International | D10: Philip Morris International Inc. | E10: ROIC 순위 대상 | F10: —
A11: KLAC | B11: KLA | C11: KLA | D11: KLA CORP | E11: ROIC 순위 대상 | F11: 2019년까지 사명은 KLA-Tencor
A12: TXN | B12: 텍사스 인스트루먼츠 | C12: Texas Instruments | D12: TEXAS INSTRUMENTS INC | E12: ROIC 순위 대상 | F12: —
A13: META | B13: 메타 플랫폼스 | C13: Meta Platforms | D13: Meta Platforms, Inc. | E13: ROIC 순위 대상 | F13: 2021년까지 사명은 Facebook
A14: HD | B14: 홈디포 | C14: Home Depot | D14: HOME DEPOT, INC. | E14: ROIC 순위 대상 | F14: —
... A53: C | B53: 씨티그룹 | C53: Citigroup | D53: CITIGROUP INC | E53: 금융업 — ROIC 미산출 | F53: —

Sheet 계산 명세
A1: 기업 | B1: 티커 | C1: 회계연도 | D1: 결산일 | E1: 매출 | F1: 영업이익 | G1: 산출 경로 | H1: 신뢰도 | I1: 실효세율 | J1: NOPAT | K1: 자기자본 | L1: 이자부차입금 | M1: 현금+단기투자 | N1: 투하자본 | O1: 직전 투하자본 | P1: 평균 투하자본 | Q1: 평균 산정 | R1: ROIC | S1: ROIC−10% | T1: 분모/매출 | U1: 대안 추정 ROIC | V1: 문턱 판정 일치 | W1: 상태 | X1: SEC 등록명
A2: 엔비디아 | B2: NVDA | C2: 2015 | D2: 2016-01-31 | E2: 5010000000 | F2: 747000000 | G2: reported | H2: HIGH | I2: 0.17362046 | J2: =IF(F2="","",F2*(1-I2)) -> 6.1730552e+08 | K2: 4469000000 | L2: 0 | M2: 5037000000 | N2: =IF(COUNT(K2:M2)<3,"",K2+L2-M2) -> -568000000 | O2: — | P2: — | Q2: — | R2: — | S2: — | T2: — | U2: — | V2: — | W2: 다음 해 평균 투하자본의 기초값으로만 사용 (보고 기간 밖 — 자체 비율은 계산하지 않음) | X2: NVIDIA CORP
A3: 엔비디아 | B3: NVDA | C3: 2016 | D3: 2017-01-29 | E3: 6910000000 | F3: 1934000000 | G3: reported | H3: HIGH | I3: 0.12545932 | J3: =IF(F3="","",F3*(1-I3)) -> 1.6913617e+09 | K3: 5762000000 | L3: 1983000000 | M3: 6798000000 | N3: =IF(COUNT(K3:M3)<3,"",K3+L3-M3) -> 947000000 | O3: =N2 -> -568000000 | P3: =IF(N3="","",IF(OR(O3="",O3<=0,N3<=0),N3,(N3+O3)/2)) -> 947000000 | Q3: 기말 단독 (기초 또는 기말 자본이 0 이하) | R3: =IF(OR(P3="",P3<=0),"",J3/P3) -> 1.7860208 | S3: =IF(R3="","",R3-0.1) -> 1.6860208 | T3: =IF(OR(P3="",E3=0,E3=""),"",P3/E3) -> 0.13704776 | U3: — | V3: — | W3: OK | X3: NVIDIA CORP
A4: 엔비디아 | B4: NVDA | C4: 2017 | D4: 2018-01-28 | E4: 9714000000 | F4: 3210000000 | G4: reported | H4: HIGH | I4: 0.05 | J4: =IF(F4="","",F4*(1-I4)) -> 3049500000 | K4: 7471000000 | L4: 1985000000 | M4: 7108000000 | N4: =IF(COUNT(K4:M4)<3,"",K4+L4-M4) -> 2348000000 | O4: =N3 -> 947000000 | P4: =IF(N4="","",IF(OR(O4="",O4<=0,N4<=0),N4,(N4+O4)/2)) -> 1647500000 | Q4: 기초·기말 평균 | R4: =IF(OR(P4="",P4<=0),"",J4/P4) -> 1.8509863 | S4: =IF(R4="","",R4-0.1) -> 1.7509863 | T4: =IF(OR(P4="",E4=0,E4=""),"",P4/E4) -> 0.16960058 | U4: — | V4: — | W4: OK | X4: NVIDIA CORP
A5: 엔비디아 | B5: NVDA | C5: 2018 | D5: 2019-01-27 | E5: 11716000000 | F5: 3804000000 | G5: reported | H5: HIGH | I5: 0.05 | J5: =IF(F5="","",F5*(1-I5)) -> 3613800000 | K5: 9342000000 | L5: 1988000000 | M5: 7422000000 | N5: =IF(COUNT(K5:M5)<3,"",K5+L5-M5) -> 3908000000 | O5: =N4 -> 2348000000 | P5: =IF(N5="","",IF(OR(O5="",O5<=0,N5<=0),N5,(N5+O5)/2)) -> 3128000000 | Q5: 기초·기말 평균 | R5: =IF(OR(P5="",P5<=0),"",J5/P5) -> 1.1553069 | S5: =IF(R5="","",R5-0.1) -> 1.0553069 | T5: =IF(OR(P5="",E5=0,E5=""),"",P5/E5) -> 0.26698532 | U5: — | V5: — | W5: OK | X5: NVIDIA CORP
A6: 엔비디아 | B6: NVDA | C6: 2019 | D6: 2020-01-26 | E6: 10918000000 | F6: 2846000000 | G6: reported | H6: HIGH | I6: 0.058585859 | J6: =IF(F6="","",F6*(1-I6)) -> 2.6792646e+09 | K6: 12204000000 | L6: 1991000000 | M6: 10897000000 | N6: =IF(COUNT(K6:M6)<3,"",K6+L6-M6) -> 3298000000 | O6: =N5 -> 3908000000 | P6: =IF(N6="","",IF(OR(O6="",O6<=0,N6<=0),N6,(N6+O6)/2)) -> 3603000000 | Q6: 기초·기말 평균 | R6: =IF(OR(P6="",P6<=0),"",J6/P6) -> 0.7436205 | S6: =IF(R6="","",R6-0.1) -> 0.6436205 | T6: =IF(OR(P6="",E6=0,E6=""),"",P6/E6) -> 0.3300055 | U6: — | V6: — | W6: OK | X6: NVIDIA CORP
A7: 엔비디아 | B7: NVDA | C7: 2020 | D7: 2021-01-31 | E7: 16675000000 | F7: 4532000000 | G7: reported | H7: HIGH | I7: 0.05 | J7: =IF(F7="","",F7*(1-I7)) -> 4305400000 | K7: 16893000000 | L7: 6963000000 | M7: 11561000000 | N7: =IF(COUNT(K7:M7)<3,"",K7+L7-M7) -> 12295000000 | O7: =N6 -> 3298000000 | P7: =IF(N7="","",IF(OR(O7="",O7<=0,N7<=0),N7,(N7+O7)/2)) -> 7796500000 | Q7: 기초·기말 평균 | R7: =IF(OR(P7="",P7<=0),"",J7/P7) -> 0.55222215 | S7: =IF(R7="","",R7-0.1) -> 0.45222215 | T7: =IF(OR(P7="",E7=0,E7=""),"",P7/E7) -> 0.46755622 | U7: — | V7: — | W7: OK | X7: NVIDIA CORP
A8: 엔비디아 | B8: NVDA | C8: 2021 | D8: 2022-01-30 | E8: 26914000000 | F8: 10041000000 | G8: reported | H8: HIGH | I8: 0.05 | J8: =IF(F8="","",F8*(1-I8)) -> 9538950000 | K8: 26612000000 | L8: 10946000000 | M8: 21208000000 | N8: =IF(COUNT(K8:M8)<3,"",K8+L8-M8) -> 16350000000 | O8: =N7 -> 12295000000 | P8: =IF(N8="","",IF(OR(O8="",O8<=0,N8<=0),N8,(N8+O8)/2)) -> 14322500000 | Q8: 기초·기말 평균 | R8: =IF(OR(P8="",P8<=0),"",J8/P8) -> 0.66601152 | S8: =IF(R8="","",R8-0.1) -> 0.56601152 | T8: =IF(OR(P8="",E8=0,E8=""),"",P8/E8) -> 0.53215798 | U8: — | V8: — | W8: OK | X8: NVIDIA CORP
A9: 엔비디아 | B9: NVDA | C9: 2022 | D9: 2023-01-29 | E9: 26974000000 | F9: 4224000000 | G9: reported | H9: HIGH | I9: 0.05 | J9: =IF(F9="","",F9*(1-I9)) -> 4012800000 | K9: 22101000000 | L9: 10953000000 | M9: 13296000000 | N9: =IF(COUNT(K9:M9)<3,"",K9+L9-M9) -> 19758000000 | O9: =N8 -> 16350000000 | P9: =IF(N9="","",IF(OR(O9="",O9<=0,N9<=0),N9,(N9+O9)/2)) -> 18054000000 | Q9: 기초·기말 평균 | R9: =IF(OR(P9="",P9<=0),"",J9/P9) -> 0.22226653 | S9: =IF(R9="","",R9-0.1) -> 0.12226653 | T9: =IF(OR(P9="",E9=0,E9=""),"",P9/E9) -> 0.66931119 | U9: — | V9: — | W9: OK | X9: NVIDIA CORP
A10: 엔비디아 | B10: NVDA | C10: 2023 | D10: 2024-01-28 | E10: 60922000000 | F10: 32972000000 | G10: reported | H10: HIGH | I10: 0.11999527 | J10: =IF(F10="","",F10*(1-I10)) -> 2.9015516e+10 | K10: 42978000000 | L10: 9709000000 | M10: 25984000000 | N10: =IF(COUNT(K10:M10)<3,"",K10+L10-M10) -> 26703000000 | O10: =N9 -> 19758000000 | P10: =IF(N10="","",IF(OR(O10="",O10<=0,N10<=0),N10,(N10+O10)/2)) -> 23230500000 | Q10: 기초·기말 평균 | R10: =IF(OR(P10="",P10<=0),"",J10/P10) -> 1.2490268 | S10: =IF(R10="","",R10-0.1) -> 1.1490268 | T10: =IF(OR(P10="",E10=0,E10=""),"",P10/E10) -> 0.38131545 | U10: — | V10: — | W10: OK | X10: NVIDIA CORP
A11: 엔비디아 | B11: NVDA | C11: 2024 | D11: 2025-01-26 | E11: 130497000000 | F11: 81453000000 | G11: reported | H11: HIGH | I11: 0.13264942 | J11: =IF(F11="","",F11*(1-I11)) -> 7.0648307e+10 | K11: 79327000000 | L11: 8463000000 | M11: 43210000000 | N11: =IF(COUNT(K11:M11)<3,"",K11+L11-M11) -> 44580000000 | O11: =N10 -> 26703000000 | P11: =IF(N11="","",IF(OR(O11="",O11<=0,N11<=0),N11,(N11+O11)/2)) -> 35641500000 | Q11: 기초·기말 평균 | R11: =IF(OR(P11="",P11<=0),"",J11/P11) -> 1.9821923 | S11: =IF(R11="","",R11-0.1) -> 1.8821923 | T11: =IF(OR(P11="",E11=0,E11=""),"",P11/E11) -> 0.27312122 | U11: — | V11: — | W11: OK | X11: NVIDIA CORP
A12: 엔비디아 | B12: NVDA | C12: 2025 | D12: 2026-01-25 | E12: 215938000000 | F12: 130387000000 | G12: reported | H12: HIGH | I12: 0.15117002 | J12: =IF(F12="","",F12*(1-I12)) -> 1.1067639e+11 | K12: 157293000000 | L12: 8468000000 | M12: 10605000000 | N12: =IF(COUNT(K12:M12)<3,"",K12+L12-M12) -> 155156000000 | O12: =N11 -> 44580000000 | P12: =IF(N12="","",IF(OR(O12="",O12<=0,N12<=0),N12,(N12+O12)/2)) -> 99868000000 | Q12: 기초·기말 평균 | R12: =IF(OR(P12="",P12<=0),"",J12/P12) -> 1.1082268 | S12: =IF(R12="","",R12-0.1) -> 1.0082268 | T12: =IF(OR(P12="",E12=0,E12=""),"",P12/E12) -> 0.4624846 | U12: — | V12: — | W12: OK | X12: NVIDIA CORP
A13: 애플 | B13: AAPL | C13: 2015 | D13: 2015-09-26 | E13: 233715000000 | F13: 71230000000 | G13: reported | H13: HIGH | I13: 0.26368338 | J13: =IF(F13="","",F13*(1-I13)) -> 5.2447833e+10 | K13: 119355000000 | L13: 64328000000 | M13: 41601000000 | N13: =IF(COUNT(K13:M13)<3,"",K13+L13-M13) -> 142082000000 | O13: — | P13: — | Q13: — | R13: — | S13: — | T13: — | U13: — | V13: — | W13: 다음 해 평균 투하자본의 기초값으로만 사용 (보고 기간 밖 — 자체 비율은 계산하지 않음) | X13: Apple Inc.
A14: 애플 | B14: AAPL | C14: 2016 | D14: 2016-09-24 | E14: 215639000000 | F14: 60024000000 | G14: reported | H14: HIGH | I14: 0.25557257 | J14: =IF(F14="","",F14*(1-I14)) -> 4.4683512e+10 | K14: 128249000000 | L14: 87032000000 | M14: 67155000000 | N14: =IF(COUNT(K14:M14)<3,"",K14+L14-M14) -> 148126000000 | O14: =N13 -> 142082000000 | P14: =IF(N14="","",IF(OR(O14="",O14<=0,N14<=0),N14,(N14+O14)/2)) -> 145104000000 | Q14: 기초·기말 평균 | R14: =IF(OR(P14="",P14<=0),"",J14/P14) -> 0.30794128 | S14: =IF(R14="","",R14-0.1) -> 0.20794128 | T14: =IF(OR(P14="",E14=0,E14=""),"",P14/E14) -> 0.6729024 | U14: — | V14: — | W14: OK | X14: Apple Inc.
A15: 애플 | B15: AAPL | C15: 2017 | D15: 2017-09-30 | E15: 229234000000 | F15: 61344000000 | G15: reported | H15: HIGH | I15: 0.24556476 | J15: =IF(F15="","",F15*(1-I15)) -> 4.6280075e+10 | K15: 134047000000 | L15: 115680000000 | M15: 74181000000 | N15: =IF(COUNT(K15:M15)<3,"",K15+L15-M15) -> 175546000000 | O15: =N14 -> 148126000000 | P15: =IF(N15="","",IF(OR(O15="",O15<=0,N15<=0),N15,(N15+O15)/2)) -> 161836000000 | Q15: 기초·기말 평균 | R15: =IF(OR(P15="",P15<=0),"",J15/P15) -> 0.28596898 | S15: =IF(R15="","",R15-0.1) -> 0.18596898 | T15: =IF(OR(P15="",E15=0,E15=""),"",P15/E15) -> 0.70598602 | U15: — | V15: — | W15: OK | X15: Apple Inc.
A16: 애플 | B16: AAPL | C16: 2018 | D16: 2018-09-29 | E16: 265595000000 | F16: 70898000000 | G16: reported | H16: HIGH | I16: 0.18342181 | J16: =IF(F16="","",F16*(1-I16)) -> 5.7893761e+10 | K16: 107147000000 | L16: 114483000000 | M16: 66301000000 | N16: =IF(COUNT(K16:M16)<3,"",K16+L16-M16) -> 155329000000 | O16: =N15 -> 175546000000 | P16: =IF(N16="","",IF(OR(O16="",O16<=0,N16<=0),N16,(N16+O16)/2)) -> 165437500000 | Q16: 기초·기말 평균 | R16: =IF(OR(P16="",P16<=0),"",J16/P16) -> 0.3499434 | S16: =IF(R16="","",R16-0.1) -> 0.2499434 | T16: =IF(OR(P16="",E16=0,E16=""),"",P16/E16) -> 0.62289388 | U16: — | V16: — | W16: OK | X16: Apple Inc.
A17: 애플 | B17: AAPL | C17: 2019 | D17: 2019-09-28 | E17: 260174000000 | F17: 63930000000 | G17: reported | H17: HIGH | I17: 0.15943837 | J17: =IF(F17="","",F17*(1-I17)) -> 5.3737105e+10 | K17: 90488000000 | L17: 108047000000 | M17: 100557000000 | N17: =IF(COUNT(K17:M17)<3,"",K17+L17-M17) -> 97978000000 | O17: =N16 -> 155329000000 | P17: =IF(N17="","",IF(OR(O17="",O17<=0,N17<=0),N17,(N17+O17)/2)) -> 126653500000 | Q17: 기초·기말 평균 | R17: =IF(OR(P17="",P17<=0),"",J17/P17) -> 0.42428441 | S17: =IF(R17="","",R17-0.1) -> 0.32428441 | T17: =IF(OR(P17="",E17=0,E17=""),"",P17/E17) -> 0.48680306 | U17: — | V17: — | W17: OK | X17: Apple Inc.
A18: 애플 | B18: AAPL | C18: 2020 | D18: 2020-09-26 | E18: 274515000000 | F18: 66288000000 | G18: reported | H18: HIGH | I18: 0.14428165 | J18: =IF(F18="","",F18*(1-I18)) -> 5.6723858e+10 | K18: 65339000000 | L18: 112436000000 | M18: 90943000000 | N18: =IF(COUNT(K18:M18)<3,"",K18+L18-M18) -> 86832000000 | O18: =N17 -> 97978000000 | P18: =IF(N18="","",IF(OR(O18="",O18<=0,N18<=0),N18,(N18+O18)/2)) -> 92405000000 | Q18: 기초·기말 평균 | R18: =IF(OR(P18="",P18<=0),"",J18/P18) -> 0.61386135 | S18: =IF(R18="","",R18-0.1) -> 0.51386135 | T18: =IF(OR(P18="",E18=0,E18=""),"",P18/E18) -> 0.33661184 | U18: — | V18: — | W18: OK | X18: Apple Inc.
A19: 애플 | B19: AAPL | C19: 2021 | D19: 2021-09-25 | E19: 365817000000 | F19: 108949000000 | G19: reported | H19: HIGH | I19: 0.13302261 | J19: =IF(F19="","",F19*(1-I19)) -> 9.445632e+10 | K19: 63090000000 | L19: 124719000000 | M19: 62639000000 | N19: =IF(COUNT(K19:M19)<3,"",K19+L19-M19) -> 125170000000 | O19: =N18 -> 86832000000 | P19: =IF(N19="","",IF(OR(O19="",O19<=0,N19<=0),N19,(N19+O19)/2)) -> 106001000000 | Q19: 기초·기말 평균 | R19: =IF(OR(P19="",P19<=0),"",J19/P19) -> 0.89108895 | S19: =IF(R19="","",R19-0.1) -> 0.79108895 | T19: =IF(OR(P19="",E19=0,E19=""),"",P19/E19) -> 0.2897651 | U19: — | V19: — | W19: OK | X19: Apple Inc.
A20: 애플 | B20: AAPL | C20: 2022 | D20: 2022-09-24 | E20: 394328000000 | F20: 119437000000 | G20: reported | H20: HIGH | I20: 0.16204462 | J20: =IF(F20="","",F20*(1-I20)) -> 1.0008288e+11 | K20: 50672000000 | L20: 120069000000 | M20: 48304000000 | N20: =IF(COUNT(K20:M20)<3,"",K20+L20-M20) -> 122437000000 | O20: =N19 -> 125170000000 | P20: =IF(N20="","",IF(OR(O20="",O20<=0,N20<=0),N20,(N20+O20)/2)) -> 123803500000 | Q20: 기초·기말 평균 | R20: =IF(OR(P20="",P20<=0),"",J20/P20) -> 0.80840103 | S20: =IF(R20="","",R20-0.1) -> 0.70840103 | T20: =IF(OR(P20="",E20=0,E20=""),"",P20/E20) -> 0.31396071 | U20: — | V20: — | W20: OK | X20: Apple Inc.
A21: 애플 | B21: AAPL | C21: 2023 | D21: 2023-09-30 | E21: 383285000000 | F21: 114301000000 | G21: reported | H21: HIGH | I21: 0.14719174 | J21: =IF(F21="","",F21*(1-I21)) -> 9.7476837e+10 | K21: 62146000000 | L21: 111088000000 | M21: 61555000000 | N21: =IF(COUNT(K21:M21)<3,"",K21+L21-M21) -> 111679000000 | O21: =N20 -> 122437000000 | P21: =IF(N21="","",IF(OR(O21="",O21<=0,N21<=0),N21,(N21+O21)/2)) -> 117058000000 | Q21: 기초·기말 평균 | R21: =IF(OR(P21="",P21<=0),"",J21/P21) -> 0.83272255 | S21: =IF(R21="","",R21-0.1) -> 0.73272255 | T21: =IF(OR(P21="",E21=0,E21=""),"",P21/E21) -> 0.3054072 | U21: — | V21: — | W21: OK | X21: Apple Inc.
A22: 애플 | B22: AAPL | C22: 2024 | D22: 2024-09-28 | E22: 391035000000 | F22: 123216000000 | G22: reported | H22: HIGH | I22: 0.24091185 | J22: =IF(F22="","",F22*(1-I22)) -> 9.3531805e+10 | K22: 56950000000 | L22: 106629000000 | M22: 65171000000 | N22: =IF(COUNT(K22:M22)<3,"",K22+L22-M22) -> 98408000000 | O22: =N21 -> 111679000000 | P22: =IF(N22="","",IF(OR(O22="",O22<=0,N22<=0),N22,(N22+O22)/2)) -> 105043500000 | Q22: 기초·기말 평균 | R22: =IF(OR(P22="",P22<=0),"",J22/P22) -> 0.89041021 | S22: =IF(R22="","",R22-0.1) -> 0.79041021 | T22: =IF(OR(P22="",E22=0,E22=""),"",P22/E22) -> 0.26862941 | U22: — | V22: — | W22: OK | X22: Apple Inc.
A23: 애플 | B23: AAPL | C23: 2025 | D23: 2025-09-27 | E23: 416161000000 | F23: 133050000000 | G23: reported | H23: HIGH | I23: 0.15610002 | J23: =IF(F23="","",F23*(1-I23)) -> 1.1228089e+11 | K23: 73733000000 | L23: 98657000000 | M23: 54697000000 | N23: =IF(COUNT(K23:M23)<3,"",K23+L23-M23) -> 117693000000 | O23: =N22 -> 98408000000 | P23: =IF(N23="","",IF(OR(O23="",O23<=0,N23<=0),N23,(N23+O23)/2)) -> 108050500000 | Q23: 기초·기말 평균 | R23: =IF(OR(P23="",P23<=0),"",J23/P23) -> 1.039152 | S23: =IF(R23="","",R23-0.1) -> 0.93915199 | T23: =IF(OR(P23="",E23=0,E23=""),"",P23/E23) -> 0.25963629 | U23: — | V23: — | W23: OK | X23: Apple Inc.
A24: 알파벳 | B24: GOOG | C24: 2015 | D24: 2015-12-31 | E24: 74989000000 | F24: 19360000000 | G24: reported | H24: HIGH | I24: 0.16808305 | J24: =IF(F24="","",F24*(1-I24)) -> 1.6105912e+10 | K24: 120331000000 | L24: 5220000000 | M24: 73066000000 | N24: =IF(COUNT(K24:M24)<3,"",K24+L24-M24) -> 52485000000 | O24: — | P24: — | Q24: — | R24: — | S24: — | T24: — | U24: — | V24: — | W24: 다음 해 평균 투하자본의 기초값으로만 사용 (보고 기간 밖 — 자체 비율은 계산하지 않음) | X24: Alphabet Inc.
A25: 알파벳 | B25: GOOG | C25: 2016 | D25: 2016-12-31 | E25: 90272000000 | F25: 23716000000 | G25: reported | H25: HIGH | I25: 0.19345756 | J25: =IF(F25="","",F25*(1-I25)) -> 1.9127961e+10 | K25: 139036000000 | L25: 3935000000 | M25: 86333000000 | N25: =IF(COUNT(K25:M25)<3,"",K25+L25-M25) -> 56638000000 | O25: =N24 -> 52485000000 | P25: =IF(N25="","",IF(OR(O25="",O25<=0,N25<=0),N25,(N25+O25)/2)) -> 54561500000 | Q25: 기초·기말 평균 | R25: =IF(OR(P25="",P25<=0),"",J25/P25) -> 0.35057615 | S25: =IF(R25="","",R25-0.1) -> 0.25057615 | T25: =IF(OR(P25="",E25=0,E25=""),"",P25/E25) -> 0.60441222 | U25: — | V25: — | W25: OK | X25: Alphabet Inc.
A26: 알파벳 | B26: GOOG | C26: 2017 | D26: 2017-12-31 | E26: 110855000000 | F26: 26178000000 | G26: reported | H26: HIGH | I26: 0.4 | J26: =IF(F26="","",F26*(1-I26)) -> 15706800000 | K26: 152502000000 | L26: 3943000000 | M26: 101871000000 | N26: =IF(COUNT(K26:M26)<3,"",K26+L26-M26) -> 54574000000 | O26: =N25 -> 56638000000 | P26: =IF(N26="","",IF(OR(O26="",O26<=0,N26<=0),N26,(N26+O26)/2)) -> 55606000000 | Q26: 기초·기말 평균 | R26: =IF(OR(P26="",P26<=0),"",J26/P26) -> 0.28246592 | S26: =IF(R26="","",R26-0.1) -> 0.18246592 | T26: =IF(OR(P26="",E26=0,E26=""),"",P26/E26) -> 0.50161021 | U26: — | V26: — | W26: OK | X26: Alphabet Inc.
A27: 알파벳 | B27: GOOG | C27: 2018 | D27: 2018-12-31 | E27: 136819000000 | F27: 27524000000 | G27: reported | H27: HIGH | I27: 0.11964025 | J27: =IF(F27="","",F27*(1-I27)) -> 2.4231022e+10 | K27: 177628000000 | L27: 3950000000 | M27: 109140000000 | N27: =IF(COUNT(K27:M27)<3,"",K27+L27-M27) -> 72438000000 | O27: =N26 -> 54574000000 | P27: =IF(N27="","",IF(OR(O27="",O27<=0,N27<=0),N27,(N27+O27)/2)) -> 63506000000 | Q27: 기초·기말 평균 | R27: =IF(OR(P27="",P27<=0),"",J27/P27) -> 0.38155484 | S27: =IF(R27="","",R27-0.1) -> 0.28155484 | T27: =IF(OR(P27="",E27=0,E27=""),"",P27/E27) -> 0.46416068 | U27: — | V27: — | W27: OK | X27: Alphabet Inc.
A28: 알파벳 | B28: GOOG | C28: 2019 | D28: 2019-12-31 | E28: 161857000000 | F28: 34231000000 | G28: reported | H28: HIGH | I28: 0.13329968 | J28: =IF(F28="","",F28*(1-I28)) -> 2.9668018e+10 | K28: 201442000000 | L28: 3958000000 | M28: 119675000000 | N28: =IF(COUNT(K28:M28)<3,"",K28+L28-M28) -> 85725000000 | O28: =N27 -> 72438000000 | P28: =IF(N28="","",IF(OR(O28="",O28<=0,N28<=0),N28,(N28+O28)/2)) -> 79081500000 | Q28: 기초·기말 평균 | R28: =IF(OR(P28="",P28<=0),"",J28/P28) -> 0.37515751 | S28: =IF(R28="","",R28-0.1) -> 0.27515751 | T28: =IF(OR(P28="",E28=0,E28=""),"",P28/E28) -> 0.48858869 | U28: — | V28: — | W28: OK | X28: Alphabet Inc.
A29: 알파벳 | B29: GOOG | C29: 2020 | D29: 2020-12-31 | E29: 182527000000 | F29: 41224000000 | G29: reported | H29: HIGH | I29: 0.16249324 | J29: =IF(F29="","",F29*(1-I29)) -> 3.4525379e+10 | K29: 222544000000 | L29: 14931000000 | M29: 136694000000 | N29: =IF(COUNT(K29:M29)<3,"",K29+L29-M29) -> 100781000000 | O29: =N28 -> 85725000000 | P29: =IF(N29="","",IF(OR(O29="",O29<=0,N29<=0),N29,(N29+O29)/2)) -> 93253000000 | Q29: 기초·기말 평균 | R29: =IF(OR(P29="",P29<=0),"",J29/P29) -> 0.37023344 | S29: =IF(R29="","",R29-0.1) -> 0.27023344 | T29: =IF(OR(P29="",E29=0,E29=""),"",P29/E29) -> 0.51089976 | U29: — | V29: — | W29: OK | X29: Alphabet Inc.
A30: 알파벳 | B30: GOOG | C30: 2021 | D30: 2021-12-31 | E30: 257637000000 | F30: 78714000000 | G30: reported | H30: HIGH | I30: 0.16202306 | J30: =IF(F30="","",F30*(1-I30)) -> 6.5960517e+10 | K30: 251635000000 | L30: 14817000000 | M30: 139649000000 | N30: =IF(COUNT(K30:M30)<3,"",K30+L30-M30) -> 126803000000 | O30: =N29 -> 100781000000 | P30: =IF(N30="","",IF(OR(O30="",O30<=0,N30<=0),N30,(N30+O30)/2)) -> 113792000000 | Q30: 기초·기말 평균 | R30: =IF(OR(P30="",P30<=0),"",J30/P30) -> 0.57965865 | S30: =IF(R30="","",R30-0.1) -> 0.47965865 | T30: =IF(OR(P30="",E30=0,E30=""),"",P30/E30) -> 0.44167569 | U30: — | V30: — | W30: OK | X30: Alphabet Inc.
A31: 알파벳 | B31: GOOG | C31: 2022 | D31: 2022-12-31 | E31: 282836000000 | F31: 74842000000 | G31: reported | H31: HIGH | I31: 0.15920817 | J31: =IF(F31="","",F31*(1-I31)) -> 6.2926543e+10 | K31: 256144000000 | L31: 14701000000 | M31: 113762000000 | N31: =IF(COUNT(K31:M31)<3,"",K31+L31-M31) -> 157083000000 | O31: =N30 -> 126803000000 | P31: =IF(N31="","",IF(OR(O31="",O31<=0,N31<=0),N31,(N31+O31)/2)) -> 141943000000 | Q31: 기초·기말 평균 | R31: =IF(OR(P31="",P31<=0),"",J31/P31) -> 0.44332262 | S31: =IF(R31="","",R31-0.1) -> 0.34332262 | T31: =IF(OR(P31="",E31=0,E31=""),"",P31/E31) -> 0.5018562 | U31: — | V31: — | W31: OK | X31: Alphabet Inc.
A32: 알파벳 | B32: GOOG | C32: 2023 | D32: 2023-12-31 | E32: 307394000000 | F32: 84293000000 | G32: reported | H32: HIGH | I32: 0.1390856 | J32: =IF(F32="","",F32*(1-I32)) -> 7.2569058e+10 | K32: 283379000000 | L32: 12870000000 | M32: 110916000000 | N32: =IF(COUNT(K32:M32)<3,"",K32+L32-M32) -> 185333000000 | O32: =N31 -> 157083000000 | P32: =IF(N32="","",IF(OR(O32="",O32<=0,N32<=0),N32,(N32+O32)/2)) -> 171208000000 | Q32: 기초·기말 평균 | R32: =IF(OR(P32="",P32<=0),"",J32/P32) -> 0.42386488 | S32: =IF(R32="","",R32-0.1) -> 0.32386488 | T32: =IF(OR(P32="",E32=0,E32=""),"",P32/E32) -> 0.55696598 | U32: — | V32: — | W32: OK | X32: Alphabet Inc.
A33: 알파벳 | B33: GOOG | C33: 2024 | D33: 2024-12-31 | E33: 350018000000 | F33: 112390000000 | G33: reported | H33: HIGH | I33: 0.16439511 | J33: =IF(F33="","",F33*(1-I33)) -> 9.3913634e+10 | K33: 325084000000 | L33: 14182000000 | M33: 95657000000 | N33: =IF(COUNT(K33:M33)<3,"",K33+L33-M33) -> 243609000000 | O33: =N32 -> 185333000000 | P33: =IF(N33="","",IF(OR(O33="",O33<=0,N33<=0),N33,(N33+O33)/2)) -> 214471000000 | Q33: 기초·기말 평균 | R33: =IF(OR(P33="",P33<=0),"",J33/P33) -> 0.437885 | S33: =IF(R33="","",R33-0.1) -> 0.337885 | T33: =IF(OR(P33="",E33=0,E33=""),"",P33/E33) -> 0.61274277 | U33: — | V33: — | W33: OK | X33: Alphabet Inc.
A34: 알파벳 | B34: GOOG | C34: 2025 | D34: 2025-12-31 | E34: 402836000000 | F34: 129039000000 | G34: reported | H34: HIGH | I34: 0.16783146 | J34: =IF(F34="","",F34*(1-I34)) -> 1.073822e+11 | K34: 415265000000 | L34: 48543000000 | M34: 126843000000 | N34: =IF(COUNT(K34:M34)<3,"",K34+L34-M34) -> 336965000000 | O34: =N33 -> 243609000000 | P34: =IF(N34="","",IF(OR(O34="",O34<=0,N34<=0),N34,(N34+O34)/2)) -> 290287000000 | Q34: 기초·기말 평균 | R34: =IF(OR(P34="",P34<=0),"",J34/P34) -> 0.36991734 | S34: =IF(R34="","",R34-0.1) -> 0.26991734 | T34: =IF(OR(P34="",E34=0,E34=""),"",P34/E34) -> 0.72060839 | U34: — | V34: — | W34: OK | X34: Alphabet Inc.
A35: 마이크로소프트 | B35: MSFT | C35: 2015 | D35: 2015-06-30 | E35: 93580000000 | F35: 18161000000 | G35: reported | H35: HIGH | I35: 0.34116821 | J35: =IF(F35="","",F35*(1-I35)) -> 1.1965044e+10 | K35: 80083000000 | L35: 35292000000 | M35: 96526000000 | N35: =IF(COUNT(K35:M35)<3,"",K35+L35-M35) -> 18849000000 | O35: — | P35: — | Q35: — | R35: — | S35: — | T35: — | U35: — | V35: — | W35: 다음 해 평균 투하자본의 기초값으로만 사용 (보고 기간 밖 — 자체 비율은 계산하지 않음) | X35: MICROSOFT CORP
A36: 마이크로소프트 | B36: MSFT | C36: 2016 | D36: 2016-06-30 | E36: 91154000000 | F36: 26078000000 | G36: reported | H36: HIGH | I36: 0.19891571 | J36: =IF(F36="","",F36*(1-I36)) -> 2.0890676e+10 | K36: 83090000000 | L36: 53461000000 | M36: 113240000000 | N36: =IF(COUNT(K36:M36)<3,"",K36+L36-M36) -> 23311000000 | O36: — | P36: — | Q36: — | R36: — | S36: — | T36: — | U36: — | V36: — | W36: 다음 해 평균 투하자본의 기초값으로만 사용 (보고 기간 밖 — 자체 비율은 계산하지 않음) | X36: MICROSOFT CORP
A37: 마이크로소프트 | B37: MSFT | C37: 2017 | D37: 2017-06-30 | E37: 96571000000 | F37: 29025000000 | G37: reported | H37: HIGH | I37: 0.14755359 | J37: =IF(F37="","",F37*(1-I37)) -> 2.4742257e+10 | K37: 87711000000 | L37: 86194000000 | M37: 132981000000 | N37: =IF(COUNT(K37:M37)<3,"",K37+L37-M37) -> 40924000000 | O37: =N36 -> 23311000000 | P37: =IF(N37="","",IF(OR(O37="",O37<=0,N37<=0),N37,(N37+O37)/2)) -> 32117500000 | Q37: 기초·기말 평균 | R37: =IF(OR(P37="",P37<=0),"",J37/P37) -> 0.77036684 | S37: =IF(R37="","",R37-0.1) -> 0.67036684 | T37: =IF(OR(P37="",E37=0,E37=""),"",P37/E37) -> 0.33257914 | U37: — | V37: — | W37: OK | X37: MICROSOFT CORP
A38: 마이크로소프트 | B38: MSFT | C38: 2018 | D38: 2018-06-30 | E38: 110360000000 | F38: 35058000000 | G38: reported | H38: HIGH | I38: 0.4 | J38: =IF(F38="","",F38*(1-I38)) -> 21034800000 | K38: 82718000000 | L38: 76240000000 | M38: 133768000000 | N38: =IF(COUNT(K38:M38)<3,"",K38+L38-M38) -> 25190000000 | O38: =N37 -> 40924000000 | P38: =IF(N38="","",IF(OR(O38="",O38<=0,N38<=0),N38,(N38+O38)/2)) -> 33057000000 | Q38: 기초·기말 평균 | R38: =IF(OR(P38="",P38<=0),"",J38/P38) -> 0.63631909 | S38: =IF(R38="","",R38-0.1) -> 0.53631909 | T38: =IF(OR(P38="",E38=0,E38=""),"",P38/E38) -> 0.29953788 | U38: — | V38: — | W38: OK | X38: MICROSOFT CORP
A39: 마이크로소프트 | B39: MSFT | C39: 2019 | D39: 2019-06-30 | E39: 125843000000 | F39: 42959000000 | G39: reported | H39: HIGH | I39: 0.10181285 | J39: =IF(F39="","",F39*(1-I39)) -> 3.8585222e+10 | K39: 102330000000 | L39: 72178000000 | M39: 133819000000 | N39: =IF(COUNT(K39:M39)<3,"",K39+L39-M39) -> 40689000000 | O39: =N38 -> 25190000000 | P39: =IF(N39="","",IF(OR(O39="",O39<=0,N39<=0),N39,(N39+O39)/2)) -> 32939500000 | Q39: 기초·기말 평균 | R39: =IF(OR(P39="",P39<=0),"",J39/P39) -> 1.1713967 | S39: =IF(R39="","",R39-0.1) -> 1.0713967 | T39: =IF(OR(P39="",E39=0,E39=""),"",P39/E39) -> 0.26175075 | U39: — | V39: — | W39: OK | X39: MICROSOFT CORP
A40: 마이크로소프트 | B40: MSFT | C40: 2020 | D40: 2020-06-30 | E40: 143015000000 | F40: 52959000000 | G40: reported | H40: HIGH | I40: 0.16507655 | J40: =IF(F40="","",F40*(1-I40)) -> 4.4216711e+10 | K40: 118304000000 | L40: 63327000000 | M40: 136527000000 | N40: =IF(COUNT(K40:M40)<3,"",K40+L40-M40) -> 45104000000 | O40: =N39 -> 40689000000 | P40: =IF(N40="","",IF(OR(O40="",O40<=0,N40<=0),N40,(N40+O40)/2)) -> 42896500000 | Q40: 기초·기말 평균 | R40: =IF(OR(P40="",P40<=0),"",J40/P40) -> 1.0307767 | S40: =IF(R40="","",R40-0.1) -> 0.93077666 | T40: =IF(OR(P40="",E40=0,E40=""),"",P40/E40) -> 0.29994406 | U40: — | V40: — | W40: OK | X40: MICROSOFT CORP
...

Sheet ROIC 연도별
A1: 셀은 '계산 명세' 시트의 ROIC를 참조합니다. 초록 = 10% 초과, 빨강 = 10% 이하, 기울임 = 영업이익을 세전이익에서 추정한 해, 노란 테두리 = 순투하자본이 매출의 10% 미만인 해.
A2: 순위 | B2: 기업 | C2: 티커 | D2: FY2016 | E2: FY2017 | F2: FY2018 | G2: FY2019 | H2: FY2020 | I2: FY2021 | J2: FY2022 | K2: FY2023 | L2: FY2024 | M2: FY2025 | N2: FY2026 | O2: 중위 | P2: 최소 | Q2: 최대 | R2: 10% 초과 연수 | S2: 산출 연수 | T2: 판정
A3: 순위 대상 (산출 5년 이상)
A4: 1 | B4: 아리스타 네트웍스 | C4: ANET | D4: ='계산 명세'!R478 -> 1.0861635 | E4: ='계산 명세'!R479 -> 2.2885491 | F4: ='계산 명세'!R480 -> 1.6561149 | G4: ='계산 명세'!R481 -> 4.2817166 | H4: ='계산 명세'!R482 -> 1.9455045 | I4: ='계산 명세'!R483 -> 1.6415471 | J4: ='계산 명세'!R484 -> 1.0735975 | K4: ='계산 명세'!R485 -> 0.95522267 | L4: ='계산 명세'!R486 -> 1.3182578 | M4: ='계산 명세'!R487 -> 1.9200796 | N4: — | O4: =MEDIAN(D4:N4) -> 1.648831 | P4: =MIN(D4:N4) -> 0.95522267 | Q4: =MAX(D4:N4) -> 4.2817166 | R4: =COUNTIF(D4:N4,">0.1") -> 10 | S4: =COUNT(D4:N4) -> 10 | T4: 전 기간 초과 · 매우 높음
A5: 2 | B5: 엔비디아 | C5: NVDA | D5: ='계산 명세'!R3 -> 1.7860208 | E5: ='계산 명세'!R4 -> 1.8509863 | F5: ='계산 명세'!R5 -> 1.1553069 | G5: ='계산 명세'!R6 -> 0.7436205 | H5: ='계산 명세'!R7 -> 0.55222215 | I5: ='계산 명세'!R8 -> 0.66601152 | J5: ='계산 명세'!R9 -> 0.22226653 | K5: ='계산 명세'!R10 -> 1.2490268 | L5: ='계산 명세'!R11 -> 1.9821923 | M5: ='계산 명세'!R12 -> 1.1082268 | N5: — | O5: =MEDIAN(D5:N5) -> 1.1317669 | P5: =MIN(D5:N5) -> 0.22226653 | Q5: =MAX(D5:N5) -> 1.9821923 | R5: =COUNTIF(D5:N5,">0.1") -> 10 | S5: =COUNT(D5:N5) -> 10 | T5: 전 기간 초과 · 매우 높음
A6: 3 | B6: 마스터카드 | C6: MA | D6: ='계산 명세'!R202 -> 1.617526 | E6: ='계산 명세'!R203 -> 1.4026209 | F6: ='계산 명세'!R204 -> 1.8186511 | G6: ='계산 명세'!R205 -> 1.5898454 | H6: ='계산 명세'!R206 -> 0.87088407 | I6: ='계산 명세'!R207 -> 0.77410625 | J6: ='계산 명세'!R208 -> 0.78754876 | K6: ='계산 명세'!R209 -> 0.86950339 | L6: ='계산 명세'!R210 -> 0.89324666 | M6: ='계산 명세'!R211 -> 0.95703638 | N6: — | O6: =MEDIAN(D6:N6) -> 0.92514152 | P6: =MIN(D6:N6) -> 0.77410625 | Q6: =MAX(D6:N6) -> 1.8186511 | R6: =COUNTIF(D6:N6,">0.1") -> 10 | S6: =COUNT(D6:N6) -> 10 | T6: 전 기간 초과 · 매우 높음
A7: 4 | B7: 애플 | C7: AAPL | D7: ='계산 명세'!R14 -> 0.30794128 | E7: ='계산 명세'!R15 -> 0.28596898 | F7: ='계산 명세'!R16 -> 0.3499434 | G7: ='계산 명세'!R17 -> 0.42428441 | H7: ='계산 명세'!R18 -> 0.61386135 | I7: ='계산 명세'!R19 -> 0.89108895 | J7: ='계산 명세'!R20 -> 0.80840103 | K7: ='계산 명세'!R21 -> 0.83272255 | L7: ='계산 명세'!R22 -> 0.89041021 | M7: ='계산 명세'!R23 -> 1.039152 | N7: — | O7: =MEDIAN(D7:N7) -> 0.71113119 | P7: =MIN(D7:N7) -> 0.28596898 | Q7: =MAX(D7:N7) -> 1.039152 | R7: =COUNTIF(D7:N7,">0.1") -> 10 | S7: =COUNT(D7:N7) -> 10 | T7: 전 기간 초과 · 매우 높음
A8: 5 | B8: 마이크로소프트 | C8: MSFT | D8: ='계산 명세'!R36 -> — | E8: ='계산 명세'!R37 -> 0.77036684 | F8: ='계산 명세'!R38 -> 0.63631909 | G8: ='계산 명세'!R39 -> 1.1713967 | H8: ='계산 명세'!R40 -> 1.0307767 | I8: ='계산 명세'!R41 -> 1.0486838 | J8: ='계산 명세'!R42 -> 0.79892226 | K8: ='계산 명세'!R43 -> 0.56526971 | L8: ='계산 명세'!R44 -> 0.46272339 | M8: ='계산 명세'!R45 -> 0.39457044 | N8: ='계산 명세'!R46 -> 0.3585794 | O8: =MEDIAN(D8:N8) -> 0.70334296 | P8: =MIN(D8:N8) -> 0.3585794 | Q8: =MAX(D8:N8) -> 1.1713967 | R8: =COUNTIF(D8:N8,">0.1") -> 10 | S8: =COUNT(D8:N8) -> 10 | T8: 전 기간 초과 · 매우 높음
A9: 6 | B9: 램리서치 | C9: LRCX | D9: ='계산 명세'!R290 -> — | E9: ='계산 명세'!R291 -> 0.52055414 | F9: ='계산 명세'!R292 -> 0.65722234 | G9: ='계산 명세'!R293 -> 0.58097307 | H9: ='계산 명세'!R294 -> 0.58903545 | I9: ='계산 명세'!R295 -> 0.84195609 | J9: ='계산 명세'!R296 -> 0.74328038 | K9: ='계산 명세'!R297 -> 0.5939825 | L9: ='계산 명세'!R298 -> 0.48425258 | M9: ='계산 명세'!R299 -> 0.68039171 | N9: ='계산 명세'!R300 -> 0.77721561 | O9: =MEDIAN(D9:N9) -> 0.62560242 | P9: =MIN(D9:N9) -> 0.48425258 | Q9: =MAX(D9:N9) -> 0.84195609 | R9: =COUNTIF(D9:N9,">0.1") -> 10 | S9: =COUNT(D9:N9) -> 10 | T9: 전 기간 초과 · 매우 높음
A10: 7 | B10: 필립모리스 인터내셔널 | C10: PM | D10: ='계산 명세'!R425 -> 0.57146557 | E10: ='계산 명세'!R426 -> 0.46965867 | F10: ='계산 명세'!R427 -> 0.58295306 | G10: ='계산 명세'!R428 -> 0.55735089 | H10: ='계산 명세'!R429 -> 0.64770167 | I10: ='계산 명세'!R430 -> 0.70607841 | J10: ='계산 명세'!R431 -> 0.4058536 | K10: ='계산 명세'!R432 -> 0.25995382 | L10: ='계산 명세'!R433 -> 0.30106487 | M10: ='계산 명세'!R434 -> 0.3540046 | N10: — | O10: =MEDIAN(D10:N10) -> 0.51350478 | P10: =MIN(D10:N10) -> 0.25995382 | Q10: =MAX(D10:N10) -> 0.70607841 | R10: =COUNTIF(D10:N10,">0.1") -> 10 | S10: =COUNT(D10:N10) -> 10 | T10: 전 기간 초과 · 매우 높음
A11: 8 | B11: KLA | C11: KLAC | D11: ='계산 명세'!R466 -> — | E11: ='계산 명세'!R467 -> 0.80700967 | F11: ='계산 명세'!R468 -> 0.8306849 | G11: ='계산 명세'!R469 -> 0.44209264 | H11: ='계산 명세'!R470 -> 0.28539867 | I11: ='계산 명세'!R471 -> 0.42946699 | J11: ='계산 명세'!R472 -> 0.55978314 | K11: ='계산 명세'!R473 -> 0.49316571 | L11: ='계산 명세'!R474 -> 0.35845898 | M11: ='계산 명세'!R475 -> 0.4814352 | N11: ='계산 명세'!R476 -> 0.49384768 | O11: =MEDIAN(D11:N11) -> 0.48730046 | P11: =MIN(D11:N11) -> 0.28539867 | Q11: =MAX(D11:N11) -> 0.8306849 | R11: =COUNTIF(D11:N11,">0.1") -> 10 | S11: =COUNT(D11:N11) -> 10 | T11: 전 기간 초과 · 매우 높음
A12: 9 | B12: 텍사스 인스트루먼츠 | C12: TXN | D12: ='계산 명세'!R455 -> 0.33025274 | E12: ='계산 명세'!R456 -> 0.35874926 | F12: ='계산 명세'!R457 -> 0.56665658 | G12: ='계산 명세'!R458 -> 0.52345662 | H12: ='계산 명세'!R459 -> 0.58491212 | I12: ='계산 명세'!R460 -> 0.75218905 | J12: ='계산 명세'!R461 -> 0.69141421 | K12: ='계산 명세'!R462 -> 0.38080197 | L12: ='계산 명세'!R463 -> 0.22652415 | M12: ='계산 명세'!R464 -> 0.21816561 | N12: — | O12: =MEDIAN(D12:N12) -> 0.4521293 | P12: =MIN(D12:N12) -> 0.21816561 | Q12: =MAX(D12:N12) -> 0.75218905 | R12: =COUNTIF(D12:N12,">0.1") -> 10 | S12: =COUNT(D12:N12) -> 10 | T12: 전 기간 초과 · 매우 높음
A13: 10 | B13: 메타 플랫폼스 | C13: META | D13: ='계산 명세'!R69 -> 0.36399523 | E13: ='계산 명세'!R70 -> 0.50116142 | F13: ='계산 명세'!R71 -> 0.57426782 | G13: ='계산 명세'!R72 -> 0.40061041 | H13: ='계산 명세'!R73 -> 0.5100437 | I13: ='계산 명세'!R74 -> 0.54362086 | J13: ='계산 명세'!R75 -> 0.27128611 | K13: ='계산 명세'!R76 -> 0.38339008 | L13: ='계산 명세'!R77 -> 0.51066109 | M13: ='계산 명세'!R78 -> 0.35720533 | N13: — | O13: =MEDIAN(D13:N13) -> 0.45088592 | P13: =MIN(D13:N13) -> 0.27128611 | Q13: =MAX(D13:N13) -> 0.57426782 | R13: =COUNTIF(D13:N13,">0.1") -> 10 | S13: =COUNT(D13:N13) -> 10 | T13: 전 기간 초과 · 매우 높음
A14: 11 | B14: 홈디포 | C14: HD | D14: ='계산 명세'!R357 -> 0.33732645 | E14: ='계산 명세'!R358 -> 0.36789009 | F14: ='계산 명세'!R359 -> 0.47053122 | G14: ='계산 명세'!R360 -> 0.46750761 | H14: ='계산 명세'!R361 -> 0.47051924 | I14: ='계산 명세'!R362 -> 0.50715712 | J14: ='계산 명세'!R363 -> 0.46879831 | K14: ='계산 명세'!R364 -> 0.39534415 | L14: ='계산 명세'!R365 -> 0.32926302 | M14: ='계산 명세'!R366 -> 0.25322002 | N14: — | O14: =MEDIAN(D14:N14) -> 0.43142588 | P14: =MIN(D14:N14) -> 0.25322002 | Q14: =MAX(D14:N14) -> 0.50715712 | R14: =COUNTIF(D14:N14,">0.1") -> 10 | S14: =COUNT(D14:N14) -> 10 | T14: 전 기간 초과 · 매우 높음
A15: 12 | B15: 어플라이드 머티리얼즈 | C15: AMAT | D15: ='계산 명세'!R247 -> 0.25951577 | E15: ='계산 명세'!R248 -> 0.49561827 | F15: ='계산 명세'!R249 -> 0.39331553 | G15: ='계산 명세'!R250 -> 0.3075528 | H15: ='계산 명세'!R251 -> 0.37548855 | I15: ='계산 명세'!R252 -> 0.53183698 | J15: ='계산 명세'!R253 -> 0.48973181 | K15: ='계산 명세'!R254 -> 0.45172265 | L15: ='계산 명세'!R255 -> 0.43933313 | M15: ='계산 명세'!R256 -> 0.35869747 | N15: — | O15: =MEDIAN(D15:N15) -> 0.41632433 | P15: =MIN(D15:N15) -> 0.25951577 | Q15: =MAX(D15:N15) -> 0.53183698 | R15: =COUNTIF(D15:N15,">0.1") -> 10 | S15: =COUNT(D15:N15) -> 10 | T15: 전 기간 초과 · 매우 높음
A16: 13 | B16: 알파벳 | C16: GOOG | D16: ='계산 명세'!R25 -> 0.35057615 | E16: ='계산 명세'!R26 -> 0.28246592 | F16: ='계산 명세'!R27 -> 0.38155484 | G16: ='계산 명세'!R28 -> 0.37515751 | H16: ='계산 명세'!R29 -> 0.37023344 | I16: ='계산 명세'!R30 -> 0.57965865 | J16: ='계산 명세'!R31 -> 0.44332262 | K16: ='계산 명세'!R32 -> 0.42386488 | L16: ='계산 명세'!R33 -> 0.437885 | M16: ='계산 명세'!R34 -> 0.36991734 | N16: — | O16: =MEDIAN(D16:N16) -> 0.37835618 | P16: =MIN(D16:N16) -> 0.28246592 | Q16: =MAX(D16:N16) -> 0.57965865 | R16: =COUNTIF(D16:N16,">0.1") -> 10 | S16: =COUNT(D16:N16) -> 10 | T16: 전 기간 초과 · 매우 높음
A17: 14 | B17: 코스트코 | C17: COST | D17: ='계산 명세'!R270 -> — | E17: ='계산 명세'!R271 -> 0.22346643 | F17: ='계산 명세'!R272 -> 0.26301849 | G17: ='계산 명세'!R273 -> 0.29012249 | H17: ='계산 명세'!R274 -> 0.31652762 | I17: ='계산 명세'!R275 -> 0.38574264 | J17: ='계산 명세'!R276 -> 0.39622213 | K17: ='계산 명세'!R277 -> 0.36989819 | L17: ='계산 명세'!R278 -> 0.40527765 | M17: ='계산 명세'!R279 -> 0.40866036 | N17: ='계산 명세'!R280 -> 0.43636596 | O17: =MEDIAN(D17:N17) -> 0.37782042 | P17: =MIN(D17:N17) -> 0.22346643 | Q17: =MAX(D17:N17) -> 0.43636596 | R17: =COUNTIF(D17:N17,">0.1") -> 10 | S17: =COUNT(D17:N17) -> 10 | T17: 전 기간 초과 · 매우 높음
A18: 15 | B18: 시스코 시스템즈 | C18: CSCO | D18: ='계산 명세'!R213 -> — | E18: ='계산 명세'!R214 -> 0.33540271 | F18: ='계산 명세'!R215 -> 0.28632795 | G18: ='계산 명세'!R216 -> 0.48206189 | H18: ='계산 명세'!R217 -> 0.45641847 | I18: ='계산 명세'!R218 -> 0.39902668 | J18: ='계산 명세'!R219 -> 0.39096855 | K18: ='계산 명세'!R220 -> 0.4371918 | L18: ='계산 명세'!R221 -> 0.24130883 | M18: ='계산 명세'!R222 -> 0.18133865 | N18: ='계산 명세'!R223 -> 0.2023031 | O18: =MEDIAN(D18:N18) -> 0.36318563 | P18: =MIN(D18:N18) -> 0.18133865 | Q18: =MAX(D18:N18) -> 0.48206189 | R18: =COUNTIF(D18:N18,">0.1") -> 10 | S18: =COUNT(D18:N18) -> 10 | T18: 전 기간 초과 · 매우 높음
A19: 16 | B19: 비자 | C19: V | D19: ='계산 명세'!R158 -> 0.18472391 | E19: ='계산 명세'!R159 -> 0.18755695 | F19: ='계산 명세'!R160 -> 0.2713166 | G19: ='계산 명세'!R161 -> 0.31017027 | H19: ='계산 명세'!R162 -> 0.27789653 | I19: ='계산 명세'!R163 -> 0.30115233 | J19: ='계산 명세'!R164 -> 0.39001372 | K19: ='계산 명세'!R165 -> 0.43887194 | L19: ='계산 명세'!R166 -> 0.46450313 | M19: ='계산 명세'!R167 -> 0.44761401 | N19: — | O19: =MEDIAN(D19:N19) -> 0.3056613 | P19: =MIN(D19:N19) -> 0.18472391 | Q19: =MAX(D19:N19) -> 0.46450313 | R19: =COUNTIF(D19:N19,">0.1") -> 10 | S19: =COUNT(D19:N19) -> 10 | T19: 전 기간 초과 · 매우 높음
A20: 17 | B20: 아마존 | C20: AMZN | D20: ='계산 명세'!R48 -> 1.2959004 | E20: ='계산 명세'!R49 -> 0.27742466 | F20: ='계산 명세'!R50 -> 0.45559076 | G20: ='계산 명세'!R51 -> 0.4097221 | H20: ='계산 명세'!R52 -> 0.54755281 | I20: ='계산 명세'!R53 -> 0.32294247 | J20: ='계산 명세'!R54 -> 0.080594049 | K20: ='계산 명세'!R55 -> 0.18132485 | L20: ='계산 명세'!R56 -> 0.27946104 | M20: ='계산 명세'!R57 -> 0.21449257 | N20: — | O20: =MEDIAN(D20:N20) -> 0.30120176 | P20: =MIN(D20:N20) -> 0.080594049 | Q20: =MAX(D20:N20) -> 1.2959004 | R20: =COUNTIF(D20:N20,">0.1") -> 9 | S20: =COUNT(D20:N20) -> 10 | T20: 대체로 초과
A21: 18 | B21: 일라이 릴리 | C21: LLY | D21: ='계산 명세'!R102 -> 0.14513322 | E21: ='계산 명세'!R103 -> 0.067473897 | F21: ='계산 명세'!R104 -> 0.19472191 | G21: ='계산 명세'!R105 -> 0.29826975 | H21: ='계산 명세'!R106 -> 0.30245991 | I21: ='계산 명세'!R107 -> 0.28208922 | J21: ='계산 명세'!R108 -> 0.27866143 | K21: ='계산 명세'!R109 -> 0.17812752 | L21: ='계산 명세'!R110 -> 0.2774587 | M21: ='계산 명세'!R111 -> 0.39709146 | N21: — | O21: =MEDIAN(D21:N21) -> 0.27806007 | P21: =MIN(D21:N21) -> 0.067473897 | Q21: =MAX(D21:N21) -> 0.39709146 | R21: =COUNTIF(D21:N21,">0.1") -> 9 | S21: =COUNT(D21:N21) -> 10 | T21: 대체로 초과
A22: 19 | B22: 존슨앤드존슨 | C22: JNJ | D22: ='계산 명세'!R180 -> 0.30873255 | E22: ='계산 명세'!R181 -> 0.16017018 | F22: ='계산 명세'!R182 -> 0.22438678 | G22: ='계산 명세'!R183 -> 0.25027067 | H22: ='계산 명세'!R184 -> 0.24502748 | I22: ='계산 명세'!R185 -> 0.24462619 | J22: ='계산 명세'!R186 -> 0.20016475 | K22: ='계산 명세'!R187 -> 0.22657844 | L22: ='계산 명세'!R188 -> 0.22691925 | M22: ='계산 명세'!R189 -> 0.21630414 | N22: — | O22: =MEDIAN(D22:N22) -> 0.22674884 | P22: =MIN(D22:N22) -> 0.16017018 | Q22: =MAX(D22:N22) -> 0.30873255 | R22: =COUNTIF(D22:N22,">0.1") -> 10 | S22: =COUNT(D22:N22) -> 10 | T22: 전 기간 초과
A23: 20 | B23: 프록터앤드갬블 | C23: PG | D23: ='계산 명세'!R368 -> — | E23: ='계산 명세'!R369 -> 0.13149065 | F23: ='계산 명세'!R370 -> 0.11992158 | G23: ='계산 명세'!R371 -> 0.047131415 | H23: ='계산 명세'!R372 -> 0.18723456 | I23: ='계산 명세'!R373 -> 0.20776987 | J23: ='계산 명세'!R374 -> 0.20996057 | K23: ='계산 명세'!R375 -> 0.2014698 | L23: ='계산 명세'!R376 -> 0.20143302 | M23: ='계산 명세'!R377 -> 0.2161028 | N23: ='계산 명세'!R378 -> 0.20091644 | O23: =MEDIAN(D23:N23) -> 0.20117473 | P23: =MIN(D23:N23) -> 0.047131415 | Q23: =MAX(D23:N23) -> 0.2161028 | R23: =COUNTIF(D23:N23,">0.1") -> 9 | S23: =COUNT(D23:N23) -> 10 | T23: 대체로 초과
A24: 21 | B24: 애브비 | C24: ABBV | D24: ='계산 명세'!R236 -> 0.22653177 | E24: ='계산 명세'!R237 -> 0.19365123 | F24: ='계산 명세'!R238 -> 0.21472937 | G24: ='계산 명세'!R239 -> 0.57239499 | H24: ='계산 명세'!R240 -> 0.19751615 | I24: ='계산 명세'!R241 -> 0.18427986 | J24: ='계산 명세'!R242 -> 0.20730663 | K24: ='계산 명세'!R243 -> 0.1550548 | L24: ='계산 명세'!R244 -> 0.14239208 | M24: ='계산 명세'!R245 -> 0.15606069 | N24: — | O24: =MEDIAN(D24:N24) -> 0.19558369 | P24: =MIN(D24:N24) -> 0.14239208 | Q24: =MAX(D24:N24) -> 0.57239499 | R24: =COUNTIF(D24:N24,">0.1") -> 10 | S24: =COUNT(D24:N24) -> 10 | T24: 전 기간 초과
A25: 22 | B25: 넷플릭스 | C25: NFLX | D25: ='계산 명세'!R391 -> 0.082542055 | E25: ='계산 명세'!R392 -> 0.13773886 | F25: ='계산 명세'!R393 -> 0.15999266 | G25: ='계산 명세'!R394 -> 0.16188264 | H25: ='계산 명세'!R395 -> 0.21690532 | I25: ='계산 명세'!R396 -> 0.24469037 | J25: ='계산 명세'!R397 -> 0.17725326 | K25: ='계산 명세'!R398 -> 0.21249354 | L25: ='계산 명세'!R399 -> 0.31009653 | M25: ='계산 명세'!R400 -> 0.36656571 | N25: — | O25: =MEDIAN(D25:N25) -> 0.1948734 | P25: =MIN(D25:N25) -> 0.082542055 | Q25: =MAX(D25:N25) -> 0.36656571 | R25: =COUNTIF(D25:N25,">0.1") -> 9 | S25: =COUNT(D25:N25) -> 10 | T25: 대체로 초과
A26: 23 | B26: 오라클 | C26: ORCL | D26: ='계산 명세'!R258 -> — | E26: ='계산 명세'!R259 -> 0.25254154 | F26: ='계산 명세'!R260 -> 0.18254886 | G26: ='계산 명세'!R261 -> 0.26423135 | H26: ='계산 명세'!R262 -> 0.26788287 | I26: ='계산 명세'!R263 -> 0.2831159 | J26: ='계산 명세'!R264 -> 0.18798545 | K26: ='계산 명세'!R265 -> 0.15908258 | L26: ='계산 명세'!R266 -> 0.14499806 | M26: ='계산 명세'!R267 -> 0.1487437 | N26: ='계산 명세'!R268 -> 0.133961 | O26: =MEDIAN(D26:N26) -> 0.18526715 | P26: =MIN(D26:N26) -> 0.133961 | Q26: =MAX(D26:N26) -> 0.2831159 | R26: =COUNTIF(D26:N26,">0.1") -> 10 | S26: =COUNT(D26:N26) -> 10 | T26: 전 기간 초과
A27: 24 | B27: 마이크론 테크놀로지 | C27: MU | D27: ='계산 명세'!R113 -> — | E27: ='계산 명세'!R114 -> 0.25562179 | F27: ='계산 명세'!R115 -> 0.50714921 | G27: ='계산 명세'!R116 -> 0.20256911 | H27: ='계산 명세'!R117 -> 0.075416008 | I27: ='계산 명세'!R118 -> 0.14791151 | J27: ='계산 명세'!R119 -> 0.19656191 | K27: ='계산 명세'!R120 -> -0.095209675 | L27: ='계산 명세'!R121 -> 0.016885215 | M27: ='계산 명세'!R122 -> 0.15860247 | N27: ='계산 명세'!R123 -> 1.0674708 | O27: =MEDIAN(D27:N27) -> 0.17758219 | P27: =MIN(D27:N27) -> -0.095209675 | Q27: =MAX(D27:N27) -> 1.0674708 | R27: =COUNTIF(D27:N27,">0.1") -> 7 | S27: =COUNT(D27:N27) -> 10 | T27: 절반 이상 초과
A28: 25 | B28: 캐터필러 | C28: CAT | D28: ='계산 명세'!R302 -> 0.018169972 | E28: ='계산 명세'!R303 -> 0.076055137 | F28: ='계산 명세'!R304 -> 0.18254742 | G28: ='계산 명세'!R305 -> 0.17225952 | H28: ='계산 명세'!R306 -> 0.094845956 | I28: ='계산 명세'!R307 -> 0.14895879 | J28: ='계산 명세'!R308 -> 0.15234682 | K28: ='계산 명세'!R309 -> 0.2482518 | L28: ='계산 명세'!R310 -> 0.24426784 | M28: ='계산 명세'!R311 -> 0.1844791 | N28: — | O28: =MEDIAN(D28:N28) -> 0.16230317 | P28: =MIN(D28:N28) -> 0.018169972 | Q28: =MAX(D28:N28) -> 0.2482518 | R28: =COUNTIF(D28:N28,">0.1") -> 7 | S28: =COUNT(D28:N28) -> 10 | T28: 절반 이상 초과
A29: 26 | B29: 델 테크놀로지스 | C29: DELL | D29: ='계산 명세'!R436 -> -0.07635391 | E29: ='계산 명세'!R437 -> -0.034160328 | F29: ='계산 명세'!R438 -> -0.0031392905 | G29: — | H29: ='계산 명세'!R440 -> 0.085513459 | I29: ='계산 명세'!R441 -> 0.15529525 | J29: ='계산 명세'!R442 -> 0.28463966 | K29: ='계산 명세'!R443 -> 0.28570158 | L29: ='계산 명세'!R444 -> 0.34324899 | M29: ='계산 명세'!R445 -> 0.39348468 | N29: — | O29: =MEDIAN(D29:N29) -> 0.15529525 | P29: =MIN(D29:N29) -> -0.07635391 | Q29: =MAX(D29:N29) -> 0.39348468 | R29: =COUNTIF(D29:N29,">0.1") -> 5 | S29: =COUNT(D29:N29) -> 9 | T29: 절반 이상 초과
A30: 27 | B30: 코카콜라 | C30: KO | D30: ='계산 명세'!R324 -> 0.13304771 | E30: ='계산 명세'!R325 -> 0.091557541 | F30: ='계산 명세'!R326 -> 0.14070134 | G30: ='계산 명세'!R327 -> 0.15658795 | H30: ='계산 명세'!R328 -> 0.12867501 | I30: ='계산 명세'!R329 -> 0.14497571 | J30: ='계산 명세'!R330 -> 0.16082777 | K30: ='계산 명세'!R331 -> 0.16804101 | L30: ='계산 명세'!R332 -> 0.14200603 | M30: ='계산 명세'!R333 -> 0.18297308 | N30: — | O30: =MEDIAN(D30:N30) -> 0.14349087 | P30: =MIN(D30:N30) -> 0.091557541 | Q30: =MAX(D30:N30) -> 0.18297308 | R30: =COUNTIF(D30:N30,">0.1") -> 9 | S30: =COUNT(D30:N30) -> 10 | T30: 대체로 초과
A31: 28 | B31: 월마트 | C31: WMT | D31: ='계산 명세'!R136 -> 0.13936391 | E31: ='계산 명세'!R137 -> 0.12940313 | F31: ='계산 명세'!R138 -> 0.12217909 | G31: ='계산 명세'!R139 -> 0.1303518 | H31: ='계산 명세'!R140 -> 0.12775837 | I31: ='계산 명세'!R141 -> 0.16900806 | J31: ='계산 명세'!R142 -> 0.11851569 | K31: ='계산 명세'!R143 -> 0.17190601 | L31: ='계산 명세'!R144 -> 0.18397155 | M31: ='계산 명세'!R145 -> 0.17491847 | N31: — | O31: =MEDIAN(D31:N31) -> 0.13485785 | P31: =MIN(D31:N31) -> 0.11851569 | Q31: =MAX(D31:N31) -> 0.18397155 | R31: =COUNTIF(D31:N31,">0.1") -> 10 | S31: =COUNT(D31:N31) -> 10 | T31: 전 기간 초과
A32: 29 | B32: 인텔 | C32: INTC | D32: ='계산 명세'!R191 -> 0.14106231 | E32: ='계산 명세'!R192 -> 0.12452355 | F32: ='계산 명세'!R193 -> 0.22596088 | G32: ='계산 명세'!R194 -> 0.19637072 | H32: ='계산 명세'!R195 -> 0.18747045 | I32: ='계산 명세'!R196 -> 0.16683123 | J32: ='계산 명세'!R197 -> 0.020044477 | K32: ='계산 명세'!R198 -> 0.00070343477 | L32: ='계산 명세'!R199 -> -0.069059728 | M32: ='계산 명세'!R200 -> -0.0098946036 | N32: — | O32: =MEDIAN(D32:N32) -> 0.13279293 | P32: =MIN(D32:N32) -> -0.069059728 | Q32: =MAX(D32:N32) -> 0.22596088 | R32: =COUNTIF(D32:N32,">0.1") -> 6 | S32: =COUNT(D32:N32) -> 10 | T32: 절반 이상 초과
A33: 30 | B33: 머크 | C33: MRK | D33: ='계산 명세'!R380 -> 0.07545999 | E33: ='계산 명세'!R381 -> 0.071309291 | F33: ='계산 명세'!R382 -> 0.12620176 | G33: ='계산 명세'!R383 -> 0.13428033 | H33: ='계산 명세'!R384 -> 0.084288943 | I33: ='계산 명세'!R385 -> 0.19862047 | J33: ='계산 명세'!R386 -> 0.24997715 | K33: ='계산 명세'!R387 -> 0.021871711 | L33: ='계산 명세'!R388 -> 0.25272105 | M33: ='계산 명세'!R389 -> 0.23404889 | N33: — | O33: =MEDIAN(D33:N33) -> 0.13024105 | P33: =MIN(D33:N33) -> 0.021871711 | Q33: =MAX(D33:N33) -> 0.25272105 | R33: =COUNTIF(D33:N33,">0.1") -> 6 | S33: =COUNT(D33:N33) -> 10 | T33: 절반 이상 초과
A34: 31 | B34: IBM | C34: IBM | D34: ='계산 명세'!R510 -> 0.25087619 | E34: ='계산 명세'!R511 -> 0.13863195 | F34: ='계산 명세'!R512 -> 0.18067919 | G34: ='계산 명세'!R513 -> 0.12188443 | H34: ='계산 명세'!R514 -> 0.046477731 | I34: ='계산 명세'!R515 -> 0.077939646 | J34: ='계산 명세'!R516 -> 0.032042887 | K34: ='계산 명세'!R517 -> 0.12509172 | L34: ='계산 명세'!R518 -> 0.09772321 | M34: ='계산 명세'!R519 -> 0.14533699 | N34: — | O34: =MEDIAN(D34:N34) -> 0.12348807 | P34: =MIN(D34:N34) -> 0.032042887 | Q34: =MAX(D34:N34) -> 0.25087619 | R34: =COUNTIF(D34:N34,">0.1") -> 6 | S34: =COUNT(D34:N34) -> 10 | T34: 절반 이상 초과
A35: 32 | B35: 브로드컴 | C35: AVGO | D35: ='계산 명세'!R58 -> -0.017205922 | E35: ='계산 명세'!R59 -> 0.093251775 | F35: ='계산 명세'!R60 -> 0.14037322 | G35: ='계산 명세'!R61 -> 0.070422626 | H35: ='계산 명세'!R62 -> 0.068894931 | I35: ='계산 명세'!R63 -> 0.14680338 | J35: ='계산 명세'!R64 -> 0.25716694 | K35: ='계산 명세'!R65 -> 0.30616223 | L35: ='계산 명세'!R66 -> 0.094539656 | M35: ='계산 명세'!R67 -> 0.18593531 | N35: — | O35: =MEDIAN(D35:N35) -> 0.11745644 | P35: =MIN(D35:N35) -> -0.017205922 | Q35: =MAX(D35:N35) -> 0.30616223 | R35: =COUNTIF(D35:N35,">0.1") -> 5 | S35: =COUNT(D35:N35) -> 10 | T35: 절반 이상 초과
A36: 33 | B36: AMD | C36: AMD | D36: ='계산 명세'!R147 -> -0.29764646 | E36: ='계산 명세'!R148 -> 0.1380055 | F36: ='계산 명세'!R149 -> 0.39561404 | G36: ='계산 명세'!R150 -> 0.36493165 | H36: ='계산 명세'!R151 -> 0.45737647 | I36: ='계산 명세'!R152 -> 0.77701918 | J36: ='계산 명세'!R153 -> 0.04322223 | K36: ='계산 명세'!R154 -> 0.0073295558 | L36: ='계산 명세'!R155 -> 0.028891331 | M36: ='계산 명세'!R156 -> 0.063906543 | N36: — | O36: =MEDIAN(D36:N36) -> 0.10095602 | P36: =MIN(D36:N36) -> -0.29764646 | Q36: =MAX(D36:N36) -> 0.77701918 | R36: =COUNTIF(D36:N36,">0.1") -> 5 | S36: =COUNT(D36:N36) -> 10 | T36: 절반 이상 초과
A37: 34 | B37: 테슬라 | C37: TSLA | D37: ='계산 명세'!R80 -> -0.090593159 | E37: ='계산 명세'!R81 -> -0.121608 | F37: ='계산 명세'!R82 -> -0.023778899 | G37: ='계산 명세'!R83 -> -0.0043094875 | H37: ='계산 명세'!R84 -> 0.12540644 | I37: ='계산 명세'!R85 -> 0.39065549 | J37: ='계산 명세'!R86 -> 0.5981238 | K37: ='계산 명세'!R87 -> 0.27563144 | L37: ='계산 명세'!R88 -> 0.14155947 | M37: ='계산 명세'!R89 -> 0.072356997 | N37: — | O37: =MEDIAN(D37:N37) -> 0.098881721 | P37: =MIN(D37:N37) -> -0.121608 | Q37: =MAX(D37:N37) -> 0.5981238 | R37: =COUNTIF(D37:N37,">0.1") -> 5 | S37: =COUNT(D37:N37) -> 10 | T37: 절반 이상 초과
A38: 35 | B38: 엑슨모빌 | C38: XOM | D38: ='계산 명세'!R169 -> 0.037759727 | E38: ='계산 명세'!R170 -> 0.082318672 | F38: ='계산 명세'!R171 -> 0.094094381 | G38: ='계산 명세'!R172 -> 0.064377689 | H38: ='계산 명세'!R173 -> -0.093333163 | I38: ='계산 명세'!R174 -> 0.10941009 | J38: ='계산 명세'!R175 -> 0.26863067 | K38: ='계산 명세'!R176 -> 0.16858854 | L38: ='계산 명세'!R177 -> 0.1397946 | M38: ='계산 명세'!R178 -> 0.10258321 | N38: — | O38: =MEDIAN(D38:N38) -> 0.098338793 | P38: =MIN(D38:N38) -> -0.093333163 | Q38: =MAX(D38:N38) -> 0.26863067 | R38: =COUNTIF(D38:N38,">0.1") -> 5 | S38: =COUNT(D38:N38) -> 10 | T38: 절반 이상 초과
A39: 36 | B39: 셰브론 | C39: CVX | D39: ='계산 명세'!R346 -> -0.0080651524 | E39: ='계산 명세'!R347 -> 0.046667354 | F39: ='계산 명세'!R348 -> 0.080257196 | G39: ='계산 명세'!R349 -> 0.020792039 | H39: ='계산 명세'!R350 -> -0.029967995 | I39: ='계산 명세'!R351 -> 0.091391774 | J39: ='계산 명세'!R352 -> 0.20970839 | K39: ='계산 명세'!R353 -> 0.12471042 | L39: ='계산 명세'!R354 -> 0.10164669 | M39: ='계산 명세'!R355 -> 0.064144067 | N39: — | O39: =MEDIAN(D39:N39) -> 0.072200631 | P39: =MIN(D39:N39) -> -0.029967995 | Q39: =MAX(D39:N39) -> 0.20970839 | R39: =COUNTIF(D39:N39,">0.1") -> 3 | S39: =COUNT(D39:N39) -> 10 | T39: 대부분 미달
A40: 37 | B40: RTX | C40: RTX | D40: ='계산 명세'!R402 -> 0.14221698 | E40: ='계산 명세'!R403 -> 0.1076375 | F40: ='계산 명세'!R404 -> 0.026080453 | G40: ='계산 명세'!R405 -> 0.053524067 | H40: ='계산 명세'!R406 -> -0.016717001 | I40: ='계산 명세'!R407 -> 0.04310354 | J40: ='계산 명세'!R408 -> 0.048797841 | K40: ='계산 명세'!R409 -> 0.031854239 | L40: ='계산 명세'!R410 -> 0.054347516 | M40: ='계산 명세'!R411 -> 0.077751746 | N40: — | O40: =MEDIAN(D40:N40) -> 0.051160954 | P40: =MIN(D40:N40) -> -0.016717001 | Q40: =MAX(D40:N40) -> 0.14221698 | R40: =COUNTIF(D40:N40,">0.1") -> 2 | S40: =COUNT(D40:N40) -> 10 | T40: 대부분 미달
...

Sheet ROIC−WACC 스프레드
A1: ROIC에서 10%를 뺀 값. 0보다 크면 자본비용을 넘겨 가치를 창출한 해입니다.
A2: 순위 | B2: 기업 | C2: 티커 | D2: FY2016 | E2: FY2017 | F2: FY2018 | G2: FY2019 | H2: FY2020 | I2: FY2021 | J2: FY2022 | K2: FY2023 | L2: FY2024 | M2: FY2025 | N2: FY2026 | O2: 중위 | P2: 최소 | Q2: 최대 | R2: 10% 초과 연수 | S2: 산출 연수 | T2: 판정
A3: 순위 대상 (산출 5년 이상)
A4: 1 | B4: 아리스타 네트웍스 | C4: ANET | D4: ='계산 명세'!S478 -> 0.98616349 | E4: ='계산 명세'!S479 -> 2.1885491 | F4: ='계산 명세'!S480 -> 1.5561149 | G4: ='계산 명세'!S481 -> 4.1817166 | H4: ='계산 명세'!S482 -> 1.8455045 | I4: ='계산 명세'!S483 -> 1.5415471 | J4: ='계산 명세'!S484 -> 0.97359752 | K4: ='계산 명세'!S485 -> 0.85522267 | L4: ='계산 명세'!S486 -> 1.2182578 | M4: ='계산 명세'!S487 -> 1.8200796 | N4: — | O4: =MEDIAN(D4:N4) -> 1.548831 | P4: =MIN(D4:N4) -> 0.85522267 | Q4: =MAX(D4:N4) -> 4.1817166 | R4: =COUNTIF(D4:N4,">0") -> 10 | S4: =COUNT(D4:N4) -> 10 | T4: 전 기간 초과 · 매우 높음
A5: 2 | B5: 엔비디아 | C5: NVDA | D5: ='계산 명세'!S3 -> 1.6860208 | E5: ='계산 명세'!S4 -> 1.7509863 | F5: ='계산 명세'!S5 -> 1.0553069 | G5: ='계산 명세'!S6 -> 0.6436205 | H5: ='계산 명세'!S7 -> 0.45222215 | I5: ='계산 명세'!S8 -> 0.56601152 | J5: ='계산 명세'!S9 -> 0.12226653 | K5: ='계산 명세'!S10 -> 1.1490268 | L5: ='계산 명세'!S11 -> 1.8821923 | M5: ='계산 명세'!S12 -> 1.0082268 | N5: — | O5: =MEDIAN(D5:N5) -> 1.0317669 | P5: =MIN(D5:N5) -> 0.12226653 | Q5: =MAX(D5:N5) -> 1.8821923 | R5: =COUNTIF(D5:N5,">0") -> 10 | S5: =COUNT(D5:N5) -> 10 | T5: 전 기간 초과 · 매우 높음
A6: 3 | B6: 마스터카드 | C6: MA | D6: ='계산 명세'!S202 -> 1.517526 | E6: ='계산 명세'!S203 -> 1.3026209 | F6: ='계산 명세'!S204 -> 1.7186511 | G6: ='계산 명세'!S205 -> 1.4898454 | H6: ='계산 명세'!S206 -> 0.77088407 | I6: ='계산 명세'!S207 -> 0.67410625 | J6: ='계산 명세'!S208 -> 0.68754876 | K6: ='계산 명세'!S209 -> 0.76950339 | L6: ='계산 명세'!S210 -> 0.79324666 | M6: ='계산 명세'!S211 -> 0.85703638 | N6: — | O6: =MEDIAN(D6:N6) -> 0.82514152 | P6: =MIN(D6:N6) -> 0.67410625 | Q6: =MAX(D6:N6) -> 1.7186511 | R6: =COUNTIF(D6:N6,">0") -> 10 | S6: =COUNT(D6:N6) -> 10 | T6: 전 기간 초과 · 매우 높음
A7: 4 | B7: 애플 | C7: AAPL | D7: ='계산 명세'!S14 -> 0.20794128 | E7: ='계산 명세'!S15 -> 0.18596898 | F7: ='계산 명세'!S16 -> 0.2499434 | G7: ='계산 명세'!S17 -> 0.32428441 | H7: ='계산 명세'!S18 -> 0.51386135 | I7: ='계산 명세'!S19 -> 0.79108895 | J7: ='계산 명세'!S20 -> 0.70840103 | K7: ='계산 명세'!S21 -> 0.73272255 | L7: ='계산 명세'!S22 -> 0.79041021 | M7: ='계산 명세'!S23 -> 0.93915199 | N7: — | O7: =MEDIAN(D7:N7) -> 0.61113119 | P7: =MIN(D7:N7) -> 0.18596898 | Q7: =MAX(D7:N7) -> 0.93915199 | R7: =COUNTIF(D7:N7,">0") -> 10 | S7: =COUNT(D7:N7) -> 10 | T7: 전 기간 초과 · 매우 높음
A8: 5 | B8: 마이크로소프트 | C8: MSFT | D8: ='계산 명세'!S36 -> — | E8: ='계산 명세'!S37 -> 0.67036684 | F8: ='계산 명세'!S38 -> 0.53631909 | G8: ='계산 명세'!S39 -> 1.0713967 | H8: ='계산 명세'!S40 -> 0.93077666 | I8: ='계산 명세'!S41 -> 0.94868383 | J8: ='계산 명세'!S42 -> 0.69892226 | K8: ='계산 명세'!S43 -> 0.46526971 | L8: ='계산 명세'!S44 -> 0.36272339 | M8: ='계산 명세'!S45 -> 0.29457044 | N8: ='계산 명세'!S46 -> 0.2585794 | O8: =MEDIAN(D8:N8) -> 0.60334296 | P8: =MIN(D8:N8) -> 0.2585794 | Q8: =MAX(D8:N8) -> 1.0713967 | R8: =COUNTIF(D8:N8,">0") -> 10 | S8: =COUNT(D8:N8) -> 10 | T8: 전 기간 초과 · 매우 높음
A9: 6 | B9: 램리서치 | C9: LRCX | D9: ='계산 명세'!S290 -> — | E9: ='계산 명세'!S291 -> 0.42055414 | F9: ='계산 명세'!S292 -> 0.55722234 | G9: ='계산 명세'!S293 -> 0.48097307 | H9: ='계산 명세'!S294 -> 0.48903545 | I9: ='계산 명세'!S295 -> 0.74195609 | J9: ='계산 명세'!S296 -> 0.64328038 | K9: ='계산 명세'!S297 -> 0.4939825 | L9: ='계산 명세'!S298 -> 0.38425258 | M9: ='계산 명세'!S299 -> 0.58039171 | N9: ='계산 명세'!S300 -> 0.67721561 | O9: =MEDIAN(D9:N9) -> 0.52560242 | P9: =MIN(D9:N9) -> 0.38425258 | Q9: =MAX(D9:N9) -> 0.74195609 | R9: =COUNTIF(D9:N9,">0") -> 10 | S9: =COUNT(D9:N9) -> 10 | T9: 전 기간 초과 · 매우 높음
A10: 7 | B10: 필립모리스 인터내셔널 | C10: PM | D10: ='계산 명세'!S425 -> 0.47146557 | E10: ='계산 명세'!S426 -> 0.36965867 | F10: ='계산 명세'!S427 -> 0.48295306 | G10: ='계산 명세'!S428 -> 0.45735089 | H10: ='계산 명세'!S429 -> 0.54770167 | I10: ='계산 명세'!S430 -> 0.60607841 | J10: ='계산 명세'!S431 -> 0.3058536 | K10: ='계산 명세'!S432 -> 0.15995382 | L10: ='계산 명세'!S433 -> 0.20106487 | M10: ='계산 명세'!S434 -> 0.2540046 | N10: — | O10: =MEDIAN(D10:N10) -> 0.41350478 | P10: =MIN(D10:N10) -> 0.15995382 | Q10: =MAX(D10:N10) -> 0.60607841 | R10: =COUNTIF(D10:N10,">0") -> 10 | S10: =COUNT(D10:N10) -> 10 | T10: 전 기간 초과 · 매우 높음
A11: 8 | B11: KLA | C11: KLAC | D11: ='계산 명세'!S466 -> — | E11: ='계산 명세'!S467 -> 0.70700967 | F11: ='계산 명세'!S468 -> 0.7306849 | G11: ='계산 명세'!S469 -> 0.34209264 | H11: ='계산 명세'!S470 -> 0.18539867 | I11: ='계산 명세'!S471 -> 0.32946699 | J11: ='계산 명세'!S472 -> 0.45978314 | K11: ='계산 명세'!S473 -> 0.39316571 | L11: ='계산 명세'!S474 -> 0.25845898 | M11: ='계산 명세'!S475 -> 0.3814352 | N11: ='계산 명세'!S476 -> 0.39384768 | O11: =MEDIAN(D11:N11) -> 0.38730046 | P11: =MIN(D11:N11) -> 0.18539867 | Q11: =MAX(D11:N11) -> 0.7306849 | R11: =COUNTIF(D11:N11,">0") -> 10 | S11: =COUNT(D11:N11) -> 10 | T11: 전 기간 초과 · 매우 높음
A12: 9 | B12: 텍사스 인스트루먼츠 | C12: TXN | D12: ='계산 명세'!S455 -> 0.23025274 | E12: ='계산 명세'!S456 -> 0.25874926 | F12: ='계산 명세'!S457 -> 0.46665658 | G12: ='계산 명세'!S458 -> 0.42345662 | H12: ='계산 명세'!S459 -> 0.48491212 | I12: ='계산 명세'!S460 -> 0.65218905 | J12: ='계산 명세'!S461 -> 0.59141421 | K12: ='계산 명세'!S462 -> 0.28080197 | L12: ='계산 명세'!S463 -> 0.12652415 | M12: ='계산 명세'!S464 -> 0.11816561 | N12: — | O12: =MEDIAN(D12:N12) -> 0.3521293 | P12: =MIN(D12:N12) -> 0.11816561 | Q12: =MAX(D12:N12) -> 0.65218905 | R12: =COUNTIF(D12:N12,">0") -> 10 | S12: =COUNT(D12:N12) -> 10 | T12: 전 기간 초과 · 매우 높음
A13: 10 | B13: 메타 플랫폼스 | C13: META | D13: ='계산 명세'!S69 -> 0.26399523 | E13: ='계산 명세'!S70 -> 0.40116142 | F13: ='계산 명세'!S71 -> 0.47426782 | G13: ='계산 명세'!S72 -> 0.30061041 | H13: ='계산 명세'!S73 -> 0.4100437 | I13: ='계산 명세'!S74 -> 0.44362086 | J13: ='계산 명세'!S75 -> 0.17128611 | K13: ='계산 명세'!S76 -> 0.28339008 | L13: ='계산 명세'!S77 -> 0.41066109 | M13: ='계산 명세'!S78 -> 0.25720533 | N13: — | O13: =MEDIAN(D13:N13) -> 0.35088592 | P13: =MIN(D13:N13) -> 0.17128611 | Q13: =MAX(D13:N13) -> 0.47426782 | R13: =COUNTIF(D13:N13,">0") -> 10 | S13: =COUNT(D13:N13) -> 10 | T13: 전 기간 초과 · 매우 높음
A14: 11 | B14: 홈디포 | C14: HD | D14: ='계산 명세'!S357 -> 0.23732645 | E14: ='계산 명세'!S358 -> 0.26789009 | F14: ='계산 명세'!S359 -> 0.37053122 | G14: ='계산 명세'!S360 -> 0.36750761 | H14: ='계산 명세'!S361 -> 0.37051924 | I14: ='계산 명세'!S362 -> 0.40715712 | J14: ='계산 명세'!S363 -> 0.36879831 | K14: ='계산 명세'!S364 -> 0.29534415 | L14: ='계산 명세'!S365 -> 0.22926302 | M14: ='계산 명세'!S366 -> 0.15322002 | N14: — | O14: =MEDIAN(D14:N14) -> 0.33142588 | P14: =MIN(D14:N14) -> 0.15322002 | Q14: =MAX(D14:N14) -> 0.40715712 | R14: =COUNTIF(D14:N14,">0") -> 10 | S14: =COUNT(D14:N14) -> 10 | T14: 전 기간 초과 · 매우 높음
A15: 12 | B15: 어플라이드 머티리얼즈 | C15: AMAT | D15: ='계산 명세'!S247 -> 0.15951577 | E15: ='계산 명세'!S248 -> 0.39561827 | F15: ='계산 명세'!S249 -> 0.29331553 | G15: ='계산 명세'!S250 -> 0.2075528 | H15: ='계산 명세'!S251 -> 0.27548855 | I15: ='계산 명세'!S252 -> 0.43183698 | J15: ='계산 명세'!S253 -> 0.38973181 | K15: ='계산 명세'!S254 -> 0.35172265 | L15: ='계산 명세'!S255 -> 0.33933313 | M15: ='계산 명세'!S256 -> 0.25869747 | N15: — | O15: =MEDIAN(D15:N15) -> 0.31632433 | P15: =MIN(D15:N15) -> 0.15951577 | Q15: =MAX(D15:N15) -> 0.43183698 | R15: =COUNTIF(D15:N15,">0") -> 10 | S15: =COUNT(D15:N15) -> 10 | T15: 전 기간 초과 · 매우 높음
A16: 13 | B16: 알파벳 | C16: GOOG | D16: ='계산 명세'!S25 -> 0.25057615 | E16: ='계산 명세'!S26 -> 0.18246592 | F16: ='계산 명세'!S27 -> 0.28155484 | G16: ='계산 명세'!S28 -> 0.27515751 | H16: ='계산 명세'!S29 -> 0.27023344 | I16: ='계산 명세'!S30 -> 0.47965865 | J16: ='계산 명세'!S31 -> 0.34332262 | K16: ='계산 명세'!S32 -> 0.32386488 | L16: ='계산 명세'!S33 -> 0.337885 | M16: ='계산 명세'!S34 -> 0.26991734 | N16: — | O16: =MEDIAN(D16:N16) -> 0.27835618 | P16: =MIN(D16:N16) -> 0.18246592 | Q16: =MAX(D16:N16) -> 0.47965865 | R16: =COUNTIF(D16:N16,">0") -> 10 | S16: =COUNT(D16:N16) -> 10 | T16: 전 기간 초과 · 매우 높음
A17: 14 | B17: 코스트코 | C17: COST | D17: ='계산 명세'!S270 -> — | E17: ='계산 명세'!S271 -> 0.12346643 | F17: ='계산 명세'!S272 -> 0.16301849 | G17: ='계산 명세'!S273 -> 0.19012249 | H17: ='계산 명세'!S274 -> 0.21652762 | I17: ='계산 명세'!S275 -> 0.28574264 | J17: ='계산 명세'!S276 -> 0.29622213 | K17: ='계산 명세'!S277 -> 0.26989819 | L17: ='계산 명세'!S278 -> 0.30527765 | M17: ='계산 명세'!S279 -> 0.30866036 | N17: ='계산 명세'!S280 -> 0.33636596 | O17: =MEDIAN(D17:N17) -> 0.27782042 | P17: =MIN(D17:N17) -> 0.12346643 | Q17: =MAX(D17:N17) -> 0.33636596 | R17: =COUNTIF(D17:N17,">0") -> 10 | S17: =COUNT(D17:N17) -> 10 | T17: 전 기간 초과 · 매우 높음
A18: 15 | B18: 시스코 시스템즈 | C18: CSCO | D18: ='계산 명세'!S213 -> — | E18: ='계산 명세'!S214 -> 0.23540271 | F18: ='계산 명세'!S215 -> 0.18632795 | G18: ='계산 명세'!S216 -> 0.38206189 | H18: ='계산 명세'!S217 -> 0.35641847 | I18: ='계산 명세'!S218 -> 0.29902668 | J18: ='계산 명세'!S219 -> 0.29096855 | K18: ='계산 명세'!S220 -> 0.3371918 | L18: ='계산 명세'!S221 -> 0.14130883 | M18: ='계산 명세'!S222 -> 0.081338646 | N18: ='계산 명세'!S223 -> 0.1023031 | O18: =MEDIAN(D18:N18) -> 0.26318563 | P18: =MIN(D18:N18) -> 0.081338646 | Q18: =MAX(D18:N18) -> 0.38206189 | R18: =COUNTIF(D18:N18,">0") -> 10 | S18: =COUNT(D18:N18) -> 10 | T18: 전 기간 초과 · 매우 높음
A19: 16 | B19: 비자 | C19: V | D19: ='계산 명세'!S158 -> 0.084723905 | E19: ='계산 명세'!S159 -> 0.087556951 | F19: ='계산 명세'!S160 -> 0.1713166 | G19: ='계산 명세'!S161 -> 0.21017027 | H19: ='계산 명세'!S162 -> 0.17789653 | I19: ='계산 명세'!S163 -> 0.20115233 | J19: ='계산 명세'!S164 -> 0.29001372 | K19: ='계산 명세'!S165 -> 0.33887194 | L19: ='계산 명세'!S166 -> 0.36450313 | M19: ='계산 명세'!S167 -> 0.34761401 | N19: — | O19: =MEDIAN(D19:N19) -> 0.2056613 | P19: =MIN(D19:N19) -> 0.084723905 | Q19: =MAX(D19:N19) -> 0.36450313 | R19: =COUNTIF(D19:N19,">0") -> 10 | S19: =COUNT(D19:N19) -> 10 | T19: 전 기간 초과 · 매우 높음
A20: 17 | B20: 아마존 | C20: AMZN | D20: ='계산 명세'!S48 -> 1.1959004 | E20: ='계산 명세'!S49 -> 0.17742466 | F20: ='계산 명세'!S50 -> 0.35559076 | G20: ='계산 명세'!S51 -> 0.3097221 | H20: ='계산 명세'!S52 -> 0.44755281 | I20: ='계산 명세'!S53 -> 0.22294247 | J20: ='계산 명세'!S54 -> -0.019405951 | K20: ='계산 명세'!S55 -> 0.081324847 | L20: ='계산 명세'!S56 -> 0.17946104 | M20: ='계산 명세'!S57 -> 0.11449257 | N20: — | O20: =MEDIAN(D20:N20) -> 0.20120176 | P20: =MIN(D20:N20) -> -0.019405951 | Q20: =MAX(D20:N20) -> 1.1959004 | R20: =COUNTIF(D20:N20,">0") -> 9 | S20: =COUNT(D20:N20) -> 10 | T20: 대체로 초과
A21: 18 | B21: 일라이 릴리 | C21: LLY | D21: ='계산 명세'!S102 -> 0.045133225 | E21: ='계산 명세'!S103 -> -0.032526103 | F21: ='계산 명세'!S104 -> 0.094721906 | G21: ='계산 명세'!S105 -> 0.19826975 | H21: ='계산 명세'!S106 -> 0.20245991 | I21: ='계산 명세'!S107 -> 0.18208922 | J21: ='계산 명세'!S108 -> 0.17866143 | K21: ='계산 명세'!S109 -> 0.078127524 | L21: ='계산 명세'!S110 -> 0.1774587 | M21: ='계산 명세'!S111 -> 0.29709146 | N21: — | O21: =MEDIAN(D21:N21) -> 0.17806007 | P21: =MIN(D21:N21) -> -0.032526103 | Q21: =MAX(D21:N21) -> 0.29709146 | R21: =COUNTIF(D21:N21,">0") -> 9 | S21: =COUNT(D21:N21) -> 10 | T21: 대체로 초과
