Workbook

Sheet 요약
A1: 버핏 기준 52개 기업 분석
A2: 생성 2026-08-11 08:18 UTC · 미국 50개사 정량 + 한국 2개사 정성
A4: 이 파일 읽는 법
A5: 글자 색 | B5: 파란 글씨는 10-K나 시세에서 그대로 가져온 원천 수치입니다. 검은 글씨는 같은 시트에서 계산한 수식이고, 초록 글씨는 다른 시트를 참조하는 수식입니다. 노란 셀은 바꿔볼 수 있는 가정입니다.
A6: 계산을 따라가는 순서 | B6: 연도별계산 → 품질순위 → DCF계산 → 밸류에이션 순으로 보시면 원천 수치가 비율이 되고, 비율이 점수와 적정가치가 되는 과정이 이어집니다. 각 열의 정의와 산식은 '산식정의' 시트에 정리했습니다.
A7: 가정을 바꾸려면 | B7: '기준표' 시트의 노란 셀을 바꾸면 배점과 적정가치가 함께 움직입니다. 예를 들어 기준 할인율을 10%에서 9%로 낮추면 모든 적정가치가 올라갑니다.
A9: 핵심 결론 | B9: 비금융 41개사 중 36개사가 ROIC로 자본비용을 넘겼지만, 할인율 10% 기준 DCF에서 안전마진 30% 이상인 기업은 0개입니다.
A10: 경계선 | B10: 0개사 (없음). 나머지는 전부 적정가치 추정 범위 밖에서 거래되고 있습니다.
A11: 주주이익 음수 | B11: 2개사 (INTC, AMD). 이익이 없어서가 아니라 설비투자와 운전자본이 순이익을 넘어서기 때문이며, 데이터 공백이 아니라 사업 판정입니다.
A12: 금융업 처리 | B12: 9개사는 ROIC·주주이익을 산출하지 않았습니다. 은행에서 부채는 자금조달이 아니라 원재료라 투하자본이 정의되지 않습니다. SIC 6000~6799 기준.
A13: 한국 2개사 | B13: 삼성전자·SK하이닉스는 정성 분석만 했습니다. DART 접근에 인증키가 필요해 감사받은 1차 출처를 확보할 수 없었고, 기억으로 숫자를 채우지 않았습니다.
A14: 검증 (PHASE 6) | B14: 50/50개사 통과. 각 수치를 해당 10-K 원문의 인라인 XBRL과 대조하고, 인용 접수번호가 EDGAR에 실재하는지 확인하고, 주식수를 재파싱으로 재현했습니다.
A16: 주의 | B16: 이 분석은 '지금 투자 가능 구간 안인가'라는 질문에만 답합니다. 목표주가가 아니며, DCF는 3개 시나리오의 범위로만 읽어야 합니다. 비자의 시가총액은 클래스 B·C 전환분이 빠져 과소평가돼 있어 실제 안전마진은 표시된 값보다 나쁩니다.

Sheet 산식정의
A1: 산식 정의 — 각 열이 어떻게 계산되는가
A2: 시트별로 열 하나하나의 정의와 산식, 그리고 왜 그렇게 계산했는지를 적었습니다.
A4: 시트 | B4: 열 | C4: 산식 | D4: 설명 | E4: 참조 대상
A5: 연도별계산 | B5: 매출 / 세전이익 / 이자비용 / 법인세비용 / 순이익 / 감가상각 / 설비투자 / 자기자본 / 현금 / 단기·장기차입금 / 유동자산 / 유동부채 | C5: 원천 (파란 셀) | D5: 각 회계연도 10-K의 XBRL 태그 값을 그대로 가져온 것. 가공하지 않았습니다. | E5: SEC EDGAR companyfacts, 접수번호 열로 해당 10-K 특정 가능
A6: 연도별계산 | B6: 영업이익(EBIT) | C6: 세전이익 + 이자비용 | D6: 세전이익과 이자비용이 모두 있으면 둘을 더합니다. 릴리·엑슨모빌·IBM·머크·셰브론은 영업이익 소계를 아예 태깅하지 않아, 태그가 있는 회사만 보고된 영업이익을 쓰면 ROIC가 회사마다 다른 것을 뜻하게 됩니다. 그래서 전 종목을 같은 방식으로 맞췄고, 이자비용이 없는 회사만 보고된 영업이익으로 대체합니다. | E6: 같은 행의 원천 셀
A7: 연도별계산 | B7: 실효세율 | C7: 법인세비용 ÷ 세전이익 (5~40%로 제한) | D7: 세전이익이 없거나 음수면 기본 세율 21%를 씁니다. 범위를 벗어나는 값은 일회성 항목의 결과라 한계 세율을 대표하지 못하므로 상·하한을 둡니다. | E7: 기준표의 세율 셀 3개
A8: 연도별계산 | B8: NOPAT | C8: 영업이익(EBIT) × (1 − 실효세율) | D8: 세후 영업이익. ROIC의 분자입니다. | E8: 같은 행
A9: 연도별계산 | B9: 이자부부채 | C9: 단기차입금 + 장기차입금 | D9: 한쪽만 태깅된 경우 나머지는 0으로 봅니다. 잔액이 0이면 태그를 생략하는 것이 관행이기 때문입니다. 양쪽 다 없으면 공란으로 둡니다. | E9: 같은 행
A10: 연도별계산 | B10: 투하자본 | C10: 자기자본 + 이자부부채 − 현금 | D10: 현금을 빼는 이유는 놀고 있는 현금이 사업에 투입된 자본이 아니기 때문입니다. 빼지 않으면 현금이 많은 대형주의 ROIC가 실제보다 낮게 나옵니다. | E10: 같은 행
A11: 연도별계산 | B11: 투하자본(평균) | C11: (당기 투하자본 + 전기 투하자본) ÷ 2 | D11: 기말 잔고를 쓰면 연말에 자본을 조달한 회사가 한 해 내내 그 자본으로 벌어들인 것처럼 보입니다. 전기 값이 없으면 당기 값을 그대로 씁니다. | E11: 같은 행
A12: 연도별계산 | B12: ROIC | C12: NOPAT ÷ 투하자본(평균) | D12: 원칙 1의 핵심 지표. 순위와 배점은 현금을 빼지 않은 '총' 기준을 씁니다 — 현금을 빼는 것이 원칙적으로는 맞지만 보유 현금이 자본 전체에 근접하면 분모가 0에 수렴해 비율이 의미를 잃기 때문입니다. 아리스타의 순ROIC는 96~192%를 오가는 반면 총ROIC는 23~32%입니다. | E12: 같은 행
A13: 연도별계산 | B13: ROE | C13: 순이익 ÷ 자기자본(평균) | D13: 원칙 2에서 ROIC와 비교합니다. | E13: 같은 행
A14: 연도별계산 | B14: ROE−ROIC | C14: ROE − ROIC | D14: 차이가 크면 ROE가 사업의 수익성이 아니라 레버리지에서 나온다는 신호입니다. 다만 자사주 매입으로 자기자본이 줄어도 같은 형태로 벌어지므로 부채 지표를 함께 봐야 합니다. | E14: 같은 행
A15: 연도별계산 | B15: EBITDA | C15: 영업이익(EBIT) + 감가상각 | E15: 같은 행
A16: 연도별계산 | B16: 순부채/EBITDA | C16: (이자부부채 − 현금) ÷ EBITDA | D16: 레버리지 건전성. | E16: 같은 행
A17: 연도별계산 | B17: 이자보상배율 | C17: 영업이익(EBIT) ÷ 이자비용 | D17: 이자를 몇 배로 감당하는지. | E17: 같은 행
A18: 연도별계산 | B18: 운전자본(영업) | C18: 유동자산 − 현금 − (유동부채 − 단기차입금) | D18: 현금과 단기차입금을 빼는 것이 핵심입니다. 유동자산에는 현금이 포함되므로 그대로 두면 현금을 쌓은 회사가 운전자본을 소모한 것처럼 보입니다. 단기차입금은 영업이 아니라 자금조달이라 같은 이유로 뺍니다. | E18: 같은 행
A19: 연도별계산 | B19: 운전자본증감 | C19: 당기 운전자본(영업) − 전기 운전자본(영업) | D19: 양수면 그해 운전자본이 현금을 흡수했다는 뜻입니다. | E19: 같은 행
A20: 연도별계산 | B20: 주주이익 | C20: 순이익 + 감가상각 − 설비투자 − 운전자본증감 | D20: 버핏의 owner earnings 정의입니다. 네 항목이 모두 같은 회계기간이어야 합니다. | E20: 같은 행
A21: 연도별계산 | B21: 주주이익률 / 영업이익률 | C21: 각각 주주이익 ÷ 매출, 영업이익(EBIT) ÷ 매출 | E21: 같은 행
A22: 품질순위 | B22: ROIC 중앙값 · 신규 ROIC · ROIC−WACC · WACC 등 (파란 셀) | C22: 여러 해에 걸친 집계값 | D22: 연도별계산의 여러 행을 걸쳐 계산한 값이라 한 행의 수식으로는 표현되지 않습니다. ROIC 중앙값은 관측된 모든 해의 ROIC 중앙값이고, 신규 ROIC는 (기간말 NOPAT − 기간초 NOPAT) ÷ (기간말 투하자본 − 기간초 투하자본)입니다. | E22: 연도별계산 시트의 해당 기업 행들
A23: 품질순위 | B23: 지속성 비율 | C23: 두자릿수 년수 ÷ 관측 년수 | D23: ROIC가 10%를 넘긴 해의 비율. 높은 평균보다 꾸준함이 해자에 가깝다는 것이 원칙 1의 취지입니다. | E23: 같은 행
A24: 품질순위 | B24: 배점 7개 열 | C24: 각 지표를 기준표의 문턱값과 비교한 조건식 | D24: 셀을 클릭하면 어떤 조건에서 몇 점이 나왔는지 그대로 보입니다. 배점: ROIC 25 · 지속성 20 · 신규 ROIC 20 · 스프레드 15 · 주주이익률 10 · 순부채 5 · 이자보상 5 (합계 100). | E24: 같은 행 + 기준표
A25: 품질순위 | B25: 총점 | C25: 배점 7개 열의 합계 | D25: 백분위가 아니라 절대 기준입니다. | E25: 같은 행
A26: DCF계산 | B26: 적용 성장률 | C26: 과거 주주이익 성장률 × 시나리오 배수, 상한 적용 | D26: 과거 성장률이 없으면 3%를 씁니다. 상한은 보수·기준 10%, 낙관 15%입니다 — 10년을 그보다 빠르게 복리성장한다고 보지 않습니다. | E26: 기준표
A27: DCF계산 | B27: 1~10년차 PV | C27: 기준 주주이익 × (1+성장률)^t ÷ (1+할인율)^t | D27: t년차 주주이익을 현재가치로 할인한 값. | E27: 같은 행
A28: DCF계산 | B28: 영구가치 | C28: 10년차 현금흐름 × (1+영구성장률) ÷ (할인율 − 영구성장률) | D28: 고든 성장 모형. 할인율이 영구성장률 이하면 값이 발산하므로 공란으로 둡니다. | E28: 같은 행
A29: DCF계산 | B29: 적정가치 | C29: 예측기간 PV 합계 + 영구가치 PV | E29: 같은 행
A30: DCF계산 | B30: 안전마진 | C30: (적정가치 − 시가총액) ÷ 적정가치 | D30: 양수면 적정가치보다 싸게 거래된다는 뜻입니다. | E30: 같은 행
A31: DCF계산 | B31: 판정 | C31: 안전마진 ≥ 30% 투자가능 / ≥ 0% 경계선 / 그 외 범위밖 | D31: 목표주가가 아니라 '지금 투자 가능 구간 안인가'에 대한 답입니다. | E31: 기준표
A32: 밸류에이션 | B32: PER / PBR / PSR | C32: 시가총액 ÷ (최근 순이익 / 자기자본 / 매출) | D32: PER은 순이익이 양수일 때만 계산합니다. 적자에서는 의미가 없습니다. | E32: 같은 행
A33: 밸류에이션 | B33: 기준 적정가치 · 안전마진 · 판정 | C33: DCF계산 시트의 기준 시나리오 행 참조 | D33: 초록 글씨는 다른 시트를 가리킵니다. 클릭하면 해당 행으로 따라갈 수 있습니다. | E33: DCF계산
A34: 전체 | B34: 시가총액 | C34: 10-K 표지의 주식수 × 최근 종가 | D34: 표지 주식수는 결산일보다 최신이고 클래스별로 나뉘어 있어 합산했습니다. 버크셔는 A주를 B주 1,500배로 환산했습니다. 비자는 클래스 B·C의 전환비율이 이사회 재량이라 클래스 A만 썼고, 그만큼 시가총액이 과소평가돼 있습니다. | E34: SEC 10-K 표지 인라인 XBRL + 거래소 종가
A35: 전체 | B35: 주식수 시계열 | C35: 액면분할 기준을 통일한 뒤 비교 | D35: 각 연도 주식수는 그해 10-K의 단위로 기록되는데 10-K는 직전 2년까지만 소급 수정하므로, 분할을 가로지르면 신주 발행처럼 보입니다. 조정 전 엔비디아는 연 41% 희석으로 나왔으나 실제로는 4:1과 10:1 분할이었습니다. 정수가 아닌 비율(델 1806:1000, GE 1281:1000)은 스핀오프에 따른 주가 조정이라 적용하지 않았습니다. | E35: 거래소 분할 이력

Sheet 기준표
A1: 기준표 — 가정과 판정 기준
A2: 노란 셀은 바꿀 수 있는 가정입니다. 다른 시트의 수식이 이 셀들을 참조하므로, 값을 바꾸면 점수와 적정가치가 함께 움직입니다.
A4: 항목 | B4: 값 | C4: 설명
A5: 세율
A6: 실효세율 하한 | B6: 0.05 | C6: 이보다 낮은 실효세율은 일회성 항목의 결과로 보고 하한을 적용
A7: 실효세율 상한 | B7: 0.4 | C7: 이보다 높은 실효세율도 마찬가지로 상한을 적용
A8: 기본 세율 | B8: 0.21 | C8: 세전이익이 없거나 음수여서 실효세율을 낼 수 없을 때 쓰는 미국 연방 법정세율
A9: 품질 배점 기준
A10: ROIC 25점 기준 | B10: 0.3 | C10: ROIC 중앙값이 이 이상이면 25점
A11: ROIC 20점 기준 | B11: 0.2
A12: ROIC 15점 기준 | B12: 0.15
A13: ROIC 10점 기준 | B13: 0.1
A14: 신규ROIC 20점 기준 | B14: 0.2 | C14: 증분 ROIC가 이 이상이면 20점
A15: 신규ROIC 15점 기준 | B15: 0.15
A16: 신규ROIC 10점 기준 | B16: 0.1
A17: 스프레드 15점 기준 | B17: 0.15 | C17: ROIC−WACC가 이 이상이면 15점
A18: 스프레드 12점 기준 | B18: 0.1
A19: 스프레드 8점 기준 | B19: 0.05
A20: 주주이익률 10점 기준 | B20: 0.2 | C20: 정규화 주주이익 ÷ 매출이 이 이상이면 10점
A21: 주주이익률 7점 기준 | B21: 0.1
A22: 주주이익률 4점 기준 | B22: 0.05
A23: 순부채 5점 기준 | B23: 1 | C23: 순부채/EBITDA가 이 이하면 5점
A24: 순부채 4점 기준 | B24: 2
A25: 순부채 2점 기준 | B25: 3
A26: 이자보상 5점 기준 | B26: 10 | C26: 이자보상배율이 이 이상이면 5점
A27: 이자보상 3점 기준 | B27: 5
A28: 이자보상 1점 기준 | B28: 2
A29: DCF 가정
A30: 예측기간(년) | B30: 10 | C30: 명시적으로 현금흐름을 추정하는 기간
A31: 보수 할인율 | B31: 0.12
A32: 보수 영구성장률 | B32: 0.02
A33: 보수 성장률 배수 | B33: 0.5 | C33: 과거 주주이익 성장률에 곱하는 배수
A34: 기준 할인율 | B34: 0.1
A35: 기준 영구성장률 | B35: 0.025
A36: 기준 성장률 배수 | B36: 1
A37: 낙관 할인율 | B37: 0.08
A38: 낙관 영구성장률 | B38: 0.03
A39: 낙관 성장률 배수 | B39: 1.25
A40: 성장률 상한(보수·기준) | B40: 0.1 | C40: 10년을 이 속도보다 빠르게 복리성장한다고 보지 않음
A41: 성장률 상한(낙관) | B41: 0.15
...

Sheet 연도별계산
A1: 연도별 계산 — 원천 수치와 그로부터 나온 모든 비율
A2: 파란 셀은 10-K에서 그대로 가져온 원천 수치이고, 검은 셀은 같은 행의 파란 셀로 계산한 수식입니다. 어떤 비율이든 셀을 클릭하면 수식 입력줄에 계산이 그대로 보입니다. 금액 단위는 십억 USD. 접수번호로 해당 10-K를 특정할 수 있습니다.
A4: 티커 | B4: 기업 | C4: 회계연도 | D4: 결산일 | E4: 업종구분 | F4: 접수번호 | G4: 매출 | H4: 세전이익 | I4: 이자비용 | J4: 법인세비용 | K4: 영업이익(보고) | L4: 순이익 | M4: 감가상각 | N4: 설비투자 | O4: 영업현금흐름 | P4: 자기자본 | Q4: 자기자본(전기) | R4: 현금 | S4: 현금(전기) | T4: 단기차입금 | U4: 단기차입금(전기) | V4: 장기차입금 | W4: 유동자산 | X4: 유동자산(전기) | Y4: 유동부채 | Z4: 유동부채(전기) | AA4: 투하자본(전기) | AB4: 주식수(백만주) | AC4: 영업이익(EBIT) | AD4: 실효세율 | AE4: NOPAT | AF4: 이자부부채 | AG4: 투하자본 | AH4: 투하자본(평균) | AI4: ROIC(순) | AJ4: 투하자본(총) | AK4: ROIC(총) | AL4: 자기자본(평균) | AM4: ROE | AN4: ROE−ROIC | AO4: EBITDA | AP4: 순부채/EBITDA | AQ4: 이자보상배율 | AR4: 운전자본(영업) | AS4: 운전자본(전기) | AT4: 운전자본증감 | AU4: 주주이익 | AV4: 주주이익 산출방식 | AW4: 주주이익률 | AX4: 영업이익률
A5: NVDA | B5: NVIDIA CORP | C5: 2014 | D5: 2015-01-25 | E5: 일반 | F5: 0001045810-17-000027 | G5: 4.682 | J5: 0.124 | K5: 0.759 | L5: 0.631 | M5: 0.143 | O5: 0.906 | P5: 4.418 | R5: 4.623 | V5: 1.384 | W5: 5.713 | Y5: 0.896 | AB5: 21800 | AC5: =IF(AND(ISNUMBER(H5),ISNUMBER(I5)),H5+I5,IF(ISNUMBER(K5),K5,IF(ISNUMBER(H5),H5,""))) | AD5: =IF(OR(NOT(ISNUMBER(J5)),NOT(ISNUMBER(H5)),H5<=0),기준표!$B$8,MIN(MAX(J5/H5,기준표!$B$6),기준표!$B$7)) | AE5: =IF(ISNUMBER(AC5),AC5*(1-AD5),"") | AF5: =IF(AND(NOT(ISNUMBER(T5)),NOT(ISNUMBER(V5))),"",IF(ISNUMBER(T5),T5,0)+IF(ISNUMBER(V5),V5,0)) | AG5: =IF(E5="금융","",IF(AND(ISNUMBER(P5),ISNUMBER(AF5),ISNUMBER(R5)),P5+AF5-R5,"")) | AH5: =IF(E5="금융","",IF(NOT(ISNUMBER(AG5)),"",IF(ISNUMBER(AA5),(AG5+AA5)/2,AG5))) | AI5: =IF(AND(ISNUMBER(AE5),ISNUMBER(AH5),AH5>0),AE5/AH5,"") | AJ5: =IF(E5="금융","",IF(AND(ISNUMBER(P5),ISNUMBER(AF5)),P5+AF5,"")) | AK5: =IF(OR(NOT(ISNUMBER(AE5)),NOT(ISNUMBER(AJ5)),AJ5<=0),"",IF(AND(ISNUMBER(G5),AJ5<0.1*G5),"",AE5/AJ5)) | AL5: =IF(NOT(ISNUMBER(P5)),"",IF(ISNUMBER(Q5),(P5+Q5)/2,P5)) | AM5: =IF(AND(ISNUMBER(L5),ISNUMBER(AL5),AL5>0),L5/AL5,"") | AN5: =IF(AND(ISNUMBER(AM5),ISNUMBER({ROIC})),AM5-{ROIC},"") | AO5: =IF(AND(ISNUMBER(AC5),ISNUMBER(M5)),AC5+M5,"") | AP5: =IF(AND(ISNUMBER(AF5),ISNUMBER(R5),ISNUMBER(AO5),AO5>0),(AF5-R5)/AO5,"") | AQ5: =IF(AND(ISNUMBER(AC5),ISNUMBER(I5),I5<>0,AC5>0),AC5/I5,"") | AR5: =IF(AND(ISNUMBER(W5),ISNUMBER(Y5)),W5-IF(ISNUMBER(R5),R5,0)-(Y5-IF(ISNUMBER(T5),T5,0)),"") | AS5: =IF(AND(ISNUMBER(X5),ISNUMBER(Z5)),X5-IF(ISNUMBER(S5),S5,0)-(Z5-IF(ISNUMBER(U5),U5,0)),"") | AT5: =IF(AND(ISNUMBER(AR5),ISNUMBER(AS5)),AR5-AS5,"") | AU5: =IF(E5="금융","",IF(AND(ISNUMBER(L5),ISNUMBER(M5),ISNUMBER(N5),ISNUMBER(AT5)),L5+M5-N5-AT5,IF(AND(ISNUMBER(O5),ISNUMBER(N5)),O5-N5,""))) | AV5: =IF(E5="금융","금융업 - 정의되지 않음",IF(AND(ISNUMBER(L5),ISNUMBER(M5),ISNUMBER(N5),ISNUMBER(AT5)),"순이익+감가상각-설비투자-운전자본증감",IF(AND(ISNUMBER(O5),ISNUMBER(N5)),"영업현금흐름-설비투자","산출불가"))) | AW5: =IF(AND(ISNUMBER(AU5),ISNUMBER(G5),G5<>0),AU5/G5,"") | AX5: =IF(AND(ISNUMBER(AC5),ISNUMBER(G5),G5<>0),AC5/G5,"")
A6: NVDA | B6: NVIDIA CORP | C6: 2015 | D6: 2016-01-31 | E6: 일반 | F6: 0001045810-18-000010 | G6: 5.01 | J6: 0.129 | K6: 0.747 | L6: 0.614 | M6: 0.124 | O6: 1.175 | P6: 4.469 | Q6: 4.418 | R6: 5.037 | S6: 4.623 | V6: 0 | W6: 6.053 | X6: 5.713 | Y6: 2.351 | Z6: 0.896 | AA6: 1.179 | AB6: 21560 | AC6: =IF(AND(ISNUMBER(H6),ISNUMBER(I6)),H6+I6,IF(ISNUMBER(K6),K6,IF(ISNUMBER(H6),H6,""))) | AD6: =IF(OR(NOT(ISNUMBER(J6)),NOT(ISNUMBER(H6)),H6<=0),기준표!$B$8,MIN(MAX(J6/H6,기준표!$B$6),기준표!$B$7)) | AE6: =IF(ISNUMBER(AC6),AC6*(1-AD6),"") | AF6: =IF(AND(NOT(ISNUMBER(T6)),NOT(ISNUMBER(V6))),"",IF(ISNUMBER(T6),T6,0)+IF(ISNUMBER(V6),V6,0)) | AG6: =IF(E6="금융","",IF(AND(ISNUMBER(P6),ISNUMBER(AF6),ISNUMBER(R6)),P6+AF6-R6,"")) | AH6: =IF(E6="금융","",IF(NOT(ISNUMBER(AG6)),"",IF(ISNUMBER(AA6),(AG6+AA6)/2,AG6))) | AI6: =IF(AND(ISNUMBER(AE6),ISNUMBER(AH6),AH6>0),AE6/AH6,"") | AJ6: =IF(E6="금융","",IF(AND(ISNUMBER(P6),ISNUMBER(AF6)),P6+AF6,"")) | AK6: =IF(OR(NOT(ISNUMBER(AE6)),NOT(ISNUMBER(AJ6)),AJ6<=0),"",IF(AND(ISNUMBER(G6),AJ6<0.1*G6),"",AE6/AJ6)) | AL6: =IF(NOT(ISNUMBER(P6)),"",IF(ISNUMBER(Q6),(P6+Q6)/2,P6)) | AM6: =IF(AND(ISNUMBER(L6),ISNUMBER(AL6),AL6>0),L6/AL6,"") | AN6: =IF(AND(ISNUMBER(AM6),ISNUMBER({ROIC})),AM6-{ROIC},"") | AO6: =IF(AND(ISNUMBER(AC6),ISNUMBER(M6)),AC6+M6,"") | AP6: =IF(AND(ISNUMBER(AF6),ISNUMBER(R6),ISNUMBER(AO6),AO6>0),(AF6-R6)/AO6,"") | AQ6: =IF(AND(ISNUMBER(AC6),ISNUMBER(I6),I6<>0,AC6>0),AC6/I6,"") | AR6: =IF(AND(ISNUMBER(W6),ISNUMBER(Y6)),W6-IF(ISNUMBER(R6),R6,0)-(Y6-IF(ISNUMBER(T6),T6,0)),"") | AS6: =IF(AND(ISNUMBER(X6),ISNUMBER(Z6)),X6-IF(ISNUMBER(S6),S6,0)-(Z6-IF(ISNUMBER(U6),U6,0)),"") | AT6: =IF(AND(ISNUMBER(AR6),ISNUMBER(AS6)),AR6-AS6,"") | AU6: =IF(E6="금융","",IF(AND(ISNUMBER(L6),ISNUMBER(M6),ISNUMBER(N6),ISNUMBER(AT6)),L6+M6-N6-AT6,IF(AND(ISNUMBER(O6),ISNUMBER(N6)),O6-N6,""))) | AV6: =IF(E6="금융","금융업 - 정의되지 않음",IF(AND(ISNUMBER(L6),ISNUMBER(M6),ISNUMBER(N6),ISNUMBER(AT6)),"순이익+감가상각-설비투자-운전자본증감",IF(AND(ISNUMBER(O6),ISNUMBER(N6)),"영업현금흐름-설비투자","산출불가"))) | AW6: =IF(AND(ISNUMBER(AU6),ISNUMBER(G6),G6<>0),AU6/G6,"") | AX6: =IF(AND(ISNUMBER(AC6),ISNUMBER(G6),G6<>0),AC6/G6,"")
A7: NVDA | B7: NVIDIA CORP | C7: 2016 | D7: 2017-01-29 | E7: 일반 | F7: 0001045810-19-000023 | G7: 6.91 | J7: 0.239 | K7: 1.934 | L7: 1.666 | M7: 0.118 | O7: 1.672 | P7: 5.762 | Q7: 4.469 | R7: 6.798 | S7: 5.037 | V7: 1.983 | W7: 8.536 | X7: 6.053 | Y7: 1.788 | Z7: 2.351 | AA7: -0.568 | AB7: 23400 | AC7: =IF(AND(ISNUMBER(H7),ISNUMBER(I7)),H7+I7,IF(ISNUMBER(K7),K7,IF(ISNUMBER(H7),H7,""))) | AD7: =IF(OR(NOT(ISNUMBER(J7)),NOT(ISNUMBER(H7)),H7<=0),기준표!$B$8,MIN(MAX(J7/H7,기준표!$B$6),기준표!$B$7)) | AE7: =IF(ISNUMBER(AC7),AC7*(1-AD7),"") | AF7: =IF(AND(NOT(ISNUMBER(T7)),NOT(ISNUMBER(V7))),"",IF(ISNUMBER(T7),T7,0)+IF(ISNUMBER(V7),V7,0)) | AG7: =IF(E7="금융","",IF(AND(ISNUMBER(P7),ISNUMBER(AF7),ISNUMBER(R7)),P7+AF7-R7,"")) | AH7: =IF(E7="금융","",IF(NOT(ISNUMBER(AG7)),"",IF(ISNUMBER(AA7),(AG7+AA7)/2,AG7))) | AI7: =IF(AND(ISNUMBER(AE7),ISNUMBER(AH7),AH7>0),AE7/AH7,"") | AJ7: =IF(E7="금융","",IF(AND(ISNUMBER(P7),ISNUMBER(AF7)),P7+AF7,"")) | AK7: =IF(OR(NOT(ISNUMBER(AE7)),NOT(ISNUMBER(AJ7)),AJ7<=0),"",IF(AND(ISNUMBER(G7),AJ7<0.1*G7),"",AE7/AJ7)) | AL7: =IF(NOT(ISNUMBER(P7)),"",IF(ISNUMBER(Q7),(P7+Q7)/2,P7)) | AM7: =IF(AND(ISNUMBER(L7),ISNUMBER(AL7),AL7>0),L7/AL7,"") | AN7: =IF(AND(ISNUMBER(AM7),ISNUMBER({ROIC})),AM7-{ROIC},"") | AO7: =IF(AND(ISNUMBER(AC7),ISNUMBER(M7)),AC7+M7,"") | AP7: =IF(AND(ISNUMBER(AF7),ISNUMBER(R7),ISNUMBER(AO7),AO7>0),(AF7-R7)/AO7,"") | AQ7: =IF(AND(ISNUMBER(AC7),ISNUMBER(I7),I7<>0,AC7>0),AC7/I7,"") | AR7: =IF(AND(ISNUMBER(W7),ISNUMBER(Y7)),W7-IF(ISNUMBER(R7),R7,0)-(Y7-IF(ISNUMBER(T7),T7,0)),"") | AS7: =IF(AND(ISNUMBER(X7),ISNUMBER(Z7)),X7-IF(ISNUMBER(S7),S7,0)-(Z7-IF(ISNUMBER(U7),U7,0)),"") | AT7: =IF(AND(ISNUMBER(AR7),ISNUMBER(AS7)),AR7-AS7,"") | AU7: =IF(E7="금융","",IF(AND(ISNUMBER(L7),ISNUMBER(M7),ISNUMBER(N7),ISNUMBER(AT7)),L7+M7-N7-AT7,IF(AND(ISNUMBER(O7),ISNUMBER(N7)),O7-N7,""))) | AV7: =IF(E7="금융","금융업 - 정의되지 않음",IF(AND(ISNUMBER(L7),ISNUMBER(M7),ISNUMBER(N7),ISNUMBER(AT7)),"순이익+감가상각-설비투자-운전자본증감",IF(AND(ISNUMBER(O7),ISNUMBER(N7)),"영업현금흐름-설비투자","산출불가"))) | AW7: =IF(AND(ISNUMBER(AU7),ISNUMBER(G7),G7<>0),AU7/G7,"") | AX7: =IF(AND(ISNUMBER(AC7),ISNUMBER(G7),G7<>0),AC7/G7,"")
A8: NVDA | B8: NVIDIA CORP | C8: 2017 | D8: 2018-01-28 | E8: 일반 | F8: 0001045810-20-000010 | G8: 9.714 | J8: 0.149 | K8: 3.21 | L8: 3.047 | M8: 0.144 | O8: 3.502 | P8: 7.471 | Q8: 5.762 | R8: 7.108 | S8: 6.798 | V8: 1.985 | W8: 9.255 | X8: 8.536 | Y8: 1.153 | Z8: 1.788 | AA8: 0.947 | AB8: 24240 | AC8: =IF(AND(ISNUMBER(H8),ISNUMBER(I8)),H8+I8,IF(ISNUMBER(K8),K8,IF(ISNUMBER(H8),H8,""))) | AD8: =IF(OR(NOT(ISNUMBER(J8)),NOT(ISNUMBER(H8)),H8<=0),기준표!$B$8,MIN(MAX(J8/H8,기준표!$B$6),기준표!$B$7)) | AE8: =IF(ISNUMBER(AC8),AC8*(1-AD8),"") | AF8: =IF(AND(NOT(ISNUMBER(T8)),NOT(ISNUMBER(V8))),"",IF(ISNUMBER(T8),T8,0)+IF(ISNUMBER(V8),V8,0)) | AG8: =IF(E8="금융","",IF(AND(ISNUMBER(P8),ISNUMBER(AF8),ISNUMBER(R8)),P8+AF8-R8,"")) | AH8: =IF(E8="금융","",IF(NOT(ISNUMBER(AG8)),"",IF(ISNUMBER(AA8),(AG8+AA8)/2,AG8))) | AI8: =IF(AND(ISNUMBER(AE8),ISNUMBER(AH8),AH8>0),AE8/AH8,"") | AJ8: =IF(E8="금융","",IF(AND(ISNUMBER(P8),ISNUMBER(AF8)),P8+AF8,"")) | AK8: =IF(OR(NOT(ISNUMBER(AE8)),NOT(ISNUMBER(AJ8)),AJ8<=0),"",IF(AND(ISNUMBER(G8),AJ8<0.1*G8),"",AE8/AJ8)) | AL8: =IF(NOT(ISNUMBER(P8)),"",IF(ISNUMBER(Q8),(P8+Q8)/2,P8)) | AM8: =IF(AND(ISNUMBER(L8),ISNUMBER(AL8),AL8>0),L8/AL8,"") | AN8: =IF(AND(ISNUMBER(AM8),ISNUMBER({ROIC})),AM8-{ROIC},"") | AO8: =IF(AND(ISNUMBER(AC8),ISNUMBER(M8)),AC8+M8,"") | AP8: =IF(AND(ISNUMBER(AF8),ISNUMBER(R8),ISNUMBER(AO8),AO8>0),(AF8-R8)/AO8,"") | AQ8: =IF(AND(ISNUMBER(AC8),ISNUMBER(I8),I8<>0,AC8>0),AC8/I8,"") | AR8: =IF(AND(ISNUMBER(W8),ISNUMBER(Y8)),W8-IF(ISNUMBER(R8),R8,0)-(Y8-IF(ISNUMBER(T8),T8,0)),"") | AS8: =IF(AND(ISNUMBER(X8),ISNUMBER(Z8)),X8-IF(ISNUMBER(S8),S8,0)-(Z8-IF(ISNUMBER(U8),U8,0)),"") | AT8: =IF(AND(ISNUMBER(AR8),ISNUMBER(AS8)),AR8-AS8,"") | AU8: =IF(E8="금융","",IF(AND(ISNUMBER(L8),ISNUMBER(M8),ISNUMBER(N8),ISNUMBER(AT8)),L8+M8-N8-AT8,IF(AND(ISNUMBER(O8),ISNUMBER(N8)),O8-N8,""))) | AV8: =IF(E8="금융","금융업 - 정의되지 않음",IF(AND(ISNUMBER(L8),ISNUMBER(M8),ISNUMBER(N8),ISNUMBER(AT8)),"순이익+감가상각-설비투자-운전자본증감",IF(AND(ISNUMBER(O8),ISNUMBER(N8)),"영업현금흐름-설비투자","산출불가"))) | AW8: =IF(AND(ISNUMBER(AU8),ISNUMBER(G8),G8<>0),AU8/G8,"") | AX8: =IF(AND(ISNUMBER(AC8),ISNUMBER(G8),G8<>0),AC8/G8,"")
A9: NVDA | B9: NVIDIA CORP | C9: 2018 | D9: 2019-01-27 | E9: 일반 | F9: 0001045810-21-000010 | G9: 11.716 | J9: -0.245 | K9: 3.804 | L9: 4.141 | M9: 0.233 | O9: 3.743 | P9: 9.342 | Q9: 7.471 | R9: 7.422 | S9: 7.108 | V9: 1.988 | W9: 10.557 | X9: 9.255 | Y9: 1.329 | Z9: 1.153 | AA9: 2.348 | AB9: 24240 | AC9: =IF(AND(ISNUMBER(H9),ISNUMBER(I9)),H9+I9,IF(ISNUMBER(K9),K9,IF(ISNUMBER(H9),H9,""))) | AD9: =IF(OR(NOT(ISNUMBER(J9)),NOT(ISNUMBER(H9)),H9<=0),기준표!$B$8,MIN(MAX(J9/H9,기준표!$B$6),기준표!$B$7)) | AE9: =IF(ISNUMBER(AC9),AC9*(1-AD9),"") | AF9: =IF(AND(NOT(ISNUMBER(T9)),NOT(ISNUMBER(V9))),"",IF(ISNUMBER(T9),T9,0)+IF(ISNUMBER(V9),V9,0)) | AG9: =IF(E9="금융","",IF(AND(ISNUMBER(P9),ISNUMBER(AF9),ISNUMBER(R9)),P9+AF9-R9,"")) | AH9: =IF(E9="금융","",IF(NOT(ISNUMBER(AG9)),"",IF(ISNUMBER(AA9),(AG9+AA9)/2,AG9))) | AI9: =IF(AND(ISNUMBER(AE9),ISNUMBER(AH9),AH9>0),AE9/AH9,"") | AJ9: =IF(E9="금융","",IF(AND(ISNUMBER(P9),ISNUMBER(AF9)),P9+AF9,"")) | AK9: =IF(OR(NOT(ISNUMBER(AE9)),NOT(ISNUMBER(AJ9)),AJ9<=0),"",IF(AND(ISNUMBER(G9),AJ9<0.1*G9),"",AE9/AJ9)) | AL9: =IF(NOT(ISNUMBER(P9)),"",IF(ISNUMBER(Q9),(P9+Q9)/2,P9)) | AM9: =IF(AND(ISNUMBER(L9),ISNUMBER(AL9),AL9>0),L9/AL9,"") | AN9: =IF(AND(ISNUMBER(AM9),ISNUMBER({ROIC})),AM9-{ROIC},"") | AO9: =IF(AND(ISNUMBER(AC9),ISNUMBER(M9)),AC9+M9,"") | AP9: =IF(AND(ISNUMBER(AF9),ISNUMBER(R9),ISNUMBER(AO9),AO9>0),(AF9-R9)/AO9,"") | AQ9: =IF(AND(ISNUMBER(AC9),ISNUMBER(I9),I9<>0,AC9>0),AC9/I9,"") | AR9: =IF(AND(ISNUMBER(W9),ISNUMBER(Y9)),W9-IF(ISNUMBER(R9),R9,0)-(Y9-IF(ISNUMBER(T9),T9,0)),"") | AS9: =IF(AND(ISNUMBER(X9),ISNUMBER(Z9)),X9-IF(ISNUMBER(S9),S9,0)-(Z9-IF(ISNUMBER(U9),U9,0)),"") | AT9: =IF(AND(ISNUMBER(AR9),ISNUMBER(AS9)),AR9-AS9,"") | AU9: =IF(E9="금융","",IF(AND(ISNUMBER(L9),ISNUMBER(M9),ISNUMBER(N9),ISNUMBER(AT9)),L9+M9-N9-AT9,IF(AND(ISNUMBER(O9),ISNUMBER(N9)),O9-N9,""))) | AV9: =IF(E9="금융","금융업 - 정의되지 않음",IF(AND(ISNUMBER(L9),ISNUMBER(M9),ISNUMBER(N9),ISNUMBER(AT9)),"순이익+감가상각-설비투자-운전자본증감",IF(AND(ISNUMBER(O9),ISNUMBER(N9)),"영업현금흐름-설비투자","산출불가"))) | AW9: =IF(AND(ISNUMBER(AU9),ISNUMBER(G9),G9<>0),AU9/G9,"") | AX9: =IF(AND(ISNUMBER(AC9),ISNUMBER(G9),G9<>0),AC9/G9,"")
A10: NVDA | B10: NVIDIA CORP | C10: 2019 | D10: 2020-01-26 | E10: 일반 | F10: 0001045810-22-000036 | G10: 10.918 | H10: 2.97 | J10: 0.174 | K10: 2.846 | L10: 2.796 | M10: 0.355 | O10: 4.761 | P10: 12.204 | Q10: 9.342 | R10: 10.897 | S10: 7.422 | T10: 0 | V10: 1.991 | W10: 13.69 | X10: 10.557 | Y10: 1.784 | Z10: 1.329 | AA10: 3.908 | AB10: 24480 | AC10: =IF(AND(ISNUMBER(H10),ISNUMBER(I10)),H10+I10,IF(ISNUMBER(K10),K10,IF(ISNUMBER(H10),H10,""))) | AD10: =IF(OR(NOT(ISNUMBER(J10)),NOT(ISNUMBER(H10)),H10<=0),기준표!$B$8,MIN(MAX(J10/H10,기준표!$B$6),기준표!$B$7)) | AE10: =IF(ISNUMBER(AC10),AC10*(1-AD10),"") | AF10: =IF(AND(NOT(ISNUMBER(T10)),NOT(ISNUMBER(V10))),"",IF(ISNUMBER(T10),T10,0)+IF(ISNUMBER(V10),V10,0)) | AG10: =IF(E10="금융","",IF(AND(ISNUMBER(P10),ISNUMBER(AF10),ISNUMBER(R10)),P10+AF10-R10,"")) | AH10: =IF(E10="금융","",IF(NOT(ISNUMBER(AG10)),"",IF(ISNUMBER(AA10),(AG10+AA10)/2,AG10))) | AI10: =IF(AND(ISNUMBER(AE10),ISNUMBER(AH10),AH10>0),AE10/AH10,"") | AJ10: =IF(E10="금융","",IF(AND(ISNUMBER(P10),ISNUMBER(AF10)),P10+AF10,"")) | AK10: =IF(OR(NOT(ISNUMBER(AE10)),NOT(ISNUMBER(AJ10)),AJ10<=0),"",IF(AND(ISNUMBER(G10),AJ10<0.1*G10),"",AE10/AJ10)) | AL10: =IF(NOT(ISNUMBER(P10)),"",IF(ISNUMBER(Q10),(P10+Q10)/2,P10)) | AM10: =IF(AND(ISNUMBER(L10),ISNUMBER(AL10),AL10>0),L10/AL10,"") | AN10: =IF(AND(ISNUMBER(AM10),ISNUMBER({ROIC})),AM10-{ROIC},"") | AO10: =IF(AND(ISNUMBER(AC10),ISNUMBER(M10)),AC10+M10,"") | AP10: =IF(AND(ISNUMBER(AF10),ISNUMBER(R10),ISNUMBER(AO10),AO10>0),(AF10-R10)/AO10,"") | AQ10: =IF(AND(ISNUMBER(AC10),ISNUMBER(I10),I10<>0,AC10>0),AC10/I10,"") | AR10: =IF(AND(ISNUMBER(W10),ISNUMBER(Y10)),W10-IF(ISNUMBER(R10),R10,0)-(Y10-IF(ISNUMBER(T10),T10,0)),"") | AS10: =IF(AND(ISNUMBER(X10),ISNUMBER(Z10)),X10-IF(ISNUMBER(S10),S10,0)-(Z10-IF(ISNUMBER(U10),U10,0)),"") | AT10: =IF(AND(ISNUMBER(AR10),ISNUMBER(AS10)),AR10-AS10,"") | AU10: =IF(E10="금융","",IF(AND(ISNUMBER(L10),ISNUMBER(M10),ISNUMBER(N10),ISNUMBER(AT10)),L10+M10-N10-AT10,IF(AND(ISNUMBER(O10),ISNUMBER(N10)),O10-N10,""))) | AV10: =IF(E10="금융","금융업 - 정의되지 않음",IF(AND(ISNUMBER(L10),ISNUMBER(M10),ISNUMBER(N10),ISNUMBER(AT10)),"순이익+감가상각-설비투자-운전자본증감",IF(AND(ISNUMBER(O10),ISNUMBER(N10)),"영업현금흐름-설비투자","산출불가"))) | AW10: =IF(AND(ISNUMBER(AU10),ISNUMBER(G10),G10<>0),AU10/G10,"") | AX10: =IF(AND(ISNUMBER(AC10),ISNUMBER(G10),G10<>0),AC10/G10,"")
A11: NVDA | B11: NVIDIA CORP | C11: 2020 | D11: 2021-01-31 | E11: 일반 | F11: 0001045810-23-000017 | G11: 16.675 | H11: 4.409 | J11: 0.077 | K11: 4.532 | L11: 4.332 | M11: 0.486 | O11: 5.822 | P11: 16.893 | Q11: 12.204 | R11: 11.561 | S11: 10.897 | T11: 0.999 | U11: 0 | V11: 6.963 | W11: 16.055 | X11: 13.69 | Y11: 3.925 | Z11: 1.784 | AA11: 3.298 | AB11: 24790 | AC11: =IF(AND(ISNUMBER(H11),ISNUMBER(I11)),H11+I11,IF(ISNUMBER(K11),K11,IF(ISNUMBER(H11),H11,""))) | AD11: =IF(OR(NOT(ISNUMBER(J11)),NOT(ISNUMBER(H11)),H11<=0),기준표!$B$8,MIN(MAX(J11/H11,기준표!$B$6),기준표!$B$7)) | AE11: =IF(ISNUMBER(AC11),AC11*(1-AD11),"") | AF11: =IF(AND(NOT(ISNUMBER(T11)),NOT(ISNUMBER(V11))),"",IF(ISNUMBER(T11),T11,0)+IF(ISNUMBER(V11),V11,0)) | AG11: =IF(E11="금융","",IF(AND(ISNUMBER(P11),ISNUMBER(AF11),ISNUMBER(R11)),P11+AF11-R11,"")) | AH11: =IF(E11="금융","",IF(NOT(ISNUMBER(AG11)),"",IF(ISNUMBER(AA11),(AG11+AA11)/2,AG11))) | AI11: =IF(AND(ISNUMBER(AE11),ISNUMBER(AH11),AH11>0),AE11/AH11,"") | AJ11: =IF(E11="금융","",IF(AND(ISNUMBER(P11),ISNUMBER(AF11)),P11+AF11,"")) | AK11: =IF(OR(NOT(ISNUMBER(AE11)),NOT(ISNUMBER(AJ11)),AJ11<=0),"",IF(AND(ISNUMBER(G11),AJ11<0.1*G11),"",AE11/AJ11)) | AL11: =IF(NOT(ISNUMBER(P11)),"",IF(ISNUMBER(Q11),(P11+Q11)/2,P11)) | AM11: =IF(AND(ISNUMBER(L11),ISNUMBER(AL11),AL11>0),L11/AL11,"") | AN11: =IF(AND(ISNUMBER(AM11),ISNUMBER({ROIC})),AM11-{ROIC},"") | AO11: =IF(AND(ISNUMBER(AC11),ISNUMBER(M11)),AC11+M11,"") | AP11: =IF(AND(ISNUMBER(AF11),ISNUMBER(R11),ISNUMBER(AO11),AO11>0),(AF11-R11)/AO11,"") | AQ11: =IF(AND(ISNUMBER(AC11),ISNUMBER(I11),I11<>0,AC11>0),AC11/I11,"") | AR11: =IF(AND(ISNUMBER(W11),ISNUMBER(Y11)),W11-IF(ISNUMBER(R11),R11,0)-(Y11-IF(ISNUMBER(T11),T11,0)),"") | AS11: =IF(AND(ISNUMBER(X11),ISNUMBER(Z11)),X11-IF(ISNUMBER(S11),S11,0)-(Z11-IF(ISNUMBER(U11),U11,0)),"") | AT11: =IF(AND(ISNUMBER(AR11),ISNUMBER(AS11)),AR11-AS11,"") | AU11: =IF(E11="금융","",IF(AND(ISNUMBER(L11),ISNUMBER(M11),ISNUMBER(N11),ISNUMBER(AT11)),L11+M11-N11-AT11,IF(AND(ISNUMBER(O11),ISNUMBER(N11)),O11-N11,""))) | AV11: =IF(E11="금융","금융업 - 정의되지 않음",IF(AND(ISNUMBER(L11),ISNUMBER(M11),ISNUMBER(N11),ISNUMBER(AT11)),"순이익+감가상각-설비투자-운전자본증감",IF(AND(ISNUMBER(O11),ISNUMBER(N11)),"영업현금흐름-설비투자","산출불가"))) | AW11: =IF(AND(ISNUMBER(AU11),ISNUMBER(G11),G11<>0),AU11/G11,"") | AX11: =IF(AND(ISNUMBER(AC11),ISNUMBER(G11),G11<>0),AC11/G11,"")
A12: NVDA | B12: NVIDIA CORP | C12: 2021 | D12: 2022-01-30 | E12: 일반 | F12: 0001045810-24-000029 | G12: 26.914 | H12: 9.941 | J12: 0.189 | K12: 10.041 | L12: 9.752 | M12: 0.611 | N12: 0.976 | O12: 9.108 | P12: 26.612 | Q12: 16.893 | R12: 21.208 | S12: 11.561 | T12: 0 | U12: 0.999 | V12: 10.946 | W12: 28.829 | X12: 16.055 | Y12: 4.335 | Z12: 3.925 | AA12: 13.294 | AB12: 25060 | AC12: =IF(AND(ISNUMBER(H12),ISNUMBER(I12)),H12+I12,IF(ISNUMBER(K12),K12,IF(ISNUMBER(H12),H12,""))) | AD12: =IF(OR(NOT(ISNUMBER(J12)),NOT(ISNUMBER(H12)),H12<=0),기준표!$B$8,MIN(MAX(J12/H12,기준표!$B$6),기준표!$B$7)) | AE12: =IF(ISNUMBER(AC12),AC12*(1-AD12),"") | AF12: =IF(AND(NOT(ISNUMBER(T12)),NOT(ISNUMBER(V12))),"",IF(ISNUMBER(T12),T12,0)+IF(ISNUMBER(V12),V12,0)) | AG12: =IF(E12="금융","",IF(AND(ISNUMBER(P12),ISNUMBER(AF12),ISNUMBER(R12)),P12+AF12-R12,"")) | AH12: =IF(E12="금융","",IF(NOT(ISNUMBER(AG12)),"",IF(ISNUMBER(AA12),(AG12+AA12)/2,AG12))) | AI12: =IF(AND(ISNUMBER(AE12),ISNUMBER(AH12),AH12>0),AE12/AH12,"") | AJ12: =IF(E12="금융","",IF(AND(ISNUMBER(P12),ISNUMBER(AF12)),P12+AF12,"")) | AK12: =IF(OR(NOT(ISNUMBER(AE12)),NOT(ISNUMBER(AJ12)),AJ12<=0),"",IF(AND(ISNUMBER(G12),AJ12<0.1*G12),"",AE12/AJ12)) | AL12: =IF(NOT(ISNUMBER(P12)),"",IF(ISNUMBER(Q12),(P12+Q12)/2,P12)) | AM12: =IF(AND(ISNUMBER(L12),ISNUMBER(AL12),AL12>0),L12/AL12,"") | AN12: =IF(AND(ISNUMBER(AM12),ISNUMBER({ROIC})),AM12-{ROIC},"") | AO12: =IF(AND(ISNUMBER(AC12),ISNUMBER(M12)),AC12+M12,"") | AP12: =IF(AND(ISNUMBER(AF12),ISNUMBER(R12),ISNUMBER(AO12),AO12>0),(AF12-R12)/AO12,"") | AQ12: =IF(AND(ISNUMBER(AC12),ISNUMBER(I12),I12<>0,AC12>0),AC12/I12,"") | AR12: =IF(AND(ISNUMBER(W12),ISNUMBER(Y12)),W12-IF(ISNUMBER(R12),R12,0)-(Y12-IF(ISNUMBER(T12),T12,0)),"") | AS12: =IF(AND(ISNUMBER(X12),ISNUMBER(Z12)),X12-IF(ISNUMBER(S12),S12,0)-(Z12-IF(ISNUMBER(U12),U12,0)),"") | AT12: =IF(AND(ISNUMBER(AR12),ISNUMBER(AS12)),AR12-AS12,"") | AU12: =IF(E12="금융","",IF(AND(ISNUMBER(L12),ISNUMBER(M12),ISNUMBER(N12),ISNUMBER(AT12)),L12+M12-N12-AT12,IF(AND(ISNUMBER(O12),ISNUMBER(N12)),O12-N12,""))) | AV12: =IF(E12="금융","금융업 - 정의되지 않음",IF(AND(ISNUMBER(L12),ISNUMBER(M12),ISNUMBER(N12),ISNUMBER(AT12)),"순이익+감가상각-설비투자-운전자본증감",IF(AND(ISNUMBER(O12),ISNUMBER(N12)),"영업현금흐름-설비투자","산출불가"))) | AW12: =IF(AND(ISNUMBER(AU12),ISNUMBER(G12),G12<>0),AU12/G12,"") | AX12: =IF(AND(ISNUMBER(AC12),ISNUMBER(G12),G12<>0),AC12/G12,"")
A13: NVDA | B13: NVIDIA CORP | C13: 2022 | D13: 2023-01-29 | E13: 일반 | F13: 0001045810-25-000023 | G13: 26.974 | H13: 4.181 | I13: 0.262 | J13: -0.187 | K13: 4.224 | L13: 4.368 | M13: 0.844 | N13: 1.833 | O13: 5.641 | P13: 22.101 | Q13: 26.612 | R13: 13.296 | S13: 21.208 | T13: 1.25 | U13: 0 | V13: 10.953 | W13: 23.073 | X13: 28.829 | Y13: 6.563 | Z13: 4.335 | AA13: 16.35 | AB13: 24660 | AC13: =IF(AND(ISNUMBER(H13),ISNUMBER(I13)),H13+I13,IF(ISNUMBER(K13),K13,IF(ISNUMBER(H13),H13,""))) | AD13: =IF(OR(NOT(ISNUMBER(J13)),NOT(ISNUMBER(H13)),H13<=0),기준표!$B$8,MIN(MAX(J13/H13,기준표!$B$6),기준표!$B$7)) | AE13: =IF(ISNUMBER(AC13),AC13*(1-AD13),"") | AF13: =IF(AND(NOT(ISNUMBER(T13)),NOT(ISNUMBER(V13))),"",IF(ISNUMBER(T13),T13,0)+IF(ISNUMBER(V13),V13,0)) | AG13: =IF(E13="금융","",IF(AND(ISNUMBER(P13),ISNUMBER(AF13),ISNUMBER(R13)),P13+AF13-R13,"")) | AH13: =IF(E13="금융","",IF(NOT(ISNUMBER(AG13)),"",IF(ISNUMBER(AA13),(AG13+AA13)/2,AG13))) | AI13: =IF(AND(ISNUMBER(AE13),ISNUMBER(AH13),AH13>0),AE13/AH13,"") | AJ13: =IF(E13="금융","",IF(AND(ISNUMBER(P13),ISNUMBER(AF13)),P13+AF13,"")) | AK13: =IF(OR(NOT(ISNUMBER(AE13)),NOT(ISNUMBER(AJ13)),AJ13<=0),"",IF(AND(ISNUMBER(G13),AJ13<0.1*G13),"",AE13/AJ13)) | AL13: =IF(NOT(ISNUMBER(P13)),"",IF(ISNUMBER(Q13),(P13+Q13)/2,P13)) | AM13: =IF(AND(ISNUMBER(L13),ISNUMBER(AL13),AL13>0),L13/AL13,"") | AN13: =IF(AND(ISNUMBER(AM13),ISNUMBER({ROIC})),AM13-{ROIC},"") | AO13: =IF(AND(ISNUMBER(AC13),ISNUMBER(M13)),AC13+M13,"") | AP13: =IF(AND(ISNUMBER(AF13),ISNUMBER(R13),ISNUMBER(AO13),AO13>0),(AF13-R13)/AO13,"") | AQ13: =IF(AND(ISNUMBER(AC13),ISNUMBER(I13),I13<>0,AC13>0),AC13/I13,"") | AR13: =IF(AND(ISNUMBER(W13),ISNUMBER(Y13)),W13-IF(ISNUMBER(R13),R13,0)-(Y13-IF(ISNUMBER(T13),T13,0)),"") | AS13: =IF(AND(ISNUMBER(X13),ISNUMBER(Z13)),X13-IF(ISNUMBER(S13),S13,0)-(Z13-IF(ISNUMBER(U13),U13,0)),"") | AT13: =IF(AND(ISNUMBER(AR13),ISNUMBER(AS13)),AR13-AS13,"") | AU13: =IF(E13="금융","",IF(AND(ISNUMBER(L13),ISNUMBER(M13),ISNUMBER(N13),ISNUMBER(AT13)),L13+M13-N13-AT13,IF(AND(ISNUMBER(O13),ISNUMBER(N13)),O13-N13,""))) | AV13: =IF(E13="금융","금융업 - 정의되지 않음",IF(AND(ISNUMBER(L13),ISNUMBER(M13),ISNUMBER(N13),ISNUMBER(AT13)),"순이익+감가상각-설비투자-운전자본증감",IF(AND(ISNUMBER(O13),ISNUMBER(N13)),"영업현금흐름-설비투자","산출불가"))) | AW13: =IF(AND(ISNUMBER(AU13),ISNUMBER(G13),G13<>0),AU13/G13,"") | AX13: =IF(AND(ISNUMBER(AC13),ISNUMBER(G13),G13<>0),AC13/G13,"")
A14: NVDA | B14: NVIDIA CORP | C14: 2023 | D14: 2024-01-28 | E14: 일반 | F14: 0001045810-26-000021 | G14: 60.922 | H14: 33.818 | I14: 0.257 | J14: 4.058 | K14: 32.972 | L14: 29.76 | M14: 0.894 | N14: 1.069 | O14: 28.09 | P14: 42.978 | Q14: 22.101 | R14: 25.984 | S14: 13.296 | T14: 1.25 | U14: 1.25 | V14: 9.709 | W14: 44.345 | X14: 23.073 | Y14: 10.631 | Z14: 6.563 | AA14: 21.008 | AB14: 24643 | AC14: =IF(AND(ISNUMBER(H14),ISNUMBER(I14)),H14+I14,IF(ISNUMBER(K14),K14,IF(ISNUMBER(H14),H14,""))) | AD14: =IF(OR(NOT(ISNUMBER(J14)),NOT(ISNUMBER(H14)),H14<=0),기준표!$B$8,MIN(MAX(J14/H14,기준표!$B$6),기준표!$B$7)) | AE14: =IF(ISNUMBER(AC14),AC14*(1-AD14),"") | AF14: =IF(AND(NOT(ISNUMBER(T14)),NOT(ISNUMBER(V14))),"",IF(ISNUMBER(T14),T14,0)+IF(ISNUMBER(V14),V14,0)) | AG14: =IF(E14="금융","",IF(AND(ISNUMBER(P14),ISNUMBER(AF14),ISNUMBER(R14)),P14+AF14-R14,"")) | AH14: =IF(E14="금융","",IF(NOT(ISNUMBER(AG14)),"",IF(ISNUMBER(AA14),(AG14+AA14)/2,AG14))) | AI14: =IF(AND(ISNUMBER(AE14),ISNUMBER(AH14),AH14>0),AE14/AH14,"") | AJ14: =IF(E14="금융","",IF(AND(ISNUMBER(P14),ISNUMBER(AF14)),P14+AF14,"")) | AK14: =IF(OR(NOT(ISNUMBER(AE14)),NOT(ISNUMBER(AJ14)),AJ14<=0),"",IF(AND(ISNUMBER(G14),AJ14<0.1*G14),"",AE14/AJ14)) | AL14: =IF(NOT(ISNUMBER(P14)),"",IF(ISNUMBER(Q14),(P14+Q14)/2,P14)) | AM14: =IF(AND(ISNUMBER(L14),ISNUMBER(AL14),AL14>0),L14/AL14,"") | AN14: =IF(AND(ISNUMBER(AM14),ISNUMBER({ROIC})),AM14-{ROIC},"") | AO14: =IF(AND(ISNUMBER(AC14),ISNUMBER(M14)),AC14+M14,"") | AP14: =IF(AND(ISNUMBER(AF14),ISNUMBER(R14),ISNUMBER(AO14),AO14>0),(AF14-R14)/AO14,"") | AQ14: =IF(AND(ISNUMBER(AC14),ISNUMBER(I14),I14<>0,AC14>0),AC14/I14,"") | AR14: =IF(AND(ISNUMBER(W14),ISNUMBER(Y14)),W14-IF(ISNUMBER(R14),R14,0)-(Y14-IF(ISNUMBER(T14),T14,0)),"") | AS14: =IF(AND(ISNUMBER(X14),ISNUMBER(Z14)),X14-IF(ISNUMBER(S14),S14,0)-(Z14-IF(ISNUMBER(U14),U14,0)),"") | AT14: =IF(AND(ISNUMBER(AR14),ISNUMBER(AS14)),AR14-AS14,"") | AU14: =IF(E14="금융","",IF(AND(ISNUMBER(L14),ISNUMBER(M14),ISNUMBER(N14),ISNUMBER(AT14)),L14+M14-N14-AT14,IF(AND(ISNUMBER(O14),ISNUMBER(N14)),O14-N14,""))) | AV14: =IF(E14="금융","금융업 - 정의되지 않음",IF(AND(ISNUMBER(L14),ISNUMBER(M14),ISNUMBER(N14),ISNUMBER(AT14)),"순이익+감가상각-설비투자-운전자본증감",IF(AND(ISNUMBER(O14),ISNUMBER(N14)),"영업현금흐름-설비투자","산출불가"))) | AW14: =IF(AND(ISNUMBER(AU14),ISNUMBER(G14),G14<>0),AU14/G14,"") | AX14: =IF(AND(ISNUMBER(AC14),ISNUMBER(G14),G14<>0),AC14/G14,"")
A15: NVDA | B15: NVIDIA CORP | C15: 2024 | D15: 2025-01-26 | E15: 일반 | F15: 0001045810-26-000021 | G15: 130.497 | H15: 84.026 | I15: 0.247 | J15: 11.146 | K15: 81.453 | L15: 72.88 | M15: 1.3 | N15: 3.236 | O15: 64.089 | P15: 79.327 | Q15: 42.978 | R15: 43.21 | S15: 25.984 | T15: 0 | U15: 1.25 | V15: 8.463 | W15: 80.126 | X15: 44.345 | Y15: 18.047 | Z15: 10.631 | AA15: 27.953 | AB15: 24477 | AC15: =IF(AND(ISNUMBER(H15),ISNUMBER(I15)),H15+I15,IF(ISNUMBER(K15),K15,IF(ISNUMBER(H15),H15,""))) | AD15: =IF(OR(NOT(ISNUMBER(J15)),NOT(ISNUMBER(H15)),H15<=0),기준표!$B$8,MIN(MAX(J15/H15,기준표!$B$6),기준표!$B$7)) | AE15: =IF(ISNUMBER(AC15),AC15*(1-AD15),"") | AF15: =IF(AND(NOT(ISNUMBER(T15)),NOT(ISNUMBER(V15))),"",IF(ISNUMBER(T15),T15,0)+IF(ISNUMBER(V15),V15,0)) | AG15: =IF(E15="금융","",IF(AND(ISNUMBER(P15),ISNUMBER(AF15),ISNUMBER(R15)),P15+AF15-R15,"")) | AH15: =IF(E15="금융","",IF(NOT(ISNUMBER(AG15)),"",IF(ISNUMBER(AA15),(AG15+AA15)/2,AG15))) | AI15: =IF(AND(ISNUMBER(AE15),ISNUMBER(AH15),AH15>0),AE15/AH15,"") | AJ15: =IF(E15="금융","",IF(AND(ISNUMBER(P15),ISNUMBER(AF15)),P15+AF15,"")) | AK15: =IF(OR(NOT(ISNUMBER(AE15)),NOT(ISNUMBER(AJ15)),AJ15<=0),"",IF(AND(ISNUMBER(G15),AJ15<0.1*G15),"",AE15/AJ15)) | AL15: =IF(NOT(ISNUMBER(P15)),"",IF(ISNUMBER(Q15),(P15+Q15)/2,P15)) | AM15: =IF(AND(ISNUMBER(L15),ISNUMBER(AL15),AL15>0),L15/AL15,"") | AN15: =IF(AND(ISNUMBER(AM15),ISNUMBER({ROIC})),AM15-{ROIC},"") | AO15: =IF(AND(ISNUMBER(AC15),ISNUMBER(M15)),AC15+M15,"") | AP15: =IF(AND(ISNUMBER(AF15),ISNUMBER(R15),ISNUMBER(AO15),AO15>0),(AF15-R15)/AO15,"") | AQ15: =IF(AND(ISNUMBER(AC15),ISNUMBER(I15),I15<>0,AC15>0),AC15/I15,"") | AR15: =IF(AND(ISNUMBER(W15),ISNUMBER(Y15)),W15-IF(ISNUMBER(R15),R15,0)-(Y15-IF(ISNUMBER(T15),T15,0)),"") | AS15: =IF(AND(ISNUMBER(X15),ISNUMBER(Z15)),X15-IF(ISNUMBER(S15),S15,0)-(Z15-IF(ISNUMBER(U15),U15,0)),"") | AT15: =IF(AND(ISNUMBER(AR15),ISNUMBER(AS15)),AR15-AS15,"") | AU15: =IF(E15="금융","",IF(AND(ISNUMBER(L15),ISNUMBER(M15),ISNUMBER(N15),ISNUMBER(AT15)),L15+M15-N15-AT15,IF(AND(ISNUMBER(O15),ISNUMBER(N15)),O15-N15,""))) | AV15: =IF(E15="금융","금융업 - 정의되지 않음",IF(AND(ISNUMBER(L15),ISNUMBER(M15),ISNUMBER(N15),ISNUMBER(AT15)),"순이익+감가상각-설비투자-운전자본증감",IF(AND(ISNUMBER(O15),ISNUMBER(N15)),"영업현금흐름-설비투자","산출불가"))) | AW15: =IF(AND(ISNUMBER(AU15),ISNUMBER(G15),G15<>0),AU15/G15,"") | AX15: =IF(AND(ISNUMBER(AC15),ISNUMBER(G15),G15<>0),AC15/G15,"")
A16: NVDA | B16: NVIDIA CORP | C16: 2025 | D16: 2026-01-25 | E16: 일반 | F16: 0001045810-26-000021 | G16: 215.938 | H16: 141.45 | I16: 0.259 | J16: 21.383 | K16: 130.387 | L16: 120.067 | M16: 2.4 | N16: 6.042 | O16: 102.718 | P16: 157.293 | Q16: 79.327 | R16: 10.605 | S16: 43.21 | T16: 0.999 | U16: 0 | V16: 8.468 | W16: 125.605 | X16: 80.126 | Y16: 32.163 | Z16: 18.047 | AA16: 44.58 | AB16: 24304 | AC16: =IF(AND(ISNUMBER(H16),ISNUMBER(I16)),H16+I16,IF(ISNUMBER(K16),K16,IF(ISNUMBER(H16),H16,""))) | AD16: =IF(OR(NOT(ISNUMBER(J16)),NOT(ISNUMBER(H16)),H16<=0),기준표!$B$8,MIN(MAX(J16/H16,기준표!$B$6),기준표!$B$7)) | AE16: =IF(ISNUMBER(AC16),AC16*(1-AD16),"") | AF16: =IF(AND(NOT(ISNUMBER(T16)),NOT(ISNUMBER(V16))),"",IF(ISNUMBER(T16),T16,0)+IF(ISNUMBER(V16),V16,0)) | AG16: =IF(E16="금융","",IF(AND(ISNUMBER(P16),ISNUMBER(AF16),ISNUMBER(R16)),P16+AF16-R16,"")) | AH16: =IF(E16="금융","",IF(NOT(ISNUMBER(AG16)),"",IF(ISNUMBER(AA16),(AG16+AA16)/2,AG16))) | AI16: =IF(AND(ISNUMBER(AE16),ISNUMBER(AH16),AH16>0),AE16/AH16,"") | AJ16: =IF(E16="금융","",IF(AND(ISNUMBER(P16),ISNUMBER(AF16)),P16+AF16,"")) | AK16: =IF(OR(NOT(ISNUMBER(AE16)),NOT(ISNUMBER(AJ16)),AJ16<=0),"",IF(AND(ISNUMBER(G16),AJ16<0.1*G16),"",AE16/AJ16)) | AL16: =IF(NOT(ISNUMBER(P16)),"",IF(ISNUMBER(Q16),(P16+Q16)/2,P16)) | AM16: =IF(AND(ISNUMBER(L16),ISNUMBER(AL16),AL16>0),L16/AL16,"") | AN16: =IF(AND(ISNUMBER(AM16),ISNUMBER({ROIC})),AM16-{ROIC},"") | AO16: =IF(AND(ISNUMBER(AC16),ISNUMBER(M16)),AC16+M16,"") | AP16: =IF(AND(ISNUMBER(AF16),ISNUMBER(R16),ISNUMBER(AO16),AO16>0),(AF16-R16)/AO16,"") | AQ16: =IF(AND(ISNUMBER(AC16),ISNUMBER(I16),I16<>0,AC16>0),AC16/I16,"") | AR16: =IF(AND(ISNUMBER(W16),ISNUMBER(Y16)),W16-IF(ISNUMBER(R16),R16,0)-(Y16-IF(ISNUMBER(T16),T16,0)),"") | AS16: =IF(AND(ISNUMBER(X16),ISNUMBER(Z16)),X16-IF(ISNUMBER(S16),S16,0)-(Z16-IF(ISNUMBER(U16),U16,0)),"") | AT16: =IF(AND(ISNUMBER(AR16),ISNUMBER(AS16)),AR16-AS16,"") | AU16: =IF(E16="금융","",IF(AND(ISNUMBER(L16),ISNUMBER(M16),ISNUMBER(N16),ISNUMBER(AT16)),L16+M16-N16-AT16,IF(AND(ISNUMBER(O16),ISNUMBER(N16)),O16-N16,""))) | AV16: =IF(E16="금융","금융업 - 정의되지 않음",IF(AND(ISNUMBER(L16),ISNUMBER(M16),ISNUMBER(N16),ISNUMBER(AT16)),"순이익+감가상각-설비투자-운전자본증감",IF(AND(ISNUMBER(O16),ISNUMBER(N16)),"영업현금흐름-설비투자","산출불가"))) | AW16: =IF(AND(ISNUMBER(AU16),ISNUMBER(G16),G16<>0),AU16/G16,"") | AX16: =IF(AND(ISNUMBER(AC16),ISNUMBER(G16),G16<>0),AC16/G16,"")
A17: AAPL | B17: Apple Inc. | C17: 2014 | D17: 2014-09-27 | E17: 일반 | F17: 0001628280-16-020309 | H17: 53.483 | I17: 0.384 | J17: 13.973 | K17: 52.503 | L17: 39.51 | N17: 9.571 | P17: 111.547 | R17: 13.844 | T17: 0 | V17: 28.987 | W17: 68.531 | Y17: 63.448 | AB17: 23464.644 | AC17: =IF(AND(ISNUMBER(H17),ISNUMBER(I17)),H17+I17,IF(ISNUMBER(K17),K17,IF(ISNUMBER(H17),H17,""))) | AD17: =IF(OR(NOT(ISNUMBER(J17)),NOT(ISNUMBER(H17)),H17<=0),기준표!$B$8,MIN(MAX(J17/H17,기준표!$B$6),기준표!$B$7)) | AE17: =IF(ISNUMBER(AC17),AC17*(1-AD17),"") | AF17: =IF(AND(NOT(ISNUMBER(T17)),NOT(ISNUMBER(V17))),"",IF(ISNUMBER(T17),T17,0)+IF(ISNUMBER(V17),V17,0)) | AG17: =IF(E17="금융","",IF(AND(ISNUMBER(P17),ISNUMBER(AF17),ISNUMBER(R17)),P17+AF17-R17,"")) | AH17: =IF(E17="금융","",IF(NOT(ISNUMBER(AG17)),"",IF(ISNUMBER(AA17),(AG17+AA17)/2,AG17))) | AI17: =IF(AND(ISNUMBER(AE17),ISNUMBER(AH17),AH17>0),AE17/AH17,"") | AJ17: =IF(E17="금융","",IF(AND(ISNUMBER(P17),ISNUMBER(AF17)),P17+AF17,"")) | AK17: =IF(OR(NOT(ISNUMBER(AE17)),NOT(ISNUMBER(AJ17)),AJ17<=0),"",IF(AND(ISNUMBER(G17),AJ17<0.1*G17),"",AE17/AJ17)) | AL17: =IF(NOT(ISNUMBER(P17)),"",IF(ISNUMBER(Q17),(P17+Q17)/2,P17)) | AM17: =IF(AND(ISNUMBER(L17),ISNUMBER(AL17),AL17>0),L17/AL17,"") | AN17: =IF(AND(ISNUMBER(AM17),ISNUMBER({ROIC})),AM17-{ROIC},"") | AO17: =IF(AND(ISNUMBER(AC17),ISNUMBER(M17)),AC17+M17,"") | AP17: =IF(AND(ISNUMBER(AF17),ISNUMBER(R17),ISNUMBER(AO17),AO17>0),(AF17-R17)/AO17,"") | AQ17: =IF(AND(ISNUMBER(AC17),ISNUMBER(I17),I17<>0,AC17>0),AC17/I17,"") | AR17: =IF(AND(ISNUMBER(W17),ISNUMBER(Y17)),W17-IF(ISNUMBER(R17),R17,0)-(Y17-IF(ISNUMBER(T17),T17,0)),"") | AS17: =IF(AND(ISNUMBER(X17),ISNUMBER(Z17)),X17-IF(ISNUMBER(S17),S17,0)-(Z17-IF(ISNUMBER(U17),U17,0)),"") | AT17: =IF(AND(ISNUMBER(AR17),ISNUMBER(AS17)),AR17-AS17,"") | AU17: =IF(E17="금융","",IF(AND(ISNUMBER(L17),ISNUMBER(M17),ISNUMBER(N17),ISNUMBER(AT17)),L17+M17-N17-AT17,IF(AND(ISNUMBER(O17),ISNUMBER(N17)),O17-N17,""))) | AV17: =IF(E17="금융","금융업 - 정의되지 않음",IF(AND(ISNUMBER(L17),ISNUMBER(M17),ISNUMBER(N17),ISNUMBER(AT17)),"순이익+감가상각-설비투자-운전자본증감",IF(AND(ISNUMBER(O17),ISNUMBER(N17)),"영업현금흐름-설비투자","산출불가"))) | AW17: =IF(AND(ISNUMBER(AU17),ISNUMBER(G17),G17<>0),AU17/G17,"") | AX17: =IF(AND(ISNUMBER(AC17),ISNUMBER(G17),G17<>0),AC17/G17,"")
A18: AAPL | B18: Apple Inc. | C18: 2015 | D18: 2015-09-26 | E18: 일반 | F18: 0000320193-17-000070 | H18: 72.515 | I18: 0.733 | J18: 19.121 | K18: 71.23 | L18: 53.394 | M18: 9.2 | N18: 11.247 | O18: 81.266 | P18: 119.355 | Q18: 111.547 | R18: 21.12 | S18: 13.844 | T18: 2.5 | U18: 0 | V18: 53.329 | W18: 89.378 | X18: 68.531 | Y18: 80.61 | Z18: 63.448 | AA18: 126.69 | AB18: 22315.012 | AC18: =IF(AND(ISNUMBER(H18),ISNUMBER(I18)),H18+I18,IF(ISNUMBER(K18),K18,IF(ISNUMBER(H18),H18,""))) | AD18: =IF(OR(NOT(ISNUMBER(J18)),NOT(ISNUMBER(H18)),H18<=0),기준표!$B$8,MIN(MAX(J18/H18,기준표!$B$6),기준표!$B$7)) | AE18: =IF(ISNUMBER(AC18),AC18*(1-AD18),"") | AF18: =IF(AND(NOT(ISNUMBER(T18)),NOT(ISNUMBER(V18))),"",IF(ISNUMBER(T18),T18,0)+IF(ISNUMBER(V18),V18,0)) | AG18: =IF(E18="금융","",IF(AND(ISNUMBER(P18),ISNUMBER(AF18),ISNUMBER(R18)),P18+AF18-R18,"")) | AH18: =IF(E18="금융","",IF(NOT(ISNUMBER(AG18)),"",IF(ISNUMBER(AA18),(AG18+AA18)/2,AG18))) | AI18: =IF(AND(ISNUMBER(AE18),ISNUMBER(AH18),AH18>0),AE18/AH18,"") | AJ18: =IF(E18="금융","",IF(AND(ISNUMBER(P18),ISNUMBER(AF18)),P18+AF18,"")) | AK18: =IF(OR(NOT(ISNUMBER(AE18)),NOT(ISNUMBER(AJ18)),AJ18<=0),"",IF(AND(ISNUMBER(G18),AJ18<0.1*G18),"",AE18/AJ18)) | AL18: =IF(NOT(ISNUMBER(P18)),"",IF(ISNUMBER(Q18),(P18+Q18)/2,P18)) | AM18: =IF(AND(ISNUMBER(L18),ISNUMBER(AL18),AL18>0),L18/AL18,"") | AN18: =IF(AND(ISNUMBER(AM18),ISNUMBER({ROIC})),AM18-{ROIC},"") | AO18: =IF(AND(ISNUMBER(AC18),ISNUMBER(M18)),AC18+M18,"") | AP18: =IF(AND(ISNUMBER(AF18),ISNUMBER(R18),ISNUMBER(AO18),AO18>0),(AF18-R18)/AO18,"") | AQ18: =IF(AND(ISNUMBER(AC18),ISNUMBER(I18),I18<>0,AC18>0),AC18/I18,"") | AR18: =IF(AND(ISNUMBER(W18),ISNUMBER(Y18)),W18-IF(ISNUMBER(R18),R18,0)-(Y18-IF(ISNUMBER(T18),T18,0)),"") | AS18: =IF(AND(ISNUMBER(X18),ISNUMBER(Z18)),X18-IF(ISNUMBER(S18),S18,0)-(Z18-IF(ISNUMBER(U18),U18,0)),"") | AT18: =IF(AND(ISNUMBER(AR18),ISNUMBER(AS18)),AR18-AS18,"") | AU18: =IF(E18="금융","",IF(AND(ISNUMBER(L18),ISNUMBER(M18),ISNUMBER(N18),ISNUMBER(AT18)),L18+M18-N18-AT18,IF(AND(ISNUMBER(O18),ISNUMBER(N18)),O18-N18,""))) | AV18: =IF(E18="금융","금융업 - 정의되지 않음",IF(AND(ISNUMBER(L18),ISNUMBER(M18),ISNUMBER(N18),ISNUMBER(AT18)),"순이익+감가상각-설비투자-운전자본증감",IF(AND(ISNUMBER(O18),ISNUMBER(N18)),"영업현금흐름-설비투자","산출불가"))) | AW18: =IF(AND(ISNUMBER(AU18),ISNUMBER(G18),G18<>0),AU18/G18,"") | AX18: =IF(AND(ISNUMBER(AC18),ISNUMBER(G18),G18<>0),AC18/G18,"")
A19: AAPL | B19: Apple Inc. | C19: 2016 | D19: 2016-09-24 | E19: 일반 | F19: 0000320193-18-000145 | H19: 61.372 | I19: 1.456 | J19: 15.685 | K19: 60.024 | L19: 45.687 | M19: 10.505 | N19: 12.734 | O19: 66.231 | P19: 128.249 | Q19: 119.355 | R19: 20.484 | S19: 21.12 | T19: 3.5 | U19: 2.5 | V19: 75.427 | W19: 106.869 | X19: 89.378 | Y19: 79.006 | Z19: 80.61 | AA19: 154.064 | AB19: 21344.664 | AC19: =IF(AND(ISNUMBER(H19),ISNUMBER(I19)),H19+I19,IF(ISNUMBER(K19),K19,IF(ISNUMBER(H19),H19,""))) | AD19: =IF(OR(NOT(ISNUMBER(J19)),NOT(ISNUMBER(H19)),H19<=0),기준표!$B$8,MIN(MAX(J19/H19,기준표!$B$6),기준표!$B$7)) | AE19: =IF(ISNUMBER(AC19),AC19*(1-AD19),"") | AF19: =IF(AND(NOT(ISNUMBER(T19)),NOT(ISNUMBER(V19))),"",IF(ISNUMBER(T19),T19,0)+IF(ISNUMBER(V19),V19,0)) | AG19: =IF(E19="금융","",IF(AND(ISNUMBER(P19),ISNUMBER(AF19),ISNUMBER(R19)),P19+AF19-R19,"")) | AH19: =IF(E19="금융","",IF(NOT(ISNUMBER(AG19)),"",IF(ISNUMBER(AA19),(AG19+AA19)/2,AG19))) | AI19: =IF(AND(ISNUMBER(AE19),ISNUMBER(AH19),AH19>0),AE19/AH19,"") | AJ19: =IF(E19="금융","",IF(AND(ISNUMBER(P19),ISNUMBER(AF19)),P19+AF19,"")) | AK19: =IF(OR(NOT(ISNUMBER(AE19)),NOT(ISNUMBER(AJ19)),AJ19<=0),"",IF(AND(ISNUMBER(G19),AJ19<0.1*G19),"",AE19/AJ19)) | AL19: =IF(NOT(ISNUMBER(P19)),"",IF(ISNUMBER(Q19),(P19+Q19)/2,P19)) | AM19: =IF(AND(ISNUMBER(L19),ISNUMBER(AL19),AL19>0),L19/AL19,"") | AN19: =IF(AND(ISNUMBER(AM19),ISNUMBER({ROIC})),AM19-{ROIC},"") | AO19: =IF(AND(ISNUMBER(AC19),ISNUMBER(M19)),AC19+M19,"") | AP19: =IF(AND(ISNUMBER(AF19),ISNUMBER(R19),ISNUMBER(AO19),AO19>0),(AF19-R19)/AO19,"") | AQ19: =IF(AND(ISNUMBER(AC19),ISNUMBER(I19),I19<>0,AC19>0),AC19/I19,"") | AR19: =IF(AND(ISNUMBER(W19),ISNUMBER(Y19)),W19-IF(ISNUMBER(R19),R19,0)-(Y19-IF(ISNUMBER(T19),T19,0)),"") | AS19: =IF(AND(ISNUMBER(X19),ISNUMBER(Z19)),X19-IF(ISNUMBER(S19),S19,0)-(Z19-IF(ISNUMBER(U19),U19,0)),"") | AT19: =IF(AND(ISNUMBER(AR19),ISNUMBER(AS19)),AR19-AS19,"") | AU19: =IF(E19="금융","",IF(AND(ISNUMBER(L19),ISNUMBER(M19),ISNUMBER(N19),ISNUMBER(AT19)),L19+M19-N19-AT19,IF(AND(ISNUMBER(O19),ISNUMBER(N19)),O19-N19,""))) | AV19: =IF(E19="금융","금융업 - 정의되지 않음",IF(AND(ISNUMBER(L19),ISNUMBER(M19),ISNUMBER(N19),ISNUMBER(AT19)),"순이익+감가상각-설비투자-운전자본증감",IF(AND(ISNUMBER(O19),ISNUMBER(N19)),"영업현금흐름-설비투자","산출불가"))) | AW19: =IF(AND(ISNUMBER(AU19),ISNUMBER(G19),G19<>0),AU19/G19,"") | AX19: =IF(AND(ISNUMBER(AC19),ISNUMBER(G19),G19<>0),AC19/G19,"")
A20: AAPL | B20: Apple Inc. | C20: 2017 | D20: 2017-09-30 | E20: 일반 | F20: 0000320193-19-000119 | G20: 229.234 | H20: 64.089 | I20: 2.323 | J20: 15.738 | K20: 61.344 | L20: 48.351 | M20: 10.157 | N20: 12.451 | O20: 64.225 | P20: 134.047 | Q20: 128.249 | R20: 20.289 | S20: 20.484 | T20: 6.496 | U20: 3.5 | V20: 97.207 | W20: 128.645 | X20: 106.869 | Y20: 100.814 | Z20: 79.006 | AA20: 186.692 | AB20: 20504.804 | AC20: =IF(AND(ISNUMBER(H20),ISNUMBER(I20)),H20+I20,IF(ISNUMBER(K20),K20,IF(ISNUMBER(H20),H20,""))) | AD20: =IF(OR(NOT(ISNUMBER(J20)),NOT(ISNUMBER(H20)),H20<=0),기준표!$B$8,MIN(MAX(J20/H20,기준표!$B$6),기준표!$B$7)) | AE20: =IF(ISNUMBER(AC20),AC20*(1-AD20),"") | AF20: =IF(AND(NOT(ISNUMBER(T20)),NOT(ISNUMBER(V20))),"",IF(ISNUMBER(T20),T20,0)+IF(ISNUMBER(V20),V20,0)) | AG20: =IF(E20="금융","",IF(AND(ISNUMBER(P20),ISNUMBER(AF20),ISNUMBER(R20)),P20+AF20-R20,"")) | AH20: =IF(E20="금융","",IF(NOT(ISNUMBER(AG20)),"",IF(ISNUMBER(AA20),(AG20+AA20)/2,AG20))) | AI20: =IF(AND(ISNUMBER(AE20),ISNUMBER(AH20),AH20>0),AE20/AH20,"") | AJ20: =IF(E20="금융","",IF(AND(ISNUMBER(P20),ISNUMBER(AF20)),P20+AF20,"")) | AK20: =IF(OR(NOT(ISNUMBER(AE20)),NOT(ISNUMBER(AJ20)),AJ20<=0),"",IF(AND(ISNUMBER(G20),AJ20<0.1*G20),"",AE20/AJ20)) | AL20: =IF(NOT(ISNUMBER(P20)),"",IF(ISNUMBER(Q20),(P20+Q20)/2,P20)) | AM20: =IF(AND(ISNUMBER(L20),ISNUMBER(AL20),AL20>0),L20/AL20,"") | AN20: =IF(AND(ISNUMBER(AM20),ISNUMBER({ROIC})),AM20-{ROIC},"") | AO20: =IF(AND(ISNUMBER(AC20),ISNUMBER(M20)),AC20+M20,"") | AP20: =IF(AND(ISNUMBER(AF20),ISNUMBER(R20),ISNUMBER(AO20),AO20>0),(AF20-R20)/AO20,"") | AQ20: =IF(AND(ISNUMBER(AC20),ISNUMBER(I20),I20<>0,AC20>0),AC20/I20,"") | AR20: =IF(AND(ISNUMBER(W20),ISNUMBER(Y20)),W20-IF(ISNUMBER(R20),R20,0)-(Y20-IF(ISNUMBER(T20),T20,0)),"") | AS20: =IF(AND(ISNUMBER(X20),ISNUMBER(Z20)),X20-IF(ISNUMBER(S20),S20,0)-(Z20-IF(ISNUMBER(U20),U20,0)),"") | AT20: =IF(AND(ISNUMBER(AR20),ISNUMBER(AS20)),AR20-AS20,"") | AU20: =IF(E20="금융","",IF(AND(ISNUMBER(L20),ISNUMBER(M20),ISNUMBER(N20),ISNUMBER(AT20)),L20+M20-N20-AT20,IF(AND(ISNUMBER(O20),ISNUMBER(N20)),O20-N20,""))) | AV20: =IF(E20="금융","금융업 - 정의되지 않음",IF(AND(ISNUMBER(L20),ISNUMBER(M20),ISNUMBER(N20),ISNUMBER(AT20)),"순이익+감가상각-설비투자-운전자본증감",IF(AND(ISNUMBER(O20),ISNUMBER(N20)),"영업현금흐름-설비투자","산출불가"))) | AW20: =IF(AND(ISNUMBER(AU20),ISNUMBER(G20),G20<>0),AU20/G20,"") | AX20: =IF(AND(ISNUMBER(AC20),ISNUMBER(G20),G20<>0),AC20/G20,"")
A21: AAPL | B21: Apple Inc. | C21: 2018 | D21: 2018-09-29 | E21: 일반 | F21: 0000320193-20-000096 | G21: 265.595 | H21: 72.903 | I21: 3.24 | J21: 13.372 | K21: 70.898 | L21: 59.531 | M21: 10.903 | N21: 13.313 | O21: 77.434 | P21: 107.147 | Q21: 134.047 | R21: 66.301 | S21: 20.289 | T21: 8.784 | U21: 6.496 | V21: 93.735 | W21: 131.339 | X21: 128.645 | Y21: 115.929 | Z21: 100.814 | AA21: 217.461 | AB21: 19019.944 | AC21: =IF(AND(ISNUMBER(H21),ISNUMBER(I21)),H21+I21,IF(ISNUMBER(K21),K21,IF(ISNUMBER(H21),H21,""))) | AD21: =IF(OR(NOT(ISNUMBER(J21)),NOT(ISNUMBER(H21)),H21<=0),기준표!$B$8,MIN(MAX(J21/H21,기준표!$B$6),기준표!$B$7)) | AE21: =IF(ISNUMBER(AC21),AC21*(1-AD21),"") | AF21: =IF(AND(NOT(ISNUMBER(T21)),NOT(ISNUMBER(V21))),"",IF(ISNUMBER(T21),T21,0)+IF(ISNUMBER(V21),V21,0)) | AG21: =IF(E21="금융","",IF(AND(ISNUMBER(P21),ISNUMBER(AF21),ISNUMBER(R21)),P21+AF21-R21,"")) | AH21: =IF(E21="금융","",IF(NOT(ISNUMBER(AG21)),"",IF(ISNUMBER(AA21),(AG21+AA21)/2,AG21))) | AI21: =IF(AND(ISNUMBER(AE21),ISNUMBER(AH21),AH21>0),AE21/AH21,"") | AJ21: =IF(E21="금융","",IF(AND(ISNUMBER(P21),ISNUMBER(AF21)),P21+AF21,"")) | AK21: =IF(OR(NOT(ISNUMBER(AE21)),NOT(ISNUMBER(AJ21)),AJ21<=0),"",IF(AND(ISNUMBER(G21),AJ21<0.1*G21),"",AE21/AJ21)) | AL21: =IF(NOT(ISNUMBER(P21)),"",IF(ISNUMBER(Q21),(P21+Q21)/2,P21)) | AM21: =IF(AND(ISNUMBER(L21),ISNUMBER(AL21),AL21>0),L21/AL21,"") | AN21: =IF(AND(ISNUMBER(AM21),ISNUMBER({ROIC})),AM21-{ROIC},"") | AO21: =IF(AND(ISNUMBER(AC21),ISNUMBER(M21)),AC21+M21,"") | AP21: =IF(AND(ISNUMBER(AF21),ISNUMBER(R21),ISNUMBER(AO21),AO21>0),(AF21-R21)/AO21,"") | AQ21: =IF(AND(ISNUMBER(AC21),ISNUMBER(I21),I21<>0,AC21>0),AC21/I21,"") | AR21: =IF(AND(ISNUMBER(W21),ISNUMBER(Y21)),W21-IF(ISNUMBER(R21),R21,0)-(Y21-IF(ISNUMBER(T21),T21,0)),"") | AS21: =IF(AND(ISNUMBER(X21),ISNUMBER(Z21)),X21-IF(ISNUMBER(S21),S21,0)-(Z21-IF(ISNUMBER(U21),U21,0)),"") | AT21: =IF(AND(ISNUMBER(AR21),ISNUMBER(AS21)),AR21-AS21,"") | AU21: =IF(E21="금융","",IF(AND(ISNUMBER(L21),ISNUMBER(M21),ISNUMBER(N21),ISNUMBER(AT21)),L21+M21-N21-AT21,IF(AND(ISNUMBER(O21),ISNUMBER(N21)),O21-N21,""))) | AV21: =IF(E21="금융","금융업 - 정의되지 않음",IF(AND(ISNUMBER(L21),ISNUMBER(M21),ISNUMBER(N21),ISNUMBER(AT21)),"순이익+감가상각-설비투자-운전자본증감",IF(AND(ISNUMBER(O21),ISNUMBER(N21)),"영업현금흐름-설비투자","산출불가"))) | AW21: =IF(AND(ISNUMBER(AU21),ISNUMBER(G21),G21<>0),AU21/G21,"") | AX21: =IF(AND(ISNUMBER(AC21),ISNUMBER(G21),G21<>0),AC21/G21,"")
A22: AAPL | B22: Apple Inc. | C22: 2019 | D22: 2019-09-28 | E22: 일반 | F22: 0000320193-21-000105 | G22: 260.174 | H22: 65.737 | I22: 3.576 | J22: 10.481 | K22: 63.93 | L22: 55.256 | M22: 12.547 | N22: 10.495 | O22: 69.391 | P22: 90.488 | Q22: 107.147 | R22: 100.557 | S22: 66.301 | T22: 10.26 | U22: 8.784 | V22: 91.807 | W22: 162.819 | X22: 131.339 | Y22: 105.718 | Z22: 115.929 | AA22: 143.365 | AB22: 17772.945 | AC22: =IF(AND(ISNUMBER(H22),ISNUMBER(I22)),H22+I22,IF(ISNUMBER(K22),K22,IF(ISNUMBER(H22),H22,""))) | AD22: =IF(OR(NOT(ISNUMBER(J22)),NOT(ISNUMBER(H22)),H22<=0),기준표!$B$8,MIN(MAX(J22/H22,기준표!$B$6),기준표!$B$7)) | AE22: =IF(ISNUMBER(AC22),AC22*(1-AD22),"") | AF22: =IF(AND(NOT(ISNUMBER(T22)),NOT(ISNUMBER(V22))),"",IF(ISNUMBER(T22),T22,0)+IF(ISNUMBER(V22),V22,0)) | AG22: =IF(E22="금융","",IF(AND(ISNUMBER(P22),ISNUMBER(AF22),ISNUMBER(R22)),P22+AF22-R22,"")) | AH22: =IF(E22="금융","",IF(NOT(ISNUMBER(AG22)),"",IF(ISNUMBER(AA22),(AG22+AA22)/2,AG22))) | AI22: =IF(AND(ISNUMBER(AE22),ISNUMBER(AH22),AH22>0),AE22/AH22,"") | AJ22: =IF(E22="금융","",IF(AND(ISNUMBER(P22),ISNUMBER(AF22)),P22+AF22,"")) | AK22: =IF(OR(NOT(ISNUMBER(AE22)),NOT(ISNUMBER(AJ22)),AJ22<=0),"",IF(AND(ISNUMBER(G22),AJ22<0.1*G22),"",AE22/AJ22)) | AL22: =IF(NOT(ISNUMBER(P22)),"",IF(ISNUMBER(Q22),(P22+Q22)/2,P22)) | AM22: =IF(AND(ISNUMBER(L22),ISNUMBER(AL22),AL22>0),L22/AL22,"") | AN22: =IF(AND(ISNUMBER(AM22),ISNUMBER({ROIC})),AM22-{ROIC},"") | AO22: =IF(AND(ISNUMBER(AC22),ISNUMBER(M22)),AC22+M22,"") | AP22: =IF(AND(ISNUMBER(AF22),ISNUMBER(R22),ISNUMBER(AO22),AO22>0),(AF22-R22)/AO22,"") | AQ22: =IF(AND(ISNUMBER(AC22),ISNUMBER(I22),I22<>0,AC22>0),AC22/I22,"") | AR22: =IF(AND(ISNUMBER(W22),ISNUMBER(Y22)),W22-IF(ISNUMBER(R22),R22,0)-(Y22-IF(ISNUMBER(T22),T22,0)),"") | AS22: =IF(AND(ISNUMBER(X22),ISNUMBER(Z22)),X22-IF(ISNUMBER(S22),S22,0)-(Z22-IF(ISNUMBER(U22),U22,0)),"") | AT22: =IF(AND(ISNUMBER(AR22),ISNUMBER(AS22)),AR22-AS22,"") | AU22: =IF(E22="금융","",IF(AND(ISNUMBER(L22),ISNUMBER(M22),ISNUMBER(N22),ISNUMBER(AT22)),L22+M22-N22-AT22,IF(AND(ISNUMBER(O22),ISNUMBER(N22)),O22-N22,""))) | AV22: =IF(E22="금융","금융업 - 정의되지 않음",IF(AND(ISNUMBER(L22),ISNUMBER(M22),ISNUMBER(N22),ISNUMBER(AT22)),"순이익+감가상각-설비투자-운전자본증감",IF(AND(ISNUMBER(O22),ISNUMBER(N22)),"영업현금흐름-설비투자","산출불가"))) | AW22: =IF(AND(ISNUMBER(AU22),ISNUMBER(G22),G22<>0),AU22/G22,"") | AX22: =IF(AND(ISNUMBER(AC22),ISNUMBER(G22),G22<>0),AC22/G22,"")
A23: AAPL | B23: Apple Inc. | C23: 2020 | D23: 2020-09-26 | E23: 일반 | F23: 0000320193-22-000108 | G23: 274.515 | H23: 67.091 | I23: 2.873 | J23: 9.68 | K23: 66.288 | L23: 57.411 | M23: 11.056 | N23: 7.309 | O23: 80.674 | P23: 65.339 | Q23: 90.488 | R23: 90.943 | S23: 100.557 | T23: 8.773 | U23: 10.26 | V23: 98.667 | W23: 143.713 | X23: 162.819 | Y23: 105.392 | Z23: 105.718 | AA23: 91.998 | AB23: 16976.763 | AC23: =IF(AND(ISNUMBER(H23),ISNUMBER(I23)),H23+I23,IF(ISNUMBER(K23),K23,IF(ISNUMBER(H23),H23,""))) | AD23: =IF(OR(NOT(ISNUMBER(J23)),NOT(ISNUMBER(H23)),H23<=0),기준표!$B$8,MIN(MAX(J23/H23,기준표!$B$6),기준표!$B$7)) | AE23: =IF(ISNUMBER(AC23),AC23*(1-AD23),"") | AF23: =IF(AND(NOT(ISNUMBER(T23)),NOT(ISNUMBER(V23))),"",IF(ISNUMBER(T23),T23,0)+IF(ISNUMBER(V23),V23,0)) | AG23: =IF(E23="금융","",IF(AND(ISNUMBER(P23),ISNUMBER(AF23),ISNUMBER(R23)),P23+AF23-R23,"")) | AH23: =IF(E23="금융","",IF(NOT(ISNUMBER(AG23)),"",IF(ISNUMBER(AA23),(AG23+AA23)/2,AG23))) | AI23: =IF(AND(ISNUMBER(AE23),ISNUMBER(AH23),AH23>0),AE23/AH23,"") | AJ23: =IF(E23="금융","",IF(AND(ISNUMBER(P23),ISNUMBER(AF23)),P23+AF23,"")) | AK23: =IF(OR(NOT(ISNUMBER(AE23)),NOT(ISNUMBER(AJ23)),AJ23<=0),"",IF(AND(ISNUMBER(G23),AJ23<0.1*G23),"",AE23/AJ23)) | AL23: =IF(NOT(ISNUMBER(P23)),"",IF(ISNUMBER(Q23),(P23+Q23)/2,P23)) | AM23: =IF(AND(ISNUMBER(L23),ISNUMBER(AL23),AL23>0),L23/AL23,"") | AN23: =IF(AND(ISNUMBER(AM23),ISNUMBER({ROIC})),AM23-{ROIC},"") | AO23: =IF(AND(ISNUMBER(AC23),ISNUMBER(M23)),AC23+M23,"") | AP23: =IF(AND(ISNUMBER(AF23),ISNUMBER(R23),ISNUMBER(AO23),AO23>0),(AF23-R23)/AO23,"") | AQ23: =IF(AND(ISNUMBER(AC23),ISNUMBER(I23),I23<>0,AC23>0),AC23/I23,"") | AR23: =IF(AND(ISNUMBER(W23),ISNUMBER(Y23)),W23-IF(ISNUMBER(R23),R23,0)-(Y23-IF(ISNUMBER(T23),T23,0)),"") | AS23: =IF(AND(ISNUMBER(X23),ISNUMBER(Z23)),X23-IF(ISNUMBER(S23),S23,0)-(Z23-IF(ISNUMBER(U23),U23,0)),"") | AT23: =IF(AND(ISNUMBER(AR23),ISNUMBER(AS23)),AR23-AS23,"") | AU23: =IF(E23="금융","",IF(AND(ISNUMBER(L23),ISNUMBER(M23),ISNUMBER(N23),ISNUMBER(AT23)),L23+M23-N23-AT23,IF(AND(ISNUMBER(O23),ISNUMBER(N23)),O23-N23,""))) | AV23: =IF(E23="금융","금융업 - 정의되지 않음",IF(AND(ISNUMBER(L23),ISNUMBER(M23),ISNUMBER(N23),ISNUMBER(AT23)),"순이익+감가상각-설비투자-운전자본증감",IF(AND(ISNUMBER(O23),ISNUMBER(N23)),"영업현금흐름-설비투자","산출불가"))) | AW23: =IF(AND(ISNUMBER(AU23),ISNUMBER(G23),G23<>0),AU23/G23,"") | AX23: =IF(AND(ISNUMBER(AC23),ISNUMBER(G23),G23<>0),AC23/G23,"")
A24: AAPL | B24: Apple Inc. | C24: 2021 | D24: 2021-09-25 | E24: 일반 | F24: 0000320193-23-000106 | G24: 365.817 | H24: 109.207 | I24: 2.645 | J24: 14.527 | K24: 108.949 | L24: 94.68 | M24: 11.284 | N24: 11.085 | O24: 104.038 | P24: 63.09 | Q24: 65.339 | R24: 62.639 | S24: 90.943 | T24: 9.613 | U24: 8.773 | V24: 109.106 | W24: 134.836 | X24: 143.713 | Y24: 125.481 | Z24: 105.392 | AA24: 81.836 | AB24: 16426.786 | AC24: =IF(AND(ISNUMBER(H24),ISNUMBER(I24)),H24+I24,IF(ISNUMBER(K24),K24,IF(ISNUMBER(H24),H24,""))) | AD24: =IF(OR(NOT(ISNUMBER(J24)),NOT(ISNUMBER(H24)),H24<=0),기준표!$B$8,MIN(MAX(J24/H24,기준표!$B$6),기준표!$B$7)) | AE24: =IF(ISNUMBER(AC24),AC24*(1-AD24),"") | AF24: =IF(AND(NOT(ISNUMBER(T24)),NOT(ISNUMBER(V24))),"",IF(ISNUMBER(T24),T24,0)+IF(ISNUMBER(V24),V24,0)) | AG24: =IF(E24="금융","",IF(AND(ISNUMBER(P24),ISNUMBER(AF24),ISNUMBER(R24)),P24+AF24-R24,"")) | AH24: =IF(E24="금융","",IF(NOT(ISNUMBER(AG24)),"",IF(ISNUMBER(AA24),(AG24+AA24)/2,AG24))) | AI24: =IF(AND(ISNUMBER(AE24),ISNUMBER(AH24),AH24>0),AE24/AH24,"") | AJ24: =IF(E24="금융","",IF(AND(ISNUMBER(P24),ISNUMBER(AF24)),P24+AF24,"")) | AK24: =IF(OR(NOT(ISNUMBER(AE24)),NOT(ISNUMBER(AJ24)),AJ24<=0),"",IF(AND(ISNUMBER(G24),AJ24<0.1*G24),"",AE24/AJ24)) | AL24: =IF(NOT(ISNUMBER(P24)),"",IF(ISNUMBER(Q24),(P24+Q24)/2,P24)) | AM24: =IF(AND(ISNUMBER(L24),ISNUMBER(AL24),AL24>0),L24/AL24,"") | AN24: =IF(AND(ISNUMBER(AM24),ISNUMBER({ROIC})),AM24-{ROIC},"") | AO24: =IF(AND(ISNUMBER(AC24),ISNUMBER(M24)),AC24+M24,"") | AP24: =IF(AND(ISNUMBER(AF24),ISNUMBER(R24),ISNUMBER(AO24),AO24>0),(AF24-R24)/AO24,"") | AQ24: =IF(AND(ISNUMBER(AC24),ISNUMBER(I24),I24<>0,AC24>0),AC24/I24,"") | AR24: =IF(AND(ISNUMBER(W24),ISNUMBER(Y24)),W24-IF(ISNUMBER(R24),R24,0)-(Y24-IF(ISNUMBER(T24),T24,0)),"") | AS24: =IF(AND(ISNUMBER(X24),ISNUMBER(Z24)),X24-IF(ISNUMBER(S24),S24,0)-(Z24-IF(ISNUMBER(U24),U24,0)),"") | AT24: =IF(AND(ISNUMBER(AR24),ISNUMBER(AS24)),AR24-AS24,"") | AU24: =IF(E24="금융","",IF(AND(ISNUMBER(L24),ISNUMBER(M24),ISNUMBER(N24),ISNUMBER(AT24)),L24+M24-N24-AT24,IF(AND(ISNUMBER(O24),ISNUMBER(N24)),O24-N24,""))) | AV24: =IF(E24="금융","금융업 - 정의되지 않음",IF(AND(ISNUMBER(L24),ISNUMBER(M24),ISNUMBER(N24),ISNUMBER(AT24)),"순이익+감가상각-설비투자-운전자본증감",IF(AND(ISNUMBER(O24),ISNUMBER(N24)),"영업현금흐름-설비투자","산출불가"))) | AW24: =IF(AND(ISNUMBER(AU24),ISNUMBER(G24),G24<>0),AU24/G24,"") | AX24: =IF(AND(ISNUMBER(AC24),ISNUMBER(G24),G24<>0),AC24/G24,"")
A25: AAPL | B25: Apple Inc. | C25: 2022 | D25: 2022-09-24 | E25: 일반 | F25: 0000320193-24-000123 | G25: 394.328 | H25: 119.103 | I25: 2.931 | J25: 19.3 | K25: 119.437 | L25: 99.803 | M25: 11.104 | N25: 10.708 | O25: 122.151 | P25: 50.672 | Q25: 63.09 | R25: 48.304 | S25: 62.639 | T25: 11.128 | U25: 9.613 | V25: 98.959 | W25: 135.405 | X25: 134.836 | Y25: 153.982 | Z25: 125.481 | AA25: 119.17 | AB25: 15943.425 | AC25: =IF(AND(ISNUMBER(H25),ISNUMBER(I25)),H25+I25,IF(ISNUMBER(K25),K25,IF(ISNUMBER(H25),H25,""))) | AD25: =IF(OR(NOT(ISNUMBER(J25)),NOT(ISNUMBER(H25)),H25<=0),기준표!$B$8,MIN(MAX(J25/H25,기준표!$B$6),기준표!$B$7)) | AE25: =IF(ISNUMBER(AC25),AC25*(1-AD25),"") | AF25: =IF(AND(NOT(ISNUMBER(T25)),NOT(ISNUMBER(V25))),"",IF(ISNUMBER(T25),T25,0)+IF(ISNUMBER(V25),V25,0)) | AG25: =IF(E25="금융","",IF(AND(ISNUMBER(P25),ISNUMBER(AF25),ISNUMBER(R25)),P25+AF25-R25,"")) | AH25: =IF(E25="금융","",IF(NOT(ISNUMBER(AG25)),"",IF(ISNUMBER(AA25),(AG25+AA25)/2,AG25))) | AI25: =IF(AND(ISNUMBER(AE25),ISNUMBER(AH25),AH25>0),AE25/AH25,"") | AJ25: =IF(E25="금융","",IF(AND(ISNUMBER(P25),ISNUMBER(AF25)),P25+AF25,"")) | AK25: =IF(OR(NOT(ISNUMBER(AE25)),NOT(ISNUMBER(AJ25)),AJ25<=0),"",IF(AND(ISNUMBER(G25),AJ25<0.1*G25),"",AE25/AJ25)) | AL25: =IF(NOT(ISNUMBER(P25)),"",IF(ISNUMBER(Q25),(P25+Q25)/2,P25)) | AM25: =IF(AND(ISNUMBER(L25),ISNUMBER(AL25),AL25>0),L25/AL25,"") | AN25: =IF(AND(ISNUMBER(AM25),ISNUMBER({ROIC})),AM25-{ROIC},"") | AO25: =IF(AND(ISNUMBER(AC25),ISNUMBER(M25)),AC25+M25,"") | AP25: =IF(AND(ISNUMBER(AF25),ISNUMBER(R25),ISNUMBER(AO25),AO25>0),(AF25-R25)/AO25,"") | AQ25: =IF(AND(ISNUMBER(AC25),ISNUMBER(I25),I25<>0,AC25>0),AC25/I25,"") | AR25: =IF(AND(ISNUMBER(W25),ISNUMBER(Y25)),W25-IF(ISNUMBER(R25),R25,0)-(Y25-IF(ISNUMBER(T25),T25,0)),"") | AS25: =IF(AND(ISNUMBER(X25),ISNUMBER(Z25)),X25-IF(ISNUMBER(S25),S25,0)-(Z25-IF(ISNUMBER(U25),U25,0)),"") | AT25: =IF(AND(ISNUMBER(AR25),ISNUMBER(AS25)),AR25-AS25,"") | AU25: =IF(E25="금융","",IF(AND(ISNUMBER(L25),ISNUMBER(M25),ISNUMBER(N25),ISNUMBER(AT25)),L25+M25-N25-AT25,IF(AND(ISNUMBER(O25),ISNUMBER(N25)),O25-N25,""))) | AV25: =IF(E25="금융","금융업 - 정의되지 않음",IF(AND(ISNUMBER(L25),ISNUMBER(M25),ISNUMBER(N25),ISNUMBER(AT25)),"순이익+감가상각-설비투자-운전자본증감",IF(AND(ISNUMBER(O25),ISNUMBER(N25)),"영업현금흐름-설비투자","산출불가"))) | AW25: =IF(AND(ISNUMBER(AU25),ISNUMBER(G25),G25<>0),AU25/G25,"") | AX25: =IF(AND(ISNUMBER(AC25),ISNUMBER(G25),G25<>0),AC25/G25,"")
A26: AAPL | B26: Apple Inc. | C26: 2023 | D26: 2023-09-30 | E26: 일반 | F26: 0000320193-25-000079 | G26: 383.285 | H26: 113.736 | I26: 3.933 | J26: 16.741 | K26: 114.301 | L26: 96.995 | M26: 11.519 | N26: 10.959 | O26: 110.543 | P26: 62.146 | Q26: 50.672 | R26: 61.555 | S26: 48.304 | T26: 9.822 | U26: 11.128 | V26: 95.281 | W26: 143.566 | X26: 135.405 | Y26: 145.308 | Z26: 153.982 | AA26: 112.455 | AB26: 15550.061 | AC26: =IF(AND(ISNUMBER(H26),ISNUMBER(I26)),H26+I26,IF(ISNUMBER(K26),K26,IF(ISNUMBER(H26),H26,""))) | AD26: =IF(OR(NOT(ISNUMBER(J26)),NOT(ISNUMBER(H26)),H26<=0),기준표!$B$8,MIN(MAX(J26/H26,기준표!$B$6),기준표!$B$7)) | AE26: =IF(ISNUMBER(AC26),AC26*(1-AD26),"") | AF26: =IF(AND(NOT(ISNUMBER(T26)),NOT(ISNUMBER(V26))),"",IF(ISNUMBER(T26),T26,0)+IF(ISNUMBER(V26),V26,0)) | AG26: =IF(E26="금융","",IF(AND(ISNUMBER(P26),ISNUMBER(AF26),ISNUMBER(R26)),P26+AF26-R26,"")) | AH26: =IF(E26="금융","",IF(NOT(ISNUMBER(AG26)),"",IF(ISNUMBER(AA26),(AG26+AA26)/2,AG26))) | AI26: =IF(AND(ISNUMBER(AE26),ISNUMBER(AH26),AH26>0),AE26/AH26,"") | AJ26: =IF(E26="금융","",IF(AND(ISNUMBER(P26),ISNUMBER(AF26)),P26+AF26,"")) | AK26: =IF(OR(NOT(ISNUMBER(AE26)),NOT(ISNUMBER(AJ26)),AJ26<=0),"",IF(AND(ISNUMBER(G26),AJ26<0.1*G26),"",AE26/AJ26)) | AL26: =IF(NOT(ISNUMBER(P26)),"",IF(ISNUMBER(Q26),(P26+Q26)/2,P26)) | AM26: =IF(AND(ISNUMBER(L26),ISNUMBER(AL26),AL26>0),L26/AL26,"") | AN26: =IF(AND(ISNUMBER(AM26),ISNUMBER({ROIC})),AM26-{ROIC},"") | AO26: =IF(AND(ISNUMBER(AC26),ISNUMBER(M26)),AC26+M26,"") | AP26: =IF(AND(ISNUMBER(AF26),ISNUMBER(R26),ISNUMBER(AO26),AO26>0),(AF26-R26)/AO26,"") | AQ26: =IF(AND(ISNUMBER(AC26),ISNUMBER(I26),I26<>0,AC26>0),AC26/I26,"") | AR26: =IF(AND(ISNUMBER(W26),ISNUMBER(Y26)),W26-IF(ISNUMBER(R26),R26,0)-(Y26-IF(ISNUMBER(T26),T26,0)),"") | AS26: =IF(AND(ISNUMBER(X26),ISNUMBER(Z26)),X26-IF(ISNUMBER(S26),S26,0)-(Z26-IF(ISNUMBER(U26),U26,0)),"") | AT26: =IF(AND(ISNUMBER(AR26),ISNUMBER(AS26)),AR26-AS26,"") | AU26: =IF(E26="금융","",IF(AND(ISNUMBER(L26),ISNUMBER(M26),ISNUMBER(N26),ISNUMBER(AT26)),L26+M26-N26-AT26,IF(AND(ISNUMBER(O26),ISNUMBER(N26)),O26-N26,""))) | AV26: =IF(E26="금융","금융업 - 정의되지 않음",IF(AND(ISNUMBER(L26),ISNUMBER(M26),ISNUMBER(N26),ISNUMBER(AT26)),"순이익+감가상각-설비투자-운전자본증감",IF(AND(ISNUMBER(O26),ISNUMBER(N26)),"영업현금흐름-설비투자","산출불가"))) | AW26: =IF(AND(ISNUMBER(AU26),ISNUMBER(G26),G26<>0),AU26/G26,"") | AX26: =IF(AND(ISNUMBER(AC26),ISNUMBER(G26),G26<>0),AC26/G26,"")
