Workbook

Sheet 요약
A1: 삼성바이오로직스 — 버핏 기준 기업분석
A2: CDMO 단일사업 기준 (별도 재무제표) FY2016~FY2025. 모든 수치는 이 워크북의 다른 시트에서 계산되며, 그 시트들은 감사보고서에서 읽은 값만을 입력으로 씁니다.
A4: 기준 | B4: 판정 | C4: 근거 (수식) | D4: 값
A5: 1. 이해할 수 있는 사업 | B5: 통과 | C5: 위탁생산 한 가지. 분할 후 보고부문 1개
A6: 2. 기존 자본의 수익률 > 자본비용 | B6: 통과 | C6: FY2025 ROIC (건설중자산 제외) | D6: =ROIC!K$26
C7: 자본비용 참고값 | D7: =가정!$B$47
A8: 3. 지속되는 해자 | B8: 조건부 통과 | C8: 선수금+계약부채 ÷ 매출 — 고객이 먼저 내는 돈
A9: 4. 증분 자본의 수익률 > 자본비용 | B9: 통과 | C9: FY2020→FY2025 증분 ROIC | D9: =((ROIC!K$7-ROIC!F$7)/(ROIC!K$19-ROIC!F$19))
A10: 5. 자본배분·주주지향 | B10: 조건부 통과 | C10: 배당 0, 2022년 유상증자 3.19조원, 지배주주 74.3%
A11: 6. 이익의 질 | B11: 조건부 통과 | C11: 10년 누적 영업현금흐름 − 설비투자 (주주이익 시트 I열 합계)
A12: 7. 합리적인 가격 | B12: 미달 | C12: 낙관 시나리오 자기자본가치 ÷ 시가총액 − 1 | D12: =(DCF_낙관!$B$28-가정!$B$46/1000000000)/(가정!$B$46/1000000000)
A14: 가치 — 기준연도 3 × 시나리오 3
A15: 기준연도 | B15: 보수 | C15: 중립 | D15: 낙관 | E15: 시가총액
A16: FY2025 실적 | B16: =DCF_보수_reported!$B$28/1000 | C16: =DCF_중립_reported!$B$28/1000 | D16: =DCF_낙관_reported!$B$28/1000 | E16: =가정!$B$46/1000000000000
A17: 2026 상반기 연율화 | B17: =DCF_보수_run!$B$28/1000 | C17: =DCF_중립_run!$B$28/1000 | D17: =DCF_낙관_run!$B$28/1000 | E17: =가정!$B$46/1000000000000
A18: 2026 연율화 · 현재 환율 | B18: =DCF_보수!$B$28/1000 | C18: =DCF_중립!$B$28/1000 | D18: =DCF_낙관!$B$28/1000 | E18: =가정!$B$46/1000000000000
A19: 단위: 조원
A21: 적정주가 — 기준연도 3 × 시나리오 3
A22: 기준연도 | B22: 보수 | C22: 중립 | D22: 낙관 | E22: 현재주가
A23: FY2025 실적 | B23: =DCF_보수_reported!$B$29 | C23: =DCF_중립_reported!$B$29 | D23: =DCF_낙관_reported!$B$29 | E23: =가정!$B$6
A24: 2026 상반기 연율화 | B24: =DCF_보수_run!$B$29 | C24: =DCF_중립_run!$B$29 | D24: =DCF_낙관_run!$B$29 | E24: =가정!$B$6
A25: 2026 연율화 · 현재 환율 | B25: =DCF_보수!$B$29 | C25: =DCF_중립!$B$29 | D25: =DCF_낙관!$B$29 | E25: =가정!$B$6
A27: 매수 규칙
A28: 중립·낙관 평균 적정주가 (현재 환율 기준) | B28: =AVERAGE(DCF_중립!$B$29,DCF_낙관!$B$29)
A29: 안전마진 적용 후 매수가 | B29: =B28*(1-가정!$B$44)
A30: 현재주가 대비 | B30: =B29/가정!$B$6-1
A32: 이 칸을 목표주가로 읽지 마십시오. '내가 정한 가정 아래서 가치가 이만큼이므로 그 아래에서만 산다'는 규칙의 출력입니다. 가정은 전부 가정 시트의 노란 칸에 있으니, 생각이 다르면 그 칸을 바꿔 이 숫자가 어떻게 움직이는지 직접 확인하시면 됩니다.
A33: 색: 파랑 = 감사보고서·시세에서 읽은 값, 검정 = 같은 시트 수식, 초록 = 다른 시트를 참조하는 수식, 노랑 = 바꿔도 되는 가정.

Sheet 가정
A1: 가정
A2: 노란 칸은 바꿔도 되는 값입니다. 바꾸면 이 워크북의 모든 계산이 따라 움직입니다. 출처가 있는 값은 출처를 적었습니다.
A4: 항목 | B4: 값 | C4: 형식 | D4: 출처 / 근거
A5: 시장
A6: 주가 | B6: 1408000 | C6: 원 | D6: 네이버 금융 일별시세 (207940), 2026-09-14 종가
A7: 유통주식수 | B7: 46239518 | C7: 원 | D7: 분할 후 발행주식 46,290,951주에서 자기주식 51,433주를 차감한 유통주식 46,239,518주 기준. 분할 전 71,174,000주였으므로 분할 전 주가·EPS와는 직접 비교할 수 없습니다.
A8: 발행주식수 | B8: 46290951 | C8: 원 | D8: FY2025 별도재무제표 자본 주석 (분할 후)
A9: 52주 최고 | B9: 1987000 | C9: 원 | D9: 네이버 금융
A10: 52주 최저 | B10: 1228000 | C10: 원 | D10: 네이버 금융
A11: 환율
A12: 현재 원/달러 | B12: 1358.5 | C12: 숫자 | D12: 2026년 9월 평균 (FRED DEXKOUS 월평균) — FRED DEXKOUS (Korea / U.S. Foreign Exchange Rate)
A13: FY2025 평균 원/달러 | B13: 1421.4 | C13: 숫자 | D13: FRED DEXKOUS (Korea / U.S. Foreign Exchange Rate)
A14: FY2024 평균 원/달러 | B14: 1363.4 | C14: 숫자 | D14: FRED DEXKOUS (Korea / U.S. Foreign Exchange Rate)
A15: 2026 상반기 평균 원/달러 | B15: 1482 | C15: 숫자 | D15: FRED DEXKOUS (Korea / U.S. Foreign Exchange Rate)
A16: 해외매출 비중 | B16: 0.91839395 | C16: 비율 | D16: FY2025 지역별 매출 주석에서 국내 매출을 뺀 비중. 원자료 시트에서 계산
A17: 원가 중 외화연동 비중 | B17: 0.3 | C17: 비율 | D17: 가정. 배양액·레진·일회용 자재는 달러 수입, 인건비·감가상각·전력은 원화. 회사가 공시하지 않으므로 0~60%로 흔들어 확인했고 결론은 바뀌지 않습니다
A18: 세율·자본비용
A19: 법정세율 | B19: 0.22 | C19: 비율 | D19: 한국 법인세 최고세율 + 지방소득세
A20: 무위험수익률 | B20: 0.04181 | C20: 비율 | D20: FRED IRLTLT01KRM156N (Korea 10-year government bond yield) (2026-06)
A21: 주식위험프리미엄 | B21: 0.065 | C21: 비율 | D21: 참고 자본비용 계산용 (5.5~7.5% 중간값)
A22: 베타 | B22: 1 | C22: 숫자 | D22: 참고 자본비용 계산용 (0.9~1.2 중간값)
A23: 세전 차입이자율 | B23: 0.04 | C23: 비율 | D23: FY2025 사채·차입금 주석 수준
A24: 보수 시나리오
A25: 보수 첫해 성장률 | B25: 0.08 | C25: 비율 | D25: 증설을 멈추고 기존 공장의 가동률·가격·믹스 개선만으로 성장. 증분 ROIC은 실측 5년 구간 최저치(24.9%)보다 크게 낮은 15%를 적용.
A26: 보수 10년차 성장률 | B26: 0.025 | C26: 비율 | D26: 1년차에서 10년차까지 직선 체감
A27: 보수 증분 ROIC | B27: 0.15 | C27: 비율 | D27: 실측 5년 구간 24.9~29.7% 대비
A28: 보수 할인율 | B28: 0.11 | C28: 비율
A29: 보수 영구성장률 | B29: 0.02 | C29: 비율
A30: 중립 시나리오
A31: 중립 첫해 성장률 | B31: 0.15 | C31: 비율 | D31: 증설을 계속하되 10년에 걸쳐 성장률이 GDP 수준으로 수렴. 증분 ROIC 20%는 실측 구간(24.9~29.7%) 하단 아래.
A32: 중립 10년차 성장률 | B32: 0.04 | C32: 비율 | D32: 1년차에서 10년차까지 직선 체감
A33: 중립 증분 ROIC | B33: 0.2 | C33: 비율 | D33: 실측 5년 구간 24.9~29.7% 대비
A34: 중립 할인율 | B34: 0.1 | C34: 비율
A35: 중립 영구성장률 | B35: 0.025 | C35: 비율
A36: 낙관 시나리오
A37: 낙관 첫해 성장률 | B37: 0.25 | C37: 비율 | D37: 최근 5년 실적(매출 CAGR 31.4%, 2026 상반기 +28.0%)의 하단에서 출발해 10년간 체감. 증분 ROIC 26%는 FY2020→FY2025 실측치(27.6%)에 근접.
A38: 낙관 10년차 성장률 | B38: 0.05 | C38: 비율 | D38: 1년차에서 10년차까지 직선 체감
A39: 낙관 증분 ROIC | B39: 0.26 | C39: 비율 | D39: 실측 5년 구간 24.9~29.7% 대비
A40: 낙관 할인율 | B40: 0.09 | C40: 비율
A41: 낙관 영구성장률 | B41: 0.03 | C41: 비율
...

Sheet 원자료
A1: 원자료 — 감사받은 재무제표에서 추출한 값
A2: 파란 글씨는 전부 감사보고서 원본 PDF에서 읽은 값입니다. 기준은 별도(別途) 재무제표 = CDMO 사업 단독. 이유는 워드 보고서 2장에 있습니다. 단위: 십억원.
A4: 항목 | B4: FY2016 | C4: FY2017 | D4: FY2018 | E4: FY2019 | F4: FY2020 | G4: FY2021 | H4: FY2022 | I4: FY2023 | J4: FY2024 | K4: FY2025 | L4: 출처
A5: 매출 | B5: 294.62202 | C5: 464.62933 | D5: 535.8058 | E5: 701.59186 | F5: 1164.7769 | G5: 1568.0069 | H5: 2437.2861 | I5: 2938.7557 | J5: 3497.1457 | K5: 4556.9717 | L5: sblsep_2025.pdf
A6: 매출원가 | B6: -268.08836 | C6: -332.82927 | D6: -390.64586 | E6: -509.58443 | F6: -748.70076 | G6: -841.55556 | H6: -1237.054 | I6: -1448.3846 | J6: -1784.1464 | K6: -2039.8573 | L6: sblsep_2025.pdf
A7: 판매비와관리비 | B7: -56.956302 | C7: -65.820659 | D7: -89.481197 | E7: -100.26505 | F7: -123.28956 | G7: -189.14196 | H7: -232.18149 | I7: -286.18307 | J7: -391.57372 | K7: -449.02154 | L7: sblsep_2025.pdf
A8: 영업이익 | B8: -30.422639 | C8: 65.979402 | D8: 55.678745 | E8: 91.742387 | F8: 292.78655 | G8: 537.30941 | H8: 968.05059 | I8: 1204.188 | J8: 1321.4255 | K8: 2068.0928 | L8: sblsep_2025.pdf
A9: 세전이익 | B9: -230.90098 | C9: -115.99475 | D9: 302.97584 | E9: 155.43531 | F9: 265.99216 | G9: 561.2826 | H9: 922.88701 | I9: 1224.1834 | J9: 1402.3779 | K9: 2078.9765 | L9: sblsep_2025.pdf
A10: 법인세비용 | B10: -54.077573 | C10: -19.022637 | D10: 78.866642 | E10: -47.46879 | F10: 25.017363 | G10: 167.69313 | H10: 236.09407 | I10: 278.26309 | J10: 351.41139 | K10: 492.78954 | L10: sblsep_2025.pdf
A11: 당기순이익 | B11: -176.82341 | C11: -96.972116 | D11: 224.10919 | E11: 202.9041 | F11: 240.9748 | G11: 393.58947 | H11: 686.79294 | I11: 945.92033 | J11: 1050.9665 | K11: 1586.187 | L11: sblsep_2025.pdf
A12: 감가상각비 | B12: 55.784426 | C12: 64.18848 | D12: 85.522362 | E12: 121.89235 | F12: 131.41481 | G12: 144.0614 | H12: 163.44098 | I12: 235.73754 | J12: 276.08039 | K12: 343.88978 | L12: sblsep_2025.pdf
A13: 무형자산상각비 | B13: 4.365463 | C13: 5.737747 | D13: 5.928193 | E13: 6.2920847 | F13: 6.107638 | G13: 6.7256613 | H13: 7.4910921 | I13: 9.3767404 | J13: 12.94111 | K13: 15.535967 | L13: sblsep_2025.pdf
A14: 사용권자산상각비 | E14: 4.3585795 | F14: 5.6524283 | G14: 11.001591 | H14: 9.8601178 | I14: 9.7821115 | J14: 10.009516 | K14: 9.88896 | L14: sblsep_2025.pdf
A15: 영업활동현금흐름 | B15: -62.661298 | C15: 149.81633 | D15: 36.787308 | E15: 10.153615 | F15: 202.09003 | G15: 454.59622 | H15: 831.09884 | I15: 1418.2144 | J15: 1382.8361 | K15: 1953.456 | L15: sblsep_2025.pdf
A16: 유형자산 취득 | B16: 162.99235 | C16: 494.11945 | D16: 347.85189 | E16: 171.73436 | F16: 139.66481 | G16: 406.25351 | H16: 948.12693 | I16: 976.19572 | J16: 1297.1265 | K16: 1376.3442 | L16: sblsep_2025.pdf
A17: 무형자산 취득 | B17: 5.179126 | C17: 10.682088 | D17: 5.811483 | E17: 9.4618551 | F17: 8.9012277 | G17: 14.898311 | H17: 12.199985 | I17: 25.106735 | J17: 26.633163 | K17: 11.502254 | L17: sblsep_2025.pdf
A18: 현금및현금성자산 | B18: 230.3376 | C18: 358.08809 | D18: 17.621905 | E18: 125.10065 | F18: 28.850121 | G18: 47.410384 | H18: 757.94599 | I18: 230.79068 | J18: 299.58833 | K18: 141.48462 | L18: sblsep_2025.pdf
A19: 단기금융상품 | C19: 970 | D19: 550 | E19: 320 | F19: 300 | G19: 450 | H19: 2168.901 | I19: 1650 | J19: 900 | K19: 1300 | L19: sblsep_2025.pdf
A20: 매출채권 등 | B20: 75.63082 | C20: 25.81715 | D20: 121.73335 | E20: 187.11812 | F20: 217.93231 | G20: 366.33068 | H20: 503.99718 | I20: 390.23294 | J20: 785.79274 | K20: 676.56549 | L20: sblsep_2025.pdf
A21: 재고자산 | B21: 164.21998 | C21: 209.98672 | D21: 302.36072 | E21: 452.46993 | F21: 645.9601 | G21: 1012.8708 | H21: 1243.172 | I21: 1678.606 | J21: 1882.9555 | K21: 2128.1642 | L21: sblsep_2025.pdf
A22: 계약자산 | D22: 96.578638 | E22: 151.48289 | F22: 196.75642 | G22: 253.24194 | H22: 304.3396 | I22: 339.14725 | J22: 362.61363 | K22: 411.59937 | L22: sblsep_2025.pdf
A23: 유형자산 | B23: 1090.9598 | C23: 1513.3326 | D23: 1717.721 | E23: 1702.7925 | F23: 1736.5673 | G23: 2207.0637 | H23: 3083.5454 | I23: 3542.8771 | J23: 5047.5831 | K23: 6028.493 | L23: sblsep_2025.pdf
A24: 무형자산 | B24: 14.044654 | C24: 18.999003 | D24: 19.981634 | E24: 21.827515 | F24: 23.344606 | G24: 32.171618 | H24: 39.436622 | I24: 53.78053 | J24: 65.174296 | K24: 60.19327 | L24: sblsep_2025.pdf
A25: 사용권자산 | E25: 16.118883 | F25: 24.160224 | G25: 20.623773 | H25: 451.79293 | I25: 458.6775 | J25: 461.45513 | K25: 8.0194321 | L25: sblsep_2025.pdf
A26: 종속·관계기업투자 | B26: 4944.3563 | C26: 5008.234 | D26: 2561.8025 | E26: 2652.7316 | F26: 2634.4285 | G26: 2661.3095 | H26: 3308.7926 | I26: 3317.5322 | J26: 3328.2262 | K26: 45.882814 | L26: sblsep_2025.pdf
A27: 자산총계 | B27: 7533.0161 | C27: 7183.0912 | D27: 5980.4086 | E27: 5911.6265 | F27: 6424.2012 | G27: 7970.0108 | H27: 12165.839 | I27: 11831.261 | J27: 13317.211 | K27: 11023.969 | L27: sblsep_2025.pdf
A28: 매입채무 등 | B28: 138.05638 | C28: 158.21485 | D28: 170.33829 | E28: 101.12806 | F28: 185.17671 | G28: 399.03009 | H28: 1628.7341 | I28: 1028.6881 | J28: 1126.4456 | K28: 485.83688 | L28: sblsep_2025.pdf
A29: 계약부채 | D29: 101.10479 | E29: 145.12926 | F29: 197.11687 | G29: 285.62183 | H29: 289.68204 | I29: 353.87375 | J29: 456.22037 | K29: 539.43715 | L29: sblsep_2025.pdf
A30: 기타유동부채(선수금) | B30: 60.323791 | C30: 56.486175 | D30: 87.695614 | E30: 144.70677 | F30: 159.56712 | G30: 364.4092 | H30: 450.88983 | I30: 732.0554 | J30: 1032.343 | K30: 1201.4585 | L30: sblsep_2025.pdf
A31: 이자부부채 | B31: 843.05728 | C31: 545.91215 | D31: 872.69611 | E31: 637.81712 | F31: 762.35836 | G31: 1274.539 | H31: 1263.0881 | I31: 928.18756 | J31: 1726.1617 | K31: 918.72442 | L31: sblsep_2025.pdf
A32: 리스부채 | E32: 15.889284 | F32: 22.546905 | G32: 18.208298 | H32: 407.22445 | I32: 278.20396 | J32: 143.84 | K32: 7.3972848 | L32: sblsep_2025.pdf
A33: 부채총계 | B33: 3450.6366 | C33: 3206.6403 | D33: 1824.9402 | E33: 1557.1728 | F33: 1825.418 | G33: 2978.9086 | H33: 4869.2357 | I33: 3592.6268 | J33: 4036.3182 | K33: 3608.5199 | L33: sblsep_2025.pdf
A34: 자본총계 | B34: 4082.3795 | C34: 3976.4509 | D34: 4155.4685 | E34: 4354.4537 | F34: 4598.7832 | G34: 4991.1021 | H34: 7296.6032 | I34: 8238.6338 | J34: 9280.8928 | K34: 7415.4488 | L34: sblsep_2025.pdf
A35: 건설중자산 | B35: 232.70546 | C35: 308.84456 | D35: 57.115774 | E35: 36.714553 | F35: 105.4696 | G35: 583.35227 | H35: 816.47839 | I35: 192.25767 | J35: 1823.2984 | K35: 430.16065 | L35: 각 연도 유형자산 주석
A37: 지역별 매출 (FY2025)
A38: 국내 | B38: 371.87648 | C38: 558.08631
A39: 유럽 | B39: 2367.7467 | C39: 2035.771
A40: 미국 | B40: 1733.9215 | C40: 822.63194
A41: 기타 | B41: 83.426957 | C41: 80.656378
A42: 합계 (매출과 일치해야 함) | B42: =SUM(B38:B41) | C42: =SUM(C38:C41) | E42: =B42-원자료!K$5 | F42: ← 0이어야 합니다 (검증)
...

Sheet ROIC
A1: 기준 2 — 투하자본이익률
A2: 모든 칸이 원자료 시트를 참조하는 수식입니다. 투하자본은 세 가지로 계산했고, 건설중자산을 뺀 값이 본문에서 쓰는 값입니다. 단위: 십억원.
A4: 항목 | B4: FY2016 | C4: FY2017 | D4: FY2018 | E4: FY2019 | F4: FY2020 | G4: FY2021 | H4: FY2022 | I4: FY2023 | J4: FY2024 | K4: FY2025
A5: 영업이익 | B5: =원자료!B$8 | C5: =원자료!C$8 | D5: =원자료!D$8 | E5: =원자료!E$8 | F5: =원자료!F$8 | G5: =원자료!G$8 | H5: =원자료!H$8 | I5: =원자료!I$8 | ... K5: =원자료!K$8
A6: 실효세율 (법인세÷세전이익) | B6: =IF(OR(원자료!B$9<=0,원자료!B$10/원자료!B$9<0.05,원자료!B$10/원자료!B$9>0.4),가정!$B$19,원자료!B$10/원자료!B$9) | C6: =IF(OR(원자료!C$9<=0,원자료!C$10/원자료!C$9<0.05,원자료!C$10/원자료!C$9>0.4),가정!$B$19,원자료!C$10/원자료!C$9) | D6: =IF(OR(원자료!D$9<=0,원자료!D$10/원자료!D$9<0.05,원자료!D$10/원자료!D$9>0.4),가정!$B$19,원자료!D$10/원자료!D$9) | E6: =IF(OR(원자료!E$9<=0,원자료!E$10/원자료!E$9<0.05,원자료!E$10/원자료!E$9>0.4),가정!$B$19,원자료!E$10/원자료!E$9) | F6: =IF(OR(원자료!F$9<=0,원자료!F$10/원자료!F$9<0.05,원자료!F$10/원자료!F$9>0.4),가정!$B$19,원자료!F$10/원자료!F$9) | G6: =IF(OR(원자료!G$9<=0,원자료!G$10/원자료!G$9<0.05,원자료!G$10/원자료!G$9>0.4),가정!$B$19,원자료!G$10/원자료!G$9) | H6: =IF(OR(원자료!H$9<=0,원자료!H$10/원자료!H$9<0.05,원자료!H$10/원자료!H$9>0.4),가정!$B$19,원자료!H$10/원자료!H$9) | I6: =IF(OR(원자료!I$9<=0,원자료!I$10/원자료!I$9<0.05,원자료!I$10/원자료!I$9>0.4),가정!$B$19,원자료!I$10/원자료!I$9) | ... K6: =IF(OR(원자료!K$9<=0,원자료!K$10/원자료!K$9<0.05,원자료!K$10/원자료!K$9>0.4),가정!$B$19,원자료!K$10/원자료!K$9)
A7: NOPAT = 영업이익 × (1 − 실효세율) | B7: =ROIC!B$5*(1-ROIC!B$6) | C7: =ROIC!C$5*(1-ROIC!C$6) | D7: =ROIC!D$5*(1-ROIC!D$6) | E7: =ROIC!E$5*(1-ROIC!E$6) | F7: =ROIC!F$5*(1-ROIC!F$6) | G7: =ROIC!G$5*(1-ROIC!G$6) | H7: =ROIC!H$5*(1-ROIC!H$6) | I7: =ROIC!I$5*(1-ROIC!I$6) | ... K7: =ROIC!K$5*(1-ROIC!K$6)
A9: 투하자본 — 하향식
A10: 자본총계 + 이자부부채 + 리스부채 − 현금성 − 종속·관계기업투자 | B10: =원자료!B$34+원자료!B$31+원자료!B$32-원자료!B$18-원자료!B$19-원자료!B$26 | C10: =원자료!C$34+원자료!C$31+원자료!C$32-원자료!C$18-원자료!C$19-원자료!C$26 | D10: =원자료!D$34+원자료!D$31+원자료!D$32-원자료!D$18-원자료!D$19-원자료!D$26 | E10: =원자료!E$34+원자료!E$31+원자료!E$32-원자료!E$18-원자료!E$19-원자료!E$26 | F10: =원자료!F$34+원자료!F$31+원자료!F$32-원자료!F$18-원자료!F$19-원자료!F$26 | G10: =원자료!G$34+원자료!G$31+원자료!G$32-원자료!G$18-원자료!G$19-원자료!G$26 | H10: =원자료!H$34+원자료!H$31+원자료!H$32-원자료!H$18-원자료!H$19-원자료!H$26 | I10: =원자료!I$34+원자료!I$31+원자료!I$32-원자료!I$18-원자료!I$19-원자료!I$26 | ... K10: =원자료!K$34+원자료!K$31+원자료!K$32-원자료!K$18-원자료!K$19-원자료!K$26
A12: 투하자본 — 상향식 영업자본
A13: 영업자산 (유형+무형+사용권+재고+매출채권+계약자산) | B13: =원자료!B$23+원자료!B$24+원자료!B$25+원자료!B$21+원자료!B$20+원자료!B$22 | C13: =원자료!C$23+원자료!C$24+원자료!C$25+원자료!C$21+원자료!C$20+원자료!C$22 | D13: =원자료!D$23+원자료!D$24+원자료!D$25+원자료!D$21+원자료!D$20+원자료!D$22 | E13: =원자료!E$23+원자료!E$24+원자료!E$25+원자료!E$21+원자료!E$20+원자료!E$22 | F13: =원자료!F$23+원자료!F$24+원자료!F$25+원자료!F$21+원자료!F$20+원자료!F$22 | G13: =원자료!G$23+원자료!G$24+원자료!G$25+원자료!G$21+원자료!G$20+원자료!G$22 | H13: =원자료!H$23+원자료!H$24+원자료!H$25+원자료!H$21+원자료!H$20+원자료!H$22 | I13: =원자료!I$23+원자료!I$24+원자료!I$25+원자료!I$21+원자료!I$20+원자료!I$22 | ... K13: =원자료!K$23+원자료!K$24+원자료!K$25+원자료!K$21+원자료!K$20+원자료!K$22
A14: − 계약부채 − 선수금 | B14: =-원자료!B$29-원자료!B$30 | C14: =-원자료!C$29-원자료!C$30 | D14: =-원자료!D$29-원자료!D$30 | E14: =-원자료!E$29-원자료!E$30 | F14: =-원자료!F$29-원자료!F$30 | G14: =-원자료!G$29-원자료!G$30 | H14: =-원자료!H$29-원자료!H$30 | I14: =-원자료!I$29-원자료!I$30 | ... K14: =-원자료!K$29-원자료!K$30
A15: 영업자본 (매입채무 미차감) | B15: =ROIC!B$13+ROIC!B$14 | C15: =ROIC!C$13+ROIC!C$14 | D15: =ROIC!D$13+ROIC!D$14 | E15: =ROIC!E$13+ROIC!E$14 | F15: =ROIC!F$13+ROIC!F$14 | G15: =ROIC!G$13+ROIC!G$14 | H15: =ROIC!H$13+ROIC!H$14 | I15: =ROIC!I$13+ROIC!I$14 | ... K15: =ROIC!K$13+ROIC!K$14
A16: − 매입채무 | B16: =-원자료!B$28 | C16: =-원자료!C$28 | D16: =-원자료!D$28 | E16: =-원자료!E$28 | F16: =-원자료!F$28 | G16: =-원자료!G$28 | H16: =-원자료!H$28 | I16: =-원자료!I$28 | ... K16: =-원자료!K$28
A17: 영업자본 (매입채무 차감) | B17: =ROIC!B$15+ROIC!B$16 | C17: =ROIC!C$15+ROIC!C$16 | D17: =ROIC!D$15+ROIC!D$16 | E17: =ROIC!E$15+ROIC!E$16 | F17: =ROIC!F$15+ROIC!F$16 | G17: =ROIC!G$15+ROIC!G$16 | H17: =ROIC!H$15+ROIC!H$16 | I17: =ROIC!I$15+ROIC!I$16 | ... K17: =ROIC!K$15+ROIC!K$16
A18: 건설중자산 | B18: =원자료!B$35 | C18: =원자료!C$35 | D18: =원자료!D$35 | E18: =원자료!E$35 | F18: =원자료!F$35 | G18: =원자료!G$35 | H18: =원자료!H$35 | I18: =원자료!I$35 | ... K18: =원자료!K$35
A19: 영업자본 − 건설중자산 (매입채무 미차감) | B19: =ROIC!B$15-ROIC!B$18 | C19: =ROIC!C$15-ROIC!C$18 | D19: =ROIC!D$15-ROIC!D$18 | E19: =ROIC!E$15-ROIC!E$18 | F19: =ROIC!F$15-ROIC!F$18 | G19: =ROIC!G$15-ROIC!G$18 | H19: =ROIC!H$15-ROIC!H$18 | I19: =ROIC!I$15-ROIC!I$18 | ... K19: =ROIC!K$15-ROIC!K$18
A20: 영업자본 − 건설중자산 (매입채무 차감) | B20: =ROIC!B$17-ROIC!B$18 | C20: =ROIC!C$17-ROIC!C$18 | D20: =ROIC!D$17-ROIC!D$18 | E20: =ROIC!E$17-ROIC!E$18 | F20: =ROIC!F$17-ROIC!F$18 | G20: =ROIC!G$17-ROIC!G$18 | H20: =ROIC!H$17-ROIC!H$18 | I20: =ROIC!I$17-ROIC!I$18 | ... K20: =ROIC!K$17-ROIC!K$18
A22: ROIC
A23: 하향식 | B23: =IF(ROIC!B$10<=0,"",ROIC!B$7/ROIC!B$10) | C23: =IF(ROIC!C$10<=0,"",ROIC!C$7/ROIC!C$10) | D23: =IF(ROIC!D$10<=0,"",ROIC!D$7/ROIC!D$10) | E23: =IF(ROIC!E$10<=0,"",ROIC!E$7/ROIC!E$10) | F23: =IF(ROIC!F$10<=0,"",ROIC!F$7/ROIC!F$10) | G23: =IF(ROIC!G$10<=0,"",ROIC!G$7/ROIC!G$10) | H23: =IF(ROIC!H$10<=0,"",ROIC!H$7/ROIC!H$10) | I23: =IF(ROIC!I$10<=0,"",ROIC!I$7/ROIC!I$10) | ... K23: =IF(ROIC!K$10<=0,"",ROIC!K$7/ROIC!K$10)
A24: 상향식 (매입채무 차감) | B24: =IF(ROIC!B$17<=0,"",ROIC!B$7/ROIC!B$17) | C24: =IF(ROIC!C$17<=0,"",ROIC!C$7/ROIC!C$17) | D24: =IF(ROIC!D$17<=0,"",ROIC!D$7/ROIC!D$17) | E24: =IF(ROIC!E$17<=0,"",ROIC!E$7/ROIC!E$17) | F24: =IF(ROIC!F$17<=0,"",ROIC!F$7/ROIC!F$17) | G24: =IF(ROIC!G$17<=0,"",ROIC!G$7/ROIC!G$17) | H24: =IF(ROIC!H$17<=0,"",ROIC!H$7/ROIC!H$17) | I24: =IF(ROIC!I$17<=0,"",ROIC!I$7/ROIC!I$17) | ... K24: =IF(ROIC!K$17<=0,"",ROIC!K$7/ROIC!K$17)
A25: 상향식 − 건설중자산 (매입채무 차감) | B25: =IF(ROIC!B$20<=0,"",ROIC!B$7/ROIC!B$20) | C25: =IF(ROIC!C$20<=0,"",ROIC!C$7/ROIC!C$20) | D25: =IF(ROIC!D$20<=0,"",ROIC!D$7/ROIC!D$20) | E25: =IF(ROIC!E$20<=0,"",ROIC!E$7/ROIC!E$20) | F25: =IF(ROIC!F$20<=0,"",ROIC!F$7/ROIC!F$20) | G25: =IF(ROIC!G$20<=0,"",ROIC!G$7/ROIC!G$20) | H25: =IF(ROIC!H$20<=0,"",ROIC!H$7/ROIC!H$20) | I25: =IF(ROIC!I$20<=0,"",ROIC!I$7/ROIC!I$20) | ... K25: =IF(ROIC!K$20<=0,"",ROIC!K$7/ROIC!K$20)
A26: 상향식 − 건설중자산 (매입채무 미차감) ← 본문 기준 | B26: =IF(ROIC!B$19<=0,"",ROIC!B$7/ROIC!B$19) | C26: =IF(ROIC!C$19<=0,"",ROIC!C$7/ROIC!C$19) | D26: =IF(ROIC!D$19<=0,"",ROIC!D$7/ROIC!D$19) | E26: =IF(ROIC!E$19<=0,"",ROIC!E$7/ROIC!E$19) | F26: =IF(ROIC!F$19<=0,"",ROIC!F$7/ROIC!F$19) | G26: =IF(ROIC!G$19<=0,"",ROIC!G$7/ROIC!G$19) | H26: =IF(ROIC!H$19<=0,"",ROIC!H$7/ROIC!H$19) | I26: =IF(ROIC!I$19<=0,"",ROIC!I$7/ROIC!I$19) | ... K26: =IF(ROIC!K$19<=0,"",ROIC!K$7/ROIC!K$19)
A27: ROIC − 자본비용 (본문 기준) | B27: =IF(ROIC!B$26="","",ROIC!B$26-가정!$B$47) | C27: =IF(ROIC!C$26="","",ROIC!C$26-가정!$B$47) | D27: =IF(ROIC!D$26="","",ROIC!D$26-가정!$B$47) | E27: =IF(ROIC!E$26="","",ROIC!E$26-가정!$B$47) | F27: =IF(ROIC!F$26="","",ROIC!F$26-가정!$B$47) | G27: =IF(ROIC!G$26="","",ROIC!G$26-가정!$B$47) | H27: =IF(ROIC!H$26="","",ROIC!H$26-가정!$B$47) | I27: =IF(ROIC!I$26="","",ROIC!I$26-가정!$B$47) | ... K27: =IF(ROIC!K$26="","",ROIC!K$26-가정!$B$47)
A29: FY2016·FY2017의 하향식 투하자본은 음수입니다 (에피스 지분이 대차대조표를 지배). 음수 분모에서 나온 비율은 수익률이 아니므로 빈칸으로 처리했습니다. FY2018 이후에는 하향식과 상향식이 −16%~+11% 범위에서 같이 움직이므로, 측정 방식의 선택이 결론을 만들지 않았습니다.
A30: 건설중자산을 빼는 이유: FY2024 말 영업자본의 30%가 아직 완공되지 않아 한 푼도 벌지 못하는 공장이었고, FY2025에 2조 1,829억원이 가동자산으로 넘어갔습니다. 빼지 않으면 FY2024가 수익률이 무너진 해로 읽힙니다.

Sheet 증분ROIC
A1: 기준 4 — 증분 투하자본이익률
A2: ΔNOPAT ÷ Δ투하자본. 분모는 건설중자산을 뺀 영업자본(매입채무 미차감)입니다. 단위: 십억원.
A4: 구간 | B4: 시작 NOPAT | C4: 종료 NOPAT | D4: ΔNOPAT | E4: 시작 투하자본 | F4: 종료 투하자본 | G4: Δ투하자본 | H4: 증분 ROIC | I4: 자본비용 대비
A5: FY2016→FY2019 | B5: =ROIC!B$7 | C5: =ROIC!E$7 | D5: =C5-B5 | E5: =ROIC!B$19 | F5: =ROIC!E$19 | G5: =F5-E5 | H5: =IF(G5<=0,"",D5/G5) | I5: =IF(H5="","",H5-가정!$B$47)
A6: FY2017→FY2020 | B6: =ROIC!C$7 | C6: =ROIC!F$7 | D6: =C6-B6 | E6: =ROIC!C$19 | F6: =ROIC!F$19 | G6: =F6-E6 | H6: =IF(G6<=0,"",D6/G6) | I6: =IF(H6="","",H6-가정!$B$47)
A7: FY2018→FY2021 | B7: =ROIC!D$7 | C7: =ROIC!G$7 | D7: =C7-B7 | E7: =ROIC!D$19 | F7: =ROIC!G$19 | G7: =F7-E7 | H7: =IF(G7<=0,"",D7/G7) | I7: =IF(H7="","",H7-가정!$B$47)
A8: FY2019→FY2022 | B8: =ROIC!E$7 | C8: =ROIC!H$7 | D8: =C8-B8 | E8: =ROIC!E$19 | F8: =ROIC!H$19 | G8: =F8-E8 | H8: =IF(G8<=0,"",D8/G8) | I8: =IF(H8="","",H8-가정!$B$47)
A9: FY2020→FY2023 | B9: =ROIC!F$7 | C9: =ROIC!I$7 | D9: =C9-B9 | E9: =ROIC!F$19 | F9: =ROIC!I$19 | G9: =F9-E9 | H9: =IF(G9<=0,"",D9/G9) | I9: =IF(H9="","",H9-가정!$B$47)
A10: FY2021→FY2024 | B10: =ROIC!G$7 | C10: =ROIC!J$7 | D10: =C10-B10 | E10: =ROIC!G$19 | F10: =ROIC!J$19 | G10: =F10-E10 | H10: =IF(G10<=0,"",D10/G10) | I10: =IF(H10="","",H10-가정!$B$47)
A11: FY2022→FY2025 | B11: =ROIC!H$7 | C11: =ROIC!K$7 | D11: =C11-B11 | E11: =ROIC!H$19 | F11: =ROIC!K$19 | G11: =F11-E11 | H11: =IF(G11<=0,"",D11/G11) | I11: =IF(H11="","",H11-가정!$B$47)
A12: FY2016→FY2021 | B12: =ROIC!B$7 | C12: =ROIC!G$7 | D12: =C12-B12 | E12: =ROIC!B$19 | F12: =ROIC!G$19 | G12: =F12-E12 | H12: =IF(G12<=0,"",D12/G12) | I12: =IF(H12="","",H12-가정!$B$47)
A13: FY2017→FY2022 | B13: =ROIC!C$7 | C13: =ROIC!H$7 | D13: =C13-B13 | E13: =ROIC!C$19 | F13: =ROIC!H$19 | G13: =F13-E13 | H13: =IF(G13<=0,"",D13/G13) | I13: =IF(H13="","",H13-가정!$B$47)
A14: FY2018→FY2023 | B14: =ROIC!D$7 | C14: =ROIC!I$7 | D14: =C14-B14 | E14: =ROIC!D$19 | F14: =ROIC!I$19 | G14: =F14-E14 | H14: =IF(G14<=0,"",D14/G14) | I14: =IF(H14="","",H14-가정!$B$47)
A15: FY2019→FY2024 | B15: =ROIC!E$7 | C15: =ROIC!J$7 | D15: =C15-B15 | E15: =ROIC!E$19 | F15: =ROIC!J$19 | G15: =F15-E15 | H15: =IF(G15<=0,"",D15/G15) | I15: =IF(H15="","",H15-가정!$B$47)
A16: FY2020→FY2025 | B16: =ROIC!F$7 | C16: =ROIC!K$7 | D16: =C16-B16 | E16: =ROIC!F$19 | F16: =ROIC!K$19 | G16: =F16-E16 | H16: =IF(G16<=0,"",D16/G16) | I16: =IF(H16="","",H16-가정!$B$47)
A17: FY2016→FY2025 | B17: =ROIC!B$7 | C17: =ROIC!K$7 | D17: =C17-B17 | E17: =ROIC!B$19 | F17: =ROIC!K$19 | G17: =F17-E17 | H17: =IF(G17<=0,"",D17/G17) | I17: =IF(H17="","",H17-가정!$B$47)
A19: 짧은 구간은 양 끝에서 무엇이 건설 중이었는지에 좌우되므로 점이 아니라 범위로 읽어야 합니다. 5년 구간 다섯 개가 모두 24.9~29.7%에 들어오고, 그것이 본문에서 쓴 근거입니다.

Sheet 주주이익
A1: 기준 6 — 주주이익 (1986년 주주서한 정의)
A2: 보고이익 + 감가상각 등 − 장기 경쟁지위와 판매량을 유지하는 데 필요한 설비투자 − 운전자본 증가. 판단이 필요한 것은 '유지에 필요한 설비투자' 한 줄뿐이므로 세 가지로 계산해 범위를 보여줍니다. 단위: 십억원.
A4: FY | B4: 당기순이익 | C4: 감가상각 합계 | D4: 유형자산 취득 | E4: 운전자본 증감 | F4: 주주이익 (유지=감가상각) | G4: 주주이익 (유지=1.2×감가상각) | H4: 주주이익 (유지=취득 전액) | I4: 영업현금흐름 − 취득
A5: 2016 | B5: =원자료!B$11 | C5: =원자료!B$12+원자료!B$13+원자료!B$14 | D5: =원자료!B$16 | F5: =B5+C5-C5-IF(ISNUMBER(E5),E5,0) | G5: =B5+C5-1.2*C5-IF(ISNUMBER(E5),E5,0) | H5: =B5+C5-D5-IF(ISNUMBER(E5),E5,0) | I5: =원자료!B$15-원자료!B$16
A6: 2017 | B6: =원자료!C$11 | C6: =원자료!C$12+원자료!C$13+원자료!C$14 | D6: =원자료!C$16 | E6: =(원자료!C$21-원자료!B$21)-(원자료!C$30-원자료!B$30)-(원자료!C$29-원자료!B$29) | F6: =B6+C6-C6-IF(ISNUMBER(E6),E6,0) | G6: =B6+C6-1.2*C6-IF(ISNUMBER(E6),E6,0) | H6: =B6+C6-D6-IF(ISNUMBER(E6),E6,0) | I6: =원자료!C$15-원자료!C$16
A7: 2018 | B7: =원자료!D$11 | C7: =원자료!D$12+원자료!D$13+원자료!D$14 | D7: =원자료!D$16 | E7: =(원자료!D$21-원자료!C$21)-(원자료!D$30-원자료!C$30)-(원자료!D$29-원자료!C$29) | F7: =B7+C7-C7-IF(ISNUMBER(E7),E7,0) | G7: =B7+C7-1.2*C7-IF(ISNUMBER(E7),E7,0) | H7: =B7+C7-D7-IF(ISNUMBER(E7),E7,0) | I7: =원자료!D$15-원자료!D$16
A8: 2019 | B8: =원자료!E$11 | C8: =원자료!E$12+원자료!E$13+원자료!E$14 | D8: =원자료!E$16 | E8: =(원자료!E$21-원자료!D$21)-(원자료!E$30-원자료!D$30)-(원자료!E$29-원자료!D$29) | F8: =B8+C8-C8-IF(ISNUMBER(E8),E8,0) | G8: =B8+C8-1.2*C8-IF(ISNUMBER(E8),E8,0) | H8: =B8+C8-D8-IF(ISNUMBER(E8),E8,0) | I8: =원자료!E$15-원자료!E$16
A9: 2020 | B9: =원자료!F$11 | C9: =원자료!F$12+원자료!F$13+원자료!F$14 | D9: =원자료!F$16 | E9: =(원자료!F$21-원자료!E$21)-(원자료!F$30-원자료!E$30)-(원자료!F$29-원자료!E$29) | F9: =B9+C9-C9-IF(ISNUMBER(E9),E9,0) | G9: =B9+C9-1.2*C9-IF(ISNUMBER(E9),E9,0) | H9: =B9+C9-D9-IF(ISNUMBER(E9),E9,0) | I9: =원자료!F$15-원자료!F$16
A10: 2021 | B10: =원자료!G$11 | C10: =원자료!G$12+원자료!G$13+원자료!G$14 | D10: =원자료!G$16 | E10: =(원자료!G$21-원자료!F$21)-(원자료!G$30-원자료!F$30)-(원자료!G$29-원자료!F$29) | F10: =B10+C10-C10-IF(ISNUMBER(E10),E10,0) | G10: =B10+C10-1.2*C10-IF(ISNUMBER(E10),E10,0) | H10: =B10+C10-D10-IF(ISNUMBER(E10),E10,0) | I10: =원자료!G$15-원자료!G$16
A11: 2022 | B11: =원자료!H$11 | C11: =원자료!H$12+원자료!H$13+원자료!H$14 | D11: =원자료!H$16 | E11: =(원자료!H$21-원자료!G$21)-(원자료!H$30-원자료!G$30)-(원자료!H$29-원자료!G$29) | F11: =B11+C11-C11-IF(ISNUMBER(E11),E11,0) | G11: =B11+C11-1.2*C11-IF(ISNUMBER(E11),E11,0) | H11: =B11+C11-D11-IF(ISNUMBER(E11),E11,0) | I11: =원자료!H$15-원자료!H$16
A12: 2023 | B12: =원자료!I$11 | C12: =원자료!I$12+원자료!I$13+원자료!I$14 | D12: =원자료!I$16 | E12: =(원자료!I$21-원자료!H$21)-(원자료!I$30-원자료!H$30)-(원자료!I$29-원자료!H$29) | F12: =B12+C12-C12-IF(ISNUMBER(E12),E12,0) | G12: =B12+C12-1.2*C12-IF(ISNUMBER(E12),E12,0) | H12: =B12+C12-D12-IF(ISNUMBER(E12),E12,0) | I12: =원자료!I$15-원자료!I$16
A13: 2024 | B13: =원자료!J$11 | C13: =원자료!J$12+원자료!J$13+원자료!J$14 | D13: =원자료!J$16 | E13: =(원자료!J$21-원자료!I$21)-(원자료!J$30-원자료!I$30)-(원자료!J$29-원자료!I$29) | F13: =B13+C13-C13-IF(ISNUMBER(E13),E13,0) | G13: =B13+C13-1.2*C13-IF(ISNUMBER(E13),E13,0) | H13: =B13+C13-D13-IF(ISNUMBER(E13),E13,0) | I13: =원자료!J$15-원자료!J$16
A14: 2025 | B14: =원자료!K$11 | C14: =원자료!K$12+원자료!K$13+원자료!K$14 | D14: =원자료!K$16 | E14: =(원자료!K$21-원자료!J$21)-(원자료!K$30-원자료!J$30)-(원자료!K$29-원자료!J$29) | F14: =B14+C14-C14-IF(ISNUMBER(E14),E14,0) | G14: =B14+C14-1.2*C14-IF(ISNUMBER(E14),E14,0) | H14: =B14+C14-D14-IF(ISNUMBER(E14),E14,0) | I14: =원자료!K$15-원자료!K$16
A15: 10년 합계 | B15: =SUM(B5:B14) | C15: =SUM(C5:C14) | D15: =SUM(D5:D14) | E15: =SUM(E5:E14) | F15: =SUM(F5:F14) | G15: =SUM(G5:G14) | H15: =SUM(H5:H14) | I15: =SUM(I5:I14)
A17: 가장 중요한 칸은 I열 합계입니다. 10년 동안 순이익을 5.06조원 벌었지만 영업현금흐름에서 설비투자를 뺀 금액의 합계는 사실상 0입니다. 번 돈 전부가 공장으로 들어갔고, 그 위에 2022년 3.19조원의 유상증자까지 받았습니다. 증분 ROIC이 25~30%라면 그 선택 자체는 옳지만, 이 주식을 10년 보유해 받은 현금이 0원이라는 사실도 같이 읽어야 합니다.
A18: F열의 수식이 '+C−C'로 보이는 것은 1986년 정의를 그대로 쓴 결과입니다. 감가상각을 더하고 유지 설비투자를 빼는데, 이 칸에서는 유지 설비투자를 감가상각과 같다고 본 것이므로 서로 상쇄됩니다. 정의를 숨기지 않기 위해 상쇄된 형태로 남겨두었습니다.

Sheet 기준연도
A1: 기준 7 (1) — 기준연도
A2: 매출의 92%를 해외에서 벌고 원가는 대부분 원화입니다. 원/달러가 FY2025 1,421원, 2026 상반기 1,482원, 현재 1,358원이므로 어느 환율을 자본화하는지가 가치에 직접 영향을 줍니다. 세 가지를 모두 계산합니다. 단위: 십억원.
A4: 항목 | B4: FY2025 실적 | C4: 2026 상반기 연율화 | D4: 2026 연율화 · 현재 환율 | E4: 설명
A5: 매출 | B5: =원자료!K$5 | C5: 5156.0601 | D5: =C5*((1-가정!$B$16)+가정!$B$16*가정!$B$12/가정!$B$15) | E5: 2026 상반기 매출 × 2. 환산은 해외분만 환율에 비례
A6: 영업이익 | B6: =원자료!K$8 | C6: 2334.3928 | D6: =D5-((C5-C6)*((1-가정!$B$17)+가정!$B$17*가정!$B$12/가정!$B$15)) | E6: 환산 영업이익 = 환산 매출 − 환산 원가. 원가는 외화연동 비중만큼만 환율에 비례
A7: 영업이익률 | B7: =B6/B5 | C7: =C6/C5 | D7: =D6/D5
A8: 실효세율 | B8: =ROIC!K$6 | C8: 0.26552123 | D8: =C8 | E8: 2026 상반기 법인세비용 ÷ 세전이익
A9: NOPAT | B9: =B6*(1-B8) | C9: =C6*(1-C8) | D9: =D6*(1-D8)
A11: 순현금
A12: 현금및현금성자산 + 단기금융상품 | B12: =원자료!K$18+원자료!K$19
A13: − 이자부부채 − 리스부채 | B13: =-원자료!K$31-원자료!K$32
A14: 순현금 | B14: =B12+B13 | D14: 선수금·계약부채 1.80조원은 순현금에 넣지 않았습니다. 그것은 영업자본에 이미 반영된 고객 자금이고, 현금흐름 추정이 그 위에서 돌아갑니다.
A16: 환율 민감도 (2026 연율화 기준)
A17: 원/달러 | B17: 매출 | C17: 영업이익 | D17: 영업이익률 | E17: NOPAT
A18: 1200 | B18: =C5*((1-가정!$B$16)+가정!$B$16*A18/가정!$B$15) | C18: =B18-((C5-C6)*((1-가정!$B$17)+가정!$B$17*A18/가정!$B$15)) | D18: =C18/B18 | E18: =C18*(1-C8)
A19: 1250 | B19: =C5*((1-가정!$B$16)+가정!$B$16*A19/가정!$B$15) | C19: =B19-((C5-C6)*((1-가정!$B$17)+가정!$B$17*A19/가정!$B$15)) | D19: =C19/B19 | E19: =C19*(1-C8)
A20: 1300 | B20: =C5*((1-가정!$B$16)+가정!$B$16*A20/가정!$B$15) | C20: =B20-((C5-C6)*((1-가정!$B$17)+가정!$B$17*A20/가정!$B$15)) | D20: =C20/B20 | E20: =C20*(1-C8)
A21: 1358.5 | B21: =C5*((1-가정!$B$16)+가정!$B$16*A21/가정!$B$15) | C21: =B21-((C5-C6)*((1-가정!$B$17)+가정!$B$17*A21/가정!$B$15)) | D21: =C21/B21 | E21: =C21*(1-C8)
A22: 1400 | B22: =C5*((1-가정!$B$16)+가정!$B$16*A22/가정!$B$15) | C22: =B22-((C5-C6)*((1-가정!$B$17)+가정!$B$17*A22/가정!$B$15)) | D22: =C22/B22 | E22: =C22*(1-C8)
A23: 1450 | B23: =C5*((1-가정!$B$16)+가정!$B$16*A23/가정!$B$15) | C23: =B23-((C5-C6)*((1-가정!$B$17)+가정!$B$17*A23/가정!$B$15)) | D23: =C23/B23 | E23: =C23*(1-C8)
A24: 1482 | B24: =C5*((1-가정!$B$16)+가정!$B$16*A24/가정!$B$15) | C24: =B24-((C5-C6)*((1-가정!$B$17)+가정!$B$17*A24/가정!$B$15)) | D24: =C24/B24 | E24: =C24*(1-C8)
A25: 1550 | B25: =C5*((1-가정!$B$16)+가정!$B$16*A25/가정!$B$15) | C25: =B25-((C5-C6)*((1-가정!$B$17)+가정!$B$17*A25/가정!$B$15)) | D25: =C25/B25 | E25: =C25*(1-C8)
A27: 원/달러가 1,200원으로 돌아가면 NOPAT은 현재 환율 대비 21% 줄어듭니다. 이 회사에 대한 투자는 상당 부분 원화 약세가 유지된다는 데 대한 투자입니다. 2026년 6월 1,529.5원에서 9월 1,358.5원까지 3개월 만에 11% 절상되었습니다.

Sheet DCF_보수_reported
A1: 기준 7 (2) — 보수 시나리오 현금흐름할인
A2: 재투자율은 가정하지 않고 성장률에서 유도합니다: 재투자율 = 성장률 ÷ 증분 ROIC. 따라서 어떤 성장도 대가 없이 얻을 수 없습니다. 기준연도는 FY2025 실적. 단위: 십억원.
A4: 연차 | B4: 성장률 | C4: NOPAT | D4: 재투자율 | E4: 재투자액 | F4: 자유현금흐름 | G4: 할인계수 | H4: 현재가치 | I4: 외부조달 필요
A5: 1 | B5: =가정!$B$25+(가정!$B$26-가정!$B$25)*(1-1)/(가정!$B$43-1) | C5: =기준연도!$B$9*(1+B5) | D5: =B5/가정!$B$27 | E5: =C5*D5 | F5: =C5-E5 | G5: =1/(1+가정!$B$28)^1 | H5: =F5*G5 | I5: =MAX(0,E5-C5)
A6: 2 | B6: =가정!$B$25+(가정!$B$26-가정!$B$25)*(2-1)/(가정!$B$43-1) | C6: =C5*(1+B6) | D6: =B6/가정!$B$27 | E6: =C6*D6 | F6: =C6-E6 | G6: =1/(1+가정!$B$28)^2 | H6: =F6*G6 | I6: =MAX(0,E6-C6)
A7: 3 | B7: =가정!$B$25+(가정!$B$26-가정!$B$25)*(3-1)/(가정!$B$43-1) | C7: =C6*(1+B7) | D7: =B7/가정!$B$27 | E7: =C7*D7 | F7: =C7-E7 | G7: =1/(1+가정!$B$28)^3 | H7: =F7*G7 | I7: =MAX(0,E7-C7)
A8: 4 | B8: =가정!$B$25+(가정!$B$26-가정!$B$25)*(4-1)/(가정!$B$43-1) | C8: =C7*(1+B8) | D8: =B8/가정!$B$27 | E8: =C8*D8 | F8: =C8-E8 | G8: =1/(1+가정!$B$28)^4 | H8: =F8*G8 | I8: =MAX(0,E8-C8)
A9: 5 | B9: =가정!$B$25+(가정!$B$26-가정!$B$25)*(5-1)/(가정!$B$43-1) | C9: =C8*(1+B9) | D9: =B9/가정!$B$27 | E9: =C9*D9 | F9: =C9-E9 | G9: =1/(1+가정!$B$28)^5 | H9: =F9*G9 | I9: =MAX(0,E9-C9)
A10: 6 | B10: =가정!$B$25+(가정!$B$26-가정!$B$25)*(6-1)/(가정!$B$43-1) | C10: =C9*(1+B10) | D10: =B10/가정!$B$27 | E10: =C10*D10 | F10: =C10-E10 | G10: =1/(1+가정!$B$28)^6 | H10: =F10*G10 | I10: =MAX(0,E10-C10)
A11: 7 | B11: =가정!$B$25+(가정!$B$26-가정!$B$25)*(7-1)/(가정!$B$43-1) | C11: =C10*(1+B11) | D11: =B11/가정!$B$27 | E11: =C11*D11 | F11: =C11-E11 | G11: =1/(1+가정!$B$28)^7 | H11: =F11*G11 | I11: =MAX(0,E11-C11)
A12: 8 | B12: =가정!$B$25+(가정!$B$26-가정!$B$25)*(8-1)/(가정!$B$43-1) | C12: =C11*(1+B12) | D12: =B12/가정!$B$27 | E12: =C12*D12 | F12: =C12-E12 | G12: =1/(1+가정!$B$28)^8 | H12: =F12*G12 | I12: =MAX(0,E12-C12)
A13: 9 | B13: =가정!$B$25+(가정!$B$26-가정!$B$25)*(9-1)/(가정!$B$43-1) | C13: =C12*(1+B13) | D13: =B13/가정!$B$27 | E13: =C13*D13 | F13: =C13-E13 | G13: =1/(1+가정!$B$28)^9 | H13: =F13*G13 | I13: =MAX(0,E13-C13)
A14: 10 | B14: =가정!$B$25+(가정!$B$26-가정!$B$25)*(10-1)/(가정!$B$43-1) | C14: =C13*(1+B14) | D14: =B14/가정!$B$27 | E14: =C14*D14 | F14: =C14-E14 | G14: =1/(1+가정!$B$28)^10 | H14: =F14*G14 | I14: =MAX(0,E14-C14)
A15: 합계 | E15: =SUM(E5:E14) | F15: =SUM(F5:F14) | H15: =SUM(H5:H14) | I15: =SUM(I5:I14)
A17: 터미널 가치
A18: 11년차 NOPAT | B18: =C14*(1+가정!$B$29)
A19: 터미널 재투자율 = 영구성장률 ÷ 증분 ROIC | B19: =가정!$B$29/가정!$B$27
A20: 터미널 가치 = 11년차 FCF ÷ (할인율 − 영구성장률) | B20: =B18*(1-B19)/(가정!$B$28-가정!$B$29)
A21: 터미널 현재가치 | B21: =B20*G14
A23: 가치
A24: 예측기간 현재가치 | B24: =H15
A25: 터미널 현재가치 | B25: =B21
A26: 기업가치 (EV) | B26: =B24+B25
A27: + 순현금 | B27: =기준연도!$B$14
A28: 자기자본가치 | B28: =B26+B27
A29: 주당가치 (원) | B29: =B28*1000000000/가정!$B$7
A30: 시가총액 (십억원) | B30: =가정!$B$46/1000000000
A31: 시장가 대비 | B31: =(DCF_보수_reported!$B$28-B30)/B30
A32: 터미널 비중 | B32: =B21/B26
A34: 실현 가능성 점검
A35: 10년 누적 재투자 | B35: =E15
A36: 10년 누적 NOPAT | B36: =SUM(C5:C14)
A37: 재투자 ÷ NOPAT | B37: =B35/B36
A38: 1년차 재투자율 | B38: =D5
A39: 외부조달 필요액 (재투자율>100%인 해의 부족분 합계) | B39: =I15
A40: 10년 뒤 매출 (NOPAT 배율 × FY2025 매출) | B40: =C14/기준연도!$B$9*원자료!K$5
A41: 재투자율이 100%를 넘으면 그 차액은 증자나 차입으로 메워야 합니다. 이 계산은 그 희석과 이자를 기존 주주에게 청구하지 않으므로, 재투자율이 100%를 넘는 시나리오의 자기자본가치는 과대평가입니다.

Sheet DCF_보수_run
A1: 기준 7 (2) — 보수 시나리오 현금흐름할인
A2: 재투자율은 가정하지 않고 성장률에서 유도합니다: 재투자율 = 성장률 ÷ 증분 ROIC. 따라서 어떤 성장도 대가 없이 얻을 수 없습니다. 기준연도는 2026 상반기 연율화. 단위: 십억원.
A4: 연차 | B4: 성장률 | C4: NOPAT | D4: 재투자율 | E4: 재투자액 | F4: 자유현금흐름 | G4: 할인계수 | H4: 현재가치 | I4: 외부조달 필요
A5: 1 | B5: =가정!$B$25+(가정!$B$26-가정!$B$25)*(1-1)/(가정!$B$43-1) | C5: =기준연도!$C$9*(1+B5) | D5: =B5/가정!$B$27 | E5: =C5*D5 | F5: =C5-E5 | G5: =1/(1+가정!$B$28)^1 | H5: =F5*G5 | I5: =MAX(0,E5-C5)
A6: 2 | B6: =가정!$B$25+(가정!$B$26-가정!$B$25)*(2-1)/(가정!$B$43-1) | C6: =C5*(1+B6) | D6: =B6/가정!$B$27 | E6: =C6*D6 | F6: =C6-E6 | G6: =1/(1+가정!$B$28)^2 | H6: =F6*G6 | I6: =MAX(0,E6-C6)
A7: 3 | B7: =가정!$B$25+(가정!$B$26-가정!$B$25)*(3-1)/(가정!$B$43-1) | C7: =C6*(1+B7) | D7: =B7/가정!$B$27 | E7: =C7*D7 | F7: =C7-E7 | G7: =1/(1+가정!$B$28)^3 | H7: =F7*G7 | I7: =MAX(0,E7-C7)
A8: 4 | B8: =가정!$B$25+(가정!$B$26-가정!$B$25)*(4-1)/(가정!$B$43-1) | C8: =C7*(1+B8) | D8: =B8/가정!$B$27 | E8: =C8*D8 | F8: =C8-E8 | G8: =1/(1+가정!$B$28)^4 | H8: =F8*G8 | I8: =MAX(0,E8-C8)
A9: 5 | B9: =가정!$B$25+(가정!$B$26-가정!$B$25)*(5-1)/(가정!$B$43-1) | C9: =C8*(1+B9) | D9: =B9/가정!$B$27 | E9: =C9*D9 | F9: =C9-E9 | G9: =1/(1+가정!$B$28)^5 | H9: =F9*G9 | I9: =MAX(0,E9-C9)
A10: 6 | B10: =가정!$B$25+(가정!$B$26-가정!$B$25)*(6-1)/(가정!$B$43-1) | C10: =C9*(1+B10) | D10: =B10/가정!$B$27 | E10: =C10*D10 | F10: =C10-E10 | G10: =1/(1+가정!$B$28)^6 | H10: =F10*G10 | I10: =MAX(0,E10-C10)
A11: 7 | B11: =가정!$B$25+(가정!$B$26-가정!$B$25)*(7-1)/(가정!$B$43-1) | C11: =C10*(1+B11) | D11: =B11/가정!$B$27 | E11: =C11*D11 | F11: =C11-E11 | G11: =1/(1+가정!$B$28)^7 | H11: =F11*G11 | I11: =MAX(0,E11-C11)
A12: 8 | B12: =가정!$B$25+(가정!$B$26-가정!$B$25)*(8-1)/(가정!$B$43-1) | C12: =C11*(1+B12) | D12: =B12/가정!$B$27 | E12: =C12*D12 | F12: =C12-E12 | G12: =1/(1+가정!$B$28)^8 | H12: =F12*G12 | I12: =MAX(0,E12-C12)
A13: 9 | B13: =가정!$B$25+(가정!$B$26-가정!$B$25)*(9-1)/(가정!$B$43-1) | C13: =C12*(1+B13) | D13: =B13/가정!$B$27 | E13: =C13*D13 | F13: =C13-E13 | G13: =1/(1+가정!$B$28)^9 | H13: =F13*G13 | I13: =MAX(0,E13-C13)
A14: 10 | B14: =가정!$B$25+(가정!$B$26-가정!$B$25)*(10-1)/(가정!$B$43-1) | C14: =C13*(1+B14) | D14: =B14/가정!$B$27 | E14: =C14*D14 | F14: =C14-E14 | G14: =1/(1+가정!$B$28)^10 | H14: =F14*G14 | I14: =MAX(0,E14-C14)
A15: 합계 | E15: =SUM(E5:E14) | F15: =SUM(F5:F14) | H15: =SUM(H5:H14) | I15: =SUM(I5:I14)
A17: 터미널 가치
A18: 11년차 NOPAT | B18: =C14*(1+가정!$B$29)
A19: 터미널 재투자율 = 영구성장률 ÷ 증분 ROIC | B19: =가정!$B$29/가정!$B$27
A20: 터미널 가치 = 11년차 FCF ÷ (할인율 − 영구성장률) | B20: =B18*(1-B19)/(가정!$B$28-가정!$B$29)
A21: 터미널 현재가치 | B21: =B20*G14
A23: 가치
A24: 예측기간 현재가치 | B24: =H15
A25: 터미널 현재가치 | B25: =B21
A26: 기업가치 (EV) | B26: =B24+B25
A27: + 순현금 | B27: =기준연도!$B$14
A28: 자기자본가치 | B28: =B26+B27
A29: 주당가치 (원) | B29: =B28*1000000000/가정!$B$7
A30: 시가총액 (십억원) | B30: =가정!$B$46/1000000000
A31: 시장가 대비 | B31: =(DCF_보수_run!$B$28-B30)/B30
A32: 터미널 비중 | B32: =B21/B26
A34: 실현 가능성 점검
A35: 10년 누적 재투자 | B35: =E15
A36: 10년 누적 NOPAT | B36: =SUM(C5:C14)
A37: 재투자 ÷ NOPAT | B37: =B35/B36
A38: 1년차 재투자율 | B38: =D5
A39: 외부조달 필요액 (재투자율>100%인 해의 부족분 합계) | B39: =I15
A40: 10년 뒤 매출 (NOPAT 배율 × FY2025 매출) | B40: =C14/기준연도!$C$9*원자료!K$5
A41: 재투자율이 100%를 넘으면 그 차액은 증자나 차입으로 메워야 합니다. 이 계산은 그 희석과 이자를 기존 주주에게 청구하지 않으므로, 재투자율이 100%를 넘는 시나리오의 자기자본가치는 과대평가입니다.

Sheet DCF_보수
A1: 기준 7 (2) — 보수 시나리오 현금흐름할인
A2: 재투자율은 가정하지 않고 성장률에서 유도합니다: 재투자율 = 성장률 ÷ 증분 ROIC. 따라서 어떤 성장도 대가 없이 얻을 수 없습니다. 기준연도는 2026 연율화 · 현재 환율. 단위: 십억원.
A4: 연차 | B4: 성장률 | C4: NOPAT | D4: 재투자율 | E4: 재투자액 | F4: 자유현금흐름 | G4: 할인계수 | H4: 현재가치 | I4: 외부조달 필요
A5: 1 | B5: =가정!$B$25+(가정!$B$26-가정!$B$25)*(1-1)/(가정!$B$43-1) | C5: =기준연도!$D$9*(1+B5) | D5: =B5/가정!$B$27 | E5: =C5*D5 | F5: =C5-E5 | G5: =1/(1+가정!$B$28)^1 | H5: =F5*G5 | I5: =MAX(0,E5-C5)
A6: 2 | B6: =가정!$B$25+(가정!$B$26-가정!$B$25)*(2-1)/(가정!$B$43-1) | C6: =C5*(1+B6) | D6: =B6/가정!$B$27 | E6: =C6*D6 | F6: =C6-E6 | G6: =1/(1+가정!$B$28)^2 | H6: =F6*G6 | I6: =MAX(0,E6-C6)
A7: 3 | B7: =가정!$B$25+(가정!$B$26-가정!$B$25)*(3-1)/(가정!$B$43-1) | C7: =C6*(1+B7) | D7: =B7/가정!$B$27 | E7: =C7*D7 | F7: =C7-E7 | G7: =1/(1+가정!$B$28)^3 | H7: =F7*G7 | I7: =MAX(0,E7-C7)
A8: 4 | B8: =가정!$B$25+(가정!$B$26-가정!$B$25)*(4-1)/(가정!$B$43-1) | C8: =C7*(1+B8) | D8: =B8/가정!$B$27 | E8: =C8*D8 | F8: =C8-E8 | G8: =1/(1+가정!$B$28)^4 | H8: =F8*G8 | I8: =MAX(0,E8-C8)
A9: 5 | B9: =가정!$B$25+(가정!$B$26-가정!$B$25)*(5-1)/(가정!$B$43-1) | C9: =C8*(1+B9) | D9: =B9/가정!$B$27 | E9: =C9*D9 | F9: =C9-E9 | G9: =1/(1+가정!$B$28)^5 | H9: =F9*G9 | I9: =MAX(0,E9-C9)
A10: 6 | B10: =가정!$B$25+(가정!$B$26-가정!$B$25)*(6-1)/(가정!$B$43-1) | C10: =C9*(1+B10) | D10: =B10/가정!$B$27 | E10: =C10*D10 | F10: =C10-E10 | G10: =1/(1+가정!$B$28)^6 | H10: =F10*G10 | I10: =MAX(0,E10-C10)
A11: 7 | B11: =가정!$B$25+(가정!$B$26-가정!$B$25)*(7-1)/(가정!$B$43-1) | C11: =C10*(1+B11) | D11: =B11/가정!$B$27 | E11: =C11*D11 | F11: =C11-E11 | G11: =1/(1+가정!$B$28)^7 | H11: =F11*G11 | I11: =MAX(0,E11-C11)
A12: 8 | B12: =가정!$B$25+(가정!$B$26-가정!$B$25)*(8-1)/(가정!$B$43-1) | C12: =C11*(1+B12) | D12: =B12/가정!$B$27 | E12: =C12*D12 | F12: =C12-E12 | G12: =1/(1+가정!$B$28)^8 | H12: =F12*G12 | I12: =MAX(0,E12-C12)
A13: 9 | B13: =가정!$B$25+(가정!$B$26-가정!$B$25)*(9-1)/(가정!$B$43-1) | C13: =C12*(1+B13) | D13: =B13/가정!$B$27 | E13: =C13*D13 | F13: =C13-E13 | G13: =1/(1+가정!$B$28)^9 | H13: =F13*G13 | I13: =MAX(0,E13-C13)
A14: 10 | B14: =가정!$B$25+(가정!$B$26-가정!$B$25)*(10-1)/(가정!$B$43-1) | C14: =C13*(1+B14) | D14: =B14/가정!$B$27 | E14: =C14*D14 | F14: =C14-E14 | G14: =1/(1+가정!$B$28)^10 | H14: =F14*G14 | I14: =MAX(0,E14-C14)
A15: 합계 | E15: =SUM(E5:E14) | F15: =SUM(F5:F14) | H15: =SUM(H5:H14) | I15: =SUM(I5:I14)
A17: 터미널 가치
A18: 11년차 NOPAT | B18: =C14*(1+가정!$B$29)
A19: 터미널 재투자율 = 영구성장률 ÷ 증분 ROIC | B19: =가정!$B$29/가정!$B$27
A20: 터미널 가치 = 11년차 FCF ÷ (할인율 − 영구성장률) | B20: =B18*(1-B19)/(가정!$B$28-가정!$B$29)
A21: 터미널 현재가치 | B21: =B20*G14
A23: 가치
A24: 예측기간 현재가치 | B24: =H15
A25: 터미널 현재가치 | B25: =B21
A26: 기업가치 (EV) | B26: =B24+B25
A27: + 순현금 | B27: =기준연도!$B$14
A28: 자기자본가치 | B28: =B26+B27
A29: 주당가치 (원) | B29: =B28*1000000000/가정!$B$7
A30: 시가총액 (십억원) | B30: =가정!$B$46/1000000000
A31: 시장가 대비 | B31: =(DCF_보수!$B$28-B30)/B30
A32: 터미널 비중 | B32: =B21/B26
A34: 실현 가능성 점검
A35: 10년 누적 재투자 | B35: =E15
A36: 10년 누적 NOPAT | B36: =SUM(C5:C14)
A37: 재투자 ÷ NOPAT | B37: =B35/B36
A38: 1년차 재투자율 | B38: =D5
A39: 외부조달 필요액 (재투자율>100%인 해의 부족분 합계) | B39: =I15
A40: 10년 뒤 매출 (NOPAT 배율 × FY2025 매출) | B40: =C14/기준연도!$D$9*원자료!K$5
A41: 재투자율이 100%를 넘으면 그 차액은 증자나 차입으로 메워야 합니다. 이 계산은 그 희석과 이자를 기존 주주에게 청구하지 않으므로, 재투자율이 100%를 넘는 시나리오의 자기자본가치는 과대평가입니다.

Sheet DCF_중립_reported
A1: 기준 7 (2) — 중립 시나리오 현금흐름할인
A2: 재투자율은 가정하지 않고 성장률에서 유도합니다: 재투자율 = 성장률 ÷ 증분 ROIC. 따라서 어떤 성장도 대가 없이 얻을 수 없습니다. 기준연도는 FY2025 실적. 단위: 십억원.
A4: 연차 | B4: 성장률 | C4: NOPAT | D4: 재투자율 | E4: 재투자액 | F4: 자유현금흐름 | G4: 할인계수 | H4: 현재가치 | I4: 외부조달 필요
A5: 1 | B5: =가정!$B$31+(가정!$B$32-가정!$B$31)*(1-1)/(가정!$B$43-1) | C5: =기준연도!$B$9*(1+B5) | D5: =B5/가정!$B$33 | E5: =C5*D5 | F5: =C5-E5 | G5: =1/(1+가정!$B$34)^1 | H5: =F5*G5 | I5: =MAX(0,E5-C5)
A6: 2 | B6: =가정!$B$31+(가정!$B$32-가정!$B$31)*(2-1)/(가정!$B$43-1) | C6: =C5*(1+B6) | D6: =B6/가정!$B$33 | E6: =C6*D6 | F6: =C6-E6 | G6: =1/(1+가정!$B$34)^2 | H6: =F6*G6 | I6: =MAX(0,E6-C6)
A7: 3 | B7: =가정!$B$31+(가정!$B$32-가정!$B$31)*(3-1)/(가정!$B$43-1) | C7: =C6*(1+B7) | D7: =B7/가정!$B$33 | E7: =C7*D7 | F7: =C7-E7 | G7: =1/(1+가정!$B$34)^3 | H7: =F7*G7 | I7: =MAX(0,E7-C7)
A8: 4 | B8: =가정!$B$31+(가정!$B$32-가정!$B$31)*(4-1)/(가정!$B$43-1) | C8: =C7*(1+B8) | D8: =B8/가정!$B$33 | E8: =C8*D8 | F8: =C8-E8 | G8: =1/(1+가정!$B$34)^4 | H8: =F8*G8 | I8: =MAX(0,E8-C8)
A9: 5 | B9: =가정!$B$31+(가정!$B$32-가정!$B$31)*(5-1)/(가정!$B$43-1) | C9: =C8*(1+B9) | D9: =B9/가정!$B$33 | E9: =C9*D9 | F9: =C9-E9 | G9: =1/(1+가정!$B$34)^5 | H9: =F9*G9 | I9: =MAX(0,E9-C9)
A10: 6 | B10: =가정!$B$31+(가정!$B$32-가정!$B$31)*(6-1)/(가정!$B$43-1) | C10: =C9*(1+B10) | D10: =B10/가정!$B$33 | E10: =C10*D10 | F10: =C10-E10 | G10: =1/(1+가정!$B$34)^6 | H10: =F10*G10 | I10: =MAX(0,E10-C10)
A11: 7 | B11: =가정!$B$31+(가정!$B$32-가정!$B$31)*(7-1)/(가정!$B$43-1) | C11: =C10*(1+B11) | D11: =B11/가정!$B$33 | E11: =C11*D11 | F11: =C11-E11 | G11: =1/(1+가정!$B$34)^7 | H11: =F11*G11 | I11: =MAX(0,E11-C11)
A12: 8 | B12: =가정!$B$31+(가정!$B$32-가정!$B$31)*(8-1)/(가정!$B$43-1) | C12: =C11*(1+B12) | D12: =B12/가정!$B$33 | E12: =C12*D12 | F12: =C12-E12 | G12: =1/(1+가정!$B$34)^8 | H12: =F12*G12 | I12: =MAX(0,E12-C12)
A13: 9 | B13: =가정!$B$31+(가정!$B$32-가정!$B$31)*(9-1)/(가정!$B$43-1) | C13: =C12*(1+B13) | D13: =B13/가정!$B$33 | E13: =C13*D13 | F13: =C13-E13 | G13: =1/(1+가정!$B$34)^9 | H13: =F13*G13 | I13: =MAX(0,E13-C13)
A14: 10 | B14: =가정!$B$31+(가정!$B$32-가정!$B$31)*(10-1)/(가정!$B$43-1) | C14: =C13*(1+B14) | D14: =B14/가정!$B$33 | E14: =C14*D14 | F14: =C14-E14 | G14: =1/(1+가정!$B$34)^10 | H14: =F14*G14 | I14: =MAX(0,E14-C14)
A15: 합계 | E15: =SUM(E5:E14) | F15: =SUM(F5:F14) | H15: =SUM(H5:H14) | I15: =SUM(I5:I14)
A17: 터미널 가치
A18: 11년차 NOPAT | B18: =C14*(1+가정!$B$35)
A19: 터미널 재투자율 = 영구성장률 ÷ 증분 ROIC | B19: =가정!$B$35/가정!$B$33
A20: 터미널 가치 = 11년차 FCF ÷ (할인율 − 영구성장률) | B20: =B18*(1-B19)/(가정!$B$34-가정!$B$35)
A21: 터미널 현재가치 | B21: =B20*G14
A23: 가치
A24: 예측기간 현재가치 | B24: =H15
A25: 터미널 현재가치 | B25: =B21
A26: 기업가치 (EV) | B26: =B24+B25
A27: + 순현금 | B27: =기준연도!$B$14
A28: 자기자본가치 | B28: =B26+B27
A29: 주당가치 (원) | B29: =B28*1000000000/가정!$B$7
A30: 시가총액 (십억원) | B30: =가정!$B$46/1000000000
A31: 시장가 대비 | B31: =(DCF_중립_reported!$B$28-B30)/B30
A32: 터미널 비중 | B32: =B21/B26
A34: 실현 가능성 점검
A35: 10년 누적 재투자 | B35: =E15
A36: 10년 누적 NOPAT | B36: =SUM(C5:C14)
A37: 재투자 ÷ NOPAT | B37: =B35/B36
A38: 1년차 재투자율 | B38: =D5
A39: 외부조달 필요액 (재투자율>100%인 해의 부족분 합계) | B39: =I15
A40: 10년 뒤 매출 (NOPAT 배율 × FY2025 매출) | B40: =C14/기준연도!$B$9*원자료!K$5
A41: 재투자율이 100%를 넘으면 그 차액은 증자나 차입으로 메워야 합니다. 이 계산은 그 희석과 이자를 기존 주주에게 청구하지 않으므로, 재투자율이 100%를 넘는 시나리오의 자기자본가치는 과대평가입니다.

Sheet DCF_중립_run
A1: 기준 7 (2) — 중립 시나리오 현금흐름할인
A2: 재투자율은 가정하지 않고 성장률에서 유도합니다: 재투자율 = 성장률 ÷ 증분 ROIC. 따라서 어떤 성장도 대가 없이 얻을 수 없습니다. 기준연도는 2026 상반기 연율화. 단위: 십억원.
A4: 연차 | B4: 성장률 | C4: NOPAT | D4: 재투자율 | E4: 재투자액 | F4: 자유현금흐름 | G4: 할인계수 | H4: 현재가치 | I4: 외부조달 필요
A5: 1 | B5: =가정!$B$31+(가정!$B$32-가정!$B$31)*(1-1)/(가정!$B$43-1) | C5: =기준연도!$C$9*(1+B5) | D5: =B5/가정!$B$33 | E5: =C5*D5 | F5: =C5-E5 | G5: =1/(1+가정!$B$34)^1 | H5: =F5*G5 | I5: =MAX(0,E5-C5)
A6: 2 | B6: =가정!$B$31+(가정!$B$32-가정!$B$31)*(2-1)/(가정!$B$43-1) | C6: =C5*(1+B6) | D6: =B6/가정!$B$33 | E6: =C6*D6 | F6: =C6-E6 | G6: =1/(1+가정!$B$34)^2 | H6: =F6*G6 | I6: =MAX(0,E6-C6)
A7: 3 | B7: =가정!$B$31+(가정!$B$32-가정!$B$31)*(3-1)/(가정!$B$43-1) | C7: =C6*(1+B7) | D7: =B7/가정!$B$33 | E7: =C7*D7 | F7: =C7-E7 | G7: =1/(1+가정!$B$34)^3 | H7: =F7*G7 | I7: =MAX(0,E7-C7)
A8: 4 | B8: =가정!$B$31+(가정!$B$32-가정!$B$31)*(4-1)/(가정!$B$43-1) | C8: =C7*(1+B8) | D8: =B8/가정!$B$33 | E8: =C8*D8 | F8: =C8-E8 | G8: =1/(1+가정!$B$34)^4 | H8: =F8*G8 | I8: =MAX(0,E8-C8)
A9: 5 | B9: =가정!$B$31+(가정!$B$32-가정!$B$31)*(5-1)/(가정!$B$43-1) | C9: =C8*(1+B9) | D9: =B9/가정!$B$33 | E9: =C9*D9 | F9: =C9-E9 | G9: =1/(1+가정!$B$34)^5 | H9: =F9*G9 | I9: =MAX(0,E9-C9)
A10: 6 | B10: =가정!$B$31+(가정!$B$32-가정!$B$31)*(6-1)/(가정!$B$43-1) | C10: =C9*(1+B10) | D10: =B10/가정!$B$33 | E10: =C10*D10 | F10: =C10-E10 | G10: =1/(1+가정!$B$34)^6 | H10: =F10*G10 | I10: =MAX(0,E10-C10)
A11: 7 | B11: =가정!$B$31+(가정!$B$32-가정!$B$31)*(7-1)/(가정!$B$43-1) | C11: =C10*(1+B11) | D11: =B11/가정!$B$33 | E11: =C11*D11 | F11: =C11-E11 | G11: =1/(1+가정!$B$34)^7 | H11: =F11*G11 | I11: =MAX(0,E11-C11)
A12: 8 | B12: =가정!$B$31+(가정!$B$32-가정!$B$31)*(8-1)/(가정!$B$43-1) | C12: =C11*(1+B12) | D12: =B12/가정!$B$33 | E12: =C12*D12 | F12: =C12-E12 | G12: =1/(1+가정!$B$34)^8 | H12: =F12*G12 | I12: =MAX(0,E12-C12)
A13: 9 | B13: =가정!$B$31+(가정!$B$32-가정!$B$31)*(9-1)/(가정!$B$43-1) | C13: =C12*(1+B13) | D13: =B13/가정!$B$33 | E13: =C13*D13 | F13: =C13-E13 | G13: =1/(1+가정!$B$34)^9 | H13: =F13*G13 | I13: =MAX(0,E13-C13)
A14: 10 | B14: =가정!$B$31+(가정!$B$32-가정!$B$31)*(10-1)/(가정!$B$43-1) | C14: =C13*(1+B14) | D14: =B14/가정!$B$33 | E14: =C14*D14 | F14: =C14-E14 | G14: =1/(1+가정!$B$34)^10 | H14: =F14*G14 | I14: =MAX(0,E14-C14)
A15: 합계 | E15: =SUM(E5:E14) | F15: =SUM(F5:F14) | H15: =SUM(H5:H14) | I15: =SUM(I5:I14)
A17: 터미널 가치
A18: 11년차 NOPAT | B18: =C14*(1+가정!$B$35)
A19: 터미널 재투자율 = 영구성장률 ÷ 증분 ROIC | B19: =가정!$B$35/가정!$B$33
A20: 터미널 가치 = 11년차 FCF ÷ (할인율 − 영구성장률) | B20: =B18*(1-B19)/(가정!$B$34-가정!$B$35)
A21: 터미널 현재가치 | B21: =B20*G14
A23: 가치
A24: 예측기간 현재가치 | B24: =H15
A25: 터미널 현재가치 | B25: =B21
A26: 기업가치 (EV) | B26: =B24+B25
A27: + 순현금 | B27: =기준연도!$B$14
A28: 자기자본가치 | B28: =B26+B27
A29: 주당가치 (원) | B29: =B28*1000000000/가정!$B$7
A30: 시가총액 (십억원) | B30: =가정!$B$46/1000000000
A31: 시장가 대비 | B31: =(DCF_중립_run!$B$28-B30)/B30
A32: 터미널 비중 | B32: =B21/B26
A34: 실현 가능성 점검
A35: 10년 누적 재투자 | B35: =E15
A36: 10년 누적 NOPAT | B36: =SUM(C5:C14)
A37: 재투자 ÷ NOPAT | B37: =B35/B36
A38: 1년차 재투자율 | B38: =D5
A39: 외부조달 필요액 (재투자율>100%인 해의 부족분 합계) | B39: =I15
A40: 10년 뒤 매출 (NOPAT 배율 × FY2025 매출) | B40: =C14/기준연도!$C$9*원자료!K$5
A41: 재투자율이 100%를 넘으면 그 차액은 증자나 차입으로 메워야 합니다. 이 계산은 그 희석과 이자를 기존 주주에게 청구하지 않으므로, 재투자율이 100%를 넘는 시나리오의 자기자본가치는 과대평가입니다.

Sheet DCF_중립
A1: 기준 7 (2) — 중립 시나리오 현금흐름할인
A2: 재투자율은 가정하지 않고 성장률에서 유도합니다: 재투자율 = 성장률 ÷ 증분 ROIC. 따라서 어떤 성장도 대가 없이 얻을 수 없습니다. 기준연도는 2026 연율화 · 현재 환율. 단위: 십억원.
A4: 연차 | B4: 성장률 | C4: NOPAT | D4: 재투자율 | E4: 재투자액 | F4: 자유현금흐름 | G4: 할인계수 | H4: 현재가치 | I4: 외부조달 필요
A5: 1 | B5: =가정!$B$31+(가정!$B$32-가정!$B$31)*(1-1)/(가정!$B$43-1) | C5: =기준연도!$D$9*(1+B5) | D5: =B5/가정!$B$33 | E5: =C5*D5 | F5: =C5-E5 | G5: =1/(1+가정!$B$34)^1 | H5: =F5*G5 | I5: =MAX(0,E5-C5)
A6: 2 | B6: =가정!$B$31+(가정!$B$32-가정!$B$31)*(2-1)/(가정!$B$43-1) | C6: =C5*(1+B6) | D6: =B6/가정!$B$33 | E6: =C6*D6 | F6: =C6-E6 | G6: =1/(1+가정!$B$34)^2 | H6: =F6*G6 | I6: =MAX(0,E6-C6)
A7: 3 | B7: =가정!$B$31+(가정!$B$32-가정!$B$31)*(3-1)/(가정!$B$43-1) | C7: =C6*(1+B7) | D7: =B7/가정!$B$33 | E7: =C7*D7 | F7: =C7-E7 | G7: =1/(1+가정!$B$34)^3 | H7: =F7*G7 | I7: =MAX(0,E7-C7)
A8: 4 | B8: =가정!$B$31+(가정!$B$32-가정!$B$31)*(4-1)/(가정!$B$43-1) | C8: =C7*(1+B8) | D8: =B8/가정!$B$33 | E8: =C8*D8 | F8: =C8-E8 | G8: =1/(1+가정!$B$34)^4 | H8: =F8*G8 | I8: =MAX(0,E8-C8)
A9: 5 | B9: =가정!$B$31+(가정!$B$32-가정!$B$31)*(5-1)/(가정!$B$43-1) | C9: =C8*(1+B9) | D9: =B9/가정!$B$33 | E9: =C9*D9 | F9: =C9-E9 | G9: =1/(1+가정!$B$34)^5 | H9: =F9*G9 | I9: =MAX(0,E9-C9)
A10: 6 | B10: =가정!$B$31+(가정!$B$32-가정!$B$31)*(6-1)/(가정!$B$43-1) | C10: =C9*(1+B10) | D10: =B10/가정!$B$33 | E10: =C10*D10 | F10: =C10-E10 | G10: =1/(1+가정!$B$34)^6 | H10: =F10*G10 | I10: =MAX(0,E10-C10)
A11: 7 | B11: =가정!$B$31+(가정!$B$32-가정!$B$31)*(7-1)/(가정!$B$43-1) | C11: =C10*(1+B11) | D11: =B11/가정!$B$33 | E11: =C11*D11 | F11: =C11-E11 | G11: =1/(1+가정!$B$34)^7 | H11: =F11*G11 | I11: =MAX(0,E11-C11)
A12: 8 | B12: =가정!$B$31+(가정!$B$32-가정!$B$31)*(8-1)/(가정!$B$43-1) | C12: =C11*(1+B12) | D12: =B12/가정!$B$33 | E12: =C12*D12 | F12: =C12-E12 | G12: =1/(1+가정!$B$34)^8 | H12: =F12*G12 | I12: =MAX(0,E12-C12)
A13: 9 | B13: =가정!$B$31+(가정!$B$32-가정!$B$31)*(9-1)/(가정!$B$43-1) | C13: =C12*(1+B13) | D13: =B13/가정!$B$33 | E13: =C13*D13 | F13: =C13-E13 | G13: =1/(1+가정!$B$34)^9 | H13: =F13*G13 | I13: =MAX(0,E13-C13)
A14: 10 | B14: =가정!$B$31+(가정!$B$32-가정!$B$31)*(10-1)/(가정!$B$43-1) | C14: =C13*(1+B14) | D14: =B14/가정!$B$33 | E14: =C14*D14 | F14: =C14-E14 | G14: =1/(1+가정!$B$34)^10 | H14: =F14*G14 | I14: =MAX(0,E14-C14)
A15: 합계 | E15: =SUM(E5:E14) | F15: =SUM(F5:F14) | H15: =SUM(H5:H14) | I15: =SUM(I5:I14)
A17: 터미널 가치
A18: 11년차 NOPAT | B18: =C14*(1+가정!$B$35)
A19: 터미널 재투자율 = 영구성장률 ÷ 증분 ROIC | B19: =가정!$B$35/가정!$B$33
A20: 터미널 가치 = 11년차 FCF ÷ (할인율 − 영구성장률) | B20: =B18*(1-B19)/(가정!$B$34-가정!$B$35)
A21: 터미널 현재가치 | B21: =B20*G14
A23: 가치
A24: 예측기간 현재가치 | B24: =H15
A25: 터미널 현재가치 | B25: =B21
A26: 기업가치 (EV) | B26: =B24+B25
A27: + 순현금 | B27: =기준연도!$B$14
A28: 자기자본가치 | B28: =B26+B27
A29: 주당가치 (원) | B29: =B28*1000000000/가정!$B$7
A30: 시가총액 (십억원) | B30: =가정!$B$46/1000000000
A31: 시장가 대비 | B31: =(DCF_중립!$B$28-B30)/B30
A32: 터미널 비중 | B32: =B21/B26
A34: 실현 가능성 점검
A35: 10년 누적 재투자 | B35: =E15
A36: 10년 누적 NOPAT | B36: =SUM(C5:C14)
A37: 재투자 ÷ NOPAT | B37: =B35/B36
A38: 1년차 재투자율 | B38: =D5
A39: 외부조달 필요액 (재투자율>100%인 해의 부족분 합계) | B39: =I15
A40: 10년 뒤 매출 (NOPAT 배율 × FY2025 매출) | B40: =C14/기준연도!$D$9*원자료!K$5
A41: 재투자율이 100%를 넘으면 그 차액은 증자나 차입으로 메워야 합니다. 이 계산은 그 희석과 이자를 기존 주주에게 청구하지 않으므로, 재투자율이 100%를 넘는 시나리오의 자기자본가치는 과대평가입니다.

Sheet DCF_낙관_reported
A1: 기준 7 (2) — 낙관 시나리오 현금흐름할인
A2: 재투자율은 가정하지 않고 성장률에서 유도합니다: 재투자율 = 성장률 ÷ 증분 ROIC. 따라서 어떤 성장도 대가 없이 얻을 수 없습니다. 기준연도는 FY2025 실적. 단위: 십억원.
A4: 연차 | B4: 성장률 | C4: NOPAT | D4: 재투자율 | E4: 재투자액 | F4: 자유현금흐름 | G4: 할인계수 | H4: 현재가치 | I4: 외부조달 필요
A5: 1 | B5: =가정!$B$37+(가정!$B$38-가정!$B$37)*(1-1)/(가정!$B$43-1) | C5: =기준연도!$B$9*(1+B5) | D5: =B5/가정!$B$39 | E5: =C5*D5 | F5: =C5-E5 | G5: =1/(1+가정!$B$40)^1 | H5: =F5*G5 | I5: =MAX(0,E5-C5)
A6: 2 | B6: =가정!$B$37+(가정!$B$38-가정!$B$37)*(2-1)/(가정!$B$43-1) | C6: =C5*(1+B6) | D6: =B6/가정!$B$39 | E6: =C6*D6 | F6: =C6-E6 | G6: =1/(1+가정!$B$40)^2 | H6: =F6*G6 | I6: =MAX(0,E6-C6)
A7: 3 | B7: =가정!$B$37+(가정!$B$38-가정!$B$37)*(3-1)/(가정!$B$43-1) | C7: =C6*(1+B7) | D7: =B7/가정!$B$39 | E7: =C7*D7 | F7: =C7-E7 | G7: =1/(1+가정!$B$40)^3 | H7: =F7*G7 | I7: =MAX(0,E7-C7)
A8: 4 | B8: =가정!$B$37+(가정!$B$38-가정!$B$37)*(4-1)/(가정!$B$43-1) | C8: =C7*(1+B8) | D8: =B8/가정!$B$39 | E8: =C8*D8 | F8: =C8-E8 | G8: =1/(1+가정!$B$40)^4 | H8: =F8*G8 | I8: =MAX(0,E8-C8)
A9: 5 | B9: =가정!$B$37+(가정!$B$38-가정!$B$37)*(5-1)/(가정!$B$43-1) | C9: =C8*(1+B9) | D9: =B9/가정!$B$39 | E9: =C9*D9 | F9: =C9-E9 | G9: =1/(1+가정!$B$40)^5 | H9: =F9*G9 | I9: =MAX(0,E9-C9)
A10: 6 | B10: =가정!$B$37+(가정!$B$38-가정!$B$37)*(6-1)/(가정!$B$43-1) | C10: =C9*(1+B10) | D10: =B10/가정!$B$39 | E10: =C10*D10 | F10: =C10-E10 | G10: =1/(1+가정!$B$40)^6 | H10: =F10*G10 | I10: =MAX(0,E10-C10)
A11: 7 | B11: =가정!$B$37+(가정!$B$38-가정!$B$37)*(7-1)/(가정!$B$43-1) | C11: =C10*(1+B11) | D11: =B11/가정!$B$39 | E11: =C11*D11 | F11: =C11-E11 | G11: =1/(1+가정!$B$40)^7 | H11: =F11*G11 | I11: =MAX(0,E11-C11)
A12: 8 | B12: =가정!$B$37+(가정!$B$38-가정!$B$37)*(8-1)/(가정!$B$43-1) | C12: =C11*(1+B12) | D12: =B12/가정!$B$39 | E12: =C12*D12 | F12: =C12-E12 | G12: =1/(1+가정!$B$40)^8 | H12: =F12*G12 | I12: =MAX(0,E12-C12)
A13: 9 | B13: =가정!$B$37+(가정!$B$38-가정!$B$37)*(9-1)/(가정!$B$43-1) | C13: =C12*(1+B13) | D13: =B13/가정!$B$39 | E13: =C13*D13 | F13: =C13-E13 | G13: =1/(1+가정!$B$40)^9 | H13: =F13*G13 | I13: =MAX(0,E13-C13)
A14: 10 | B14: =가정!$B$37+(가정!$B$38-가정!$B$37)*(10-1)/(가정!$B$43-1) | C14: =C13*(1+B14) | D14: =B14/가정!$B$39 | E14: =C14*D14 | F14: =C14-E14 | G14: =1/(1+가정!$B$40)^10 | H14: =F14*G14 | I14: =MAX(0,E14-C14)
A15: 합계 | E15: =SUM(E5:E14) | F15: =SUM(F5:F14) | H15: =SUM(H5:H14) | I15: =SUM(I5:I14)
A17: 터미널 가치
A18: 11년차 NOPAT | B18: =C14*(1+가정!$B$41)
A19: 터미널 재투자율 = 영구성장률 ÷ 증분 ROIC | B19: =가정!$B$41/가정!$B$39
A20: 터미널 가치 = 11년차 FCF ÷ (할인율 − 영구성장률) | B20: =B18*(1-B19)/(가정!$B$40-가정!$B$41)
A21: 터미널 현재가치 | B21: =B20*G14
A23: 가치
A24: 예측기간 현재가치 | B24: =H15
A25: 터미널 현재가치 | B25: =B21
A26: 기업가치 (EV) | B26: =B24+B25
A27: + 순현금 | B27: =기준연도!$B$14
A28: 자기자본가치 | B28: =B26+B27
A29: 주당가치 (원) | B29: =B28*1000000000/가정!$B$7
A30: 시가총액 (십억원) | B30: =가정!$B$46/1000000000
A31: 시장가 대비 | B31: =(DCF_낙관_reported!$B$28-B30)/B30
A32: 터미널 비중 | B32: =B21/B26
A34: 실현 가능성 점검
A35: 10년 누적 재투자 | B35: =E15
A36: 10년 누적 NOPAT | B36: =SUM(C5:C14)
A37: 재투자 ÷ NOPAT | B37: =B35/B36
A38: 1년차 재투자율 | B38: =D5
A39: 외부조달 필요액 (재투자율>100%인 해의 부족분 합계) | B39: =I15
A40: 10년 뒤 매출 (NOPAT 배율 × FY2025 매출) | B40: =C14/기준연도!$B$9*원자료!K$5
A41: 재투자율이 100%를 넘으면 그 차액은 증자나 차입으로 메워야 합니다. 이 계산은 그 희석과 이자를 기존 주주에게 청구하지 않으므로, 재투자율이 100%를 넘는 시나리오의 자기자본가치는 과대평가입니다.

Sheet DCF_낙관_run
A1: 기준 7 (2) — 낙관 시나리오 현금흐름할인
A2: 재투자율은 가정하지 않고 성장률에서 유도합니다: 재투자율 = 성장률 ÷ 증분 ROIC. 따라서 어떤 성장도 대가 없이 얻을 수 없습니다. 기준연도는 2026 상반기 연율화. 단위: 십억원.
A4: 연차 | B4: 성장률 | C4: NOPAT | D4: 재투자율 | E4: 재투자액 | F4: 자유현금흐름 | G4: 할인계수 | H4: 현재가치 | I4: 외부조달 필요
A5: 1 | B5: =가정!$B$37+(가정!$B$38-가정!$B$37)*(1-1)/(가정!$B$43-1) | C5: =기준연도!$C$9*(1+B5) | D5: =B5/가정!$B$39 | E5: =C5*D5 | F5: =C5-E5 | G5: =1/(1+가정!$B$40)^1 | H5: =F5*G5 | I5: =MAX(0,E5-C5)
A6: 2 | B6: =가정!$B$37+(가정!$B$38-가정!$B$37)*(2-1)/(가정!$B$43-1) | C6: =C5*(1+B6) | D6: =B6/가정!$B$39 | E6: =C6*D6 | F6: =C6-E6 | G6: =1/(1+가정!$B$40)^2 | H6: =F6*G6 | I6: =MAX(0,E6-C6)
A7: 3 | B7: =가정!$B$37+(가정!$B$38-가정!$B$37)*(3-1)/(가정!$B$43-1) | C7: =C6*(1+B7) | D7: =B7/가정!$B$39 | E7: =C7*D7 | F7: =C7-E7 | G7: =1/(1+가정!$B$40)^3 | H7: =F7*G7 | I7: =MAX(0,E7-C7)
A8: 4 | B8: =가정!$B$37+(가정!$B$38-가정!$B$37)*(4-1)/(가정!$B$43-1) | C8: =C7*(1+B8) | D8: =B8/가정!$B$39 | E8: =C8*D8 | F8: =C8-E8 | G8: =1/(1+가정!$B$40)^4 | H8: =F8*G8 | I8: =MAX(0,E8-C8)
A9: 5 | B9: =가정!$B$37+(가정!$B$38-가정!$B$37)*(5-1)/(가정!$B$43-1) | C9: =C8*(1+B9) | D9: =B9/가정!$B$39 | E9: =C9*D9 | F9: =C9-E9 | G9: =1/(1+가정!$B$40)^5 | H9: =F9*G9 | I9: =MAX(0,E9-C9)
A10: 6 | B10: =가정!$B$37+(가정!$B$38-가정!$B$37)*(6-1)/(가정!$B$43-1) | C10: =C9*(1+B10) | D10: =B10/가정!$B$39 | E10: =C10*D10 | F10: =C10-E10 | G10: =1/(1+가정!$B$40)^6 | H10: =F10*G10 | I10: =MAX(0,E10-C10)
A11: 7 | B11: =가정!$B$37+(가정!$B$38-가정!$B$37)*(7-1)/(가정!$B$43-1) | C11: =C10*(1+B11) | D11: =B11/가정!$B$39 | E11: =C11*D11 | F11: =C11-E11 | G11: =1/(1+가정!$B$40)^7 | H11: =F11*G11 | I11: =MAX(0,E11-C11)
A12: 8 | B12: =가정!$B$37+(가정!$B$38-가정!$B$37)*(8-1)/(가정!$B$43-1) | C12: =C11*(1+B12) | D12: =B12/가정!$B$39 | E12: =C12*D12 | F12: =C12-E12 | G12: =1/(1+가정!$B$40)^8 | H12: =F12*G12 | I12: =MAX(0,E12-C12)
A13: 9 | B13: =가정!$B$37+(가정!$B$38-가정!$B$37)*(9-1)/(가정!$B$43-1) | C13: =C12*(1+B13) | D13: =B13/가정!$B$39 | E13: =C13*D13 | F13: =C13-E13 | G13: =1/(1+가정!$B$40)^9 | H13: =F13*G13 | I13: =MAX(0,E13-C13)
A14: 10 | B14: =가정!$B$37+(가정!$B$38-가정!$B$37)*(10-1)/(가정!$B$43-1) | C14: =C13*(1+B14) | D14: =B14/가정!$B$39 | E14: =C14*D14 | F14: =C14-E14 | G14: =1/(1+가정!$B$40)^10 | H14: =F14*G14 | I14: =MAX(0,E14-C14)
A15: 합계 | E15: =SUM(E5:E14) | F15: =SUM(F5:F14) | H15: =SUM(H5:H14) | I15: =SUM(I5:I14)
A17: 터미널 가치
A18: 11년차 NOPAT | B18: =C14*(1+가정!$B$41)
A19: 터미널 재투자율 = 영구성장률 ÷ 증분 ROIC | B19: =가정!$B$41/가정!$B$39
A20: 터미널 가치 = 11년차 FCF ÷ (할인율 − 영구성장률) | B20: =B18*(1-B19)/(가정!$B$40-가정!$B$41)
A21: 터미널 현재가치 | B21: =B20*G14
A23: 가치
A24: 예측기간 현재가치 | B24: =H15
A25: 터미널 현재가치 | B25: =B21
A26: 기업가치 (EV) | B26: =B24+B25
A27: + 순현금 | B27: =기준연도!$B$14
A28: 자기자본가치 | B28: =B26+B27
A29: 주당가치 (원) | B29: =B28*1000000000/가정!$B$7
A30: 시가총액 (십억원) | B30: =가정!$B$46/1000000000
A31: 시장가 대비 | B31: =(DCF_낙관_run!$B$28-B30)/B30
A32: 터미널 비중 | B32: =B21/B26
A34: 실현 가능성 점검
A35: 10년 누적 재투자 | B35: =E15
A36: 10년 누적 NOPAT | B36: =SUM(C5:C14)
A37: 재투자 ÷ NOPAT | B37: =B35/B36
A38: 1년차 재투자율 | B38: =D5
A39: 외부조달 필요액 (재투자율>100%인 해의 부족분 합계) | B39: =I15
A40: 10년 뒤 매출 (NOPAT 배율 × FY2025 매출) | B40: =C14/기준연도!$C$9*원자료!K$5
A41: 재투자율이 100%를 넘으면 그 차액은 증자나 차입으로 메워야 합니다. 이 계산은 그 희석과 이자를 기존 주주에게 청구하지 않으므로, 재투자율이 100%를 넘는 시나리오의 자기자본가치는 과대평가입니다.

Sheet DCF_낙관
A1: 기준 7 (2) — 낙관 시나리오 현금흐름할인
A2: 재투자율은 가정하지 않고 성장률에서 유도합니다: 재투자율 = 성장률 ÷ 증분 ROIC. 따라서 어떤 성장도 대가 없이 얻을 수 없습니다. 기준연도는 2026 연율화 · 현재 환율. 단위: 십억원.
A4: 연차 | B4: 성장률 | C4: NOPAT | D4: 재투자율 | E4: 재투자액 | F4: 자유현금흐름 | G4: 할인계수 | H4: 현재가치 | I4: 외부조달 필요
A5: 1 | B5: =가정!$B$37+(가정!$B$38-가정!$B$37)*(1-1)/(가정!$B$43-1) | C5: =기준연도!$D$9*(1+B5) | D5: =B5/가정!$B$39 | E5: =C5*D5 | F5: =C5-E5 | G5: =1/(1+가정!$B$40)^1 | H5: =F5*G5 | I5: =MAX(0,E5-C5)
A6: 2 | B6: =가정!$B$37+(가정!$B$38-가정!$B$37)*(2-1)/(가정!$B$43-1) | C6: =C5*(1+B6) | D6: =B6/가정!$B$39 | E6: =C6*D6 | F6: =C6-E6 | G6: =1/(1+가정!$B$40)^2 | H6: =F6*G6 | I6: =MAX(0,E6-C6)
A7: 3 | B7: =가정!$B$37+(가정!$B$38-가정!$B$37)*(3-1)/(가정!$B$43-1) | C7: =C6*(1+B7) | D7: =B7/가정!$B$39 | E7: =C7*D7 | F7: =C7-E7 | G7: =1/(1+가정!$B$40)^3 | H7: =F7*G7 | I7: =MAX(0,E7-C7)
A8: 4 | B8: =가정!$B$37+(가정!$B$38-가정!$B$37)*(4-1)/(가정!$B$43-1) | C8: =C7*(1+B8) | D8: =B8/가정!$B$39 | E8: =C8*D8 | F8: =C8-E8 | G8: =1/(1+가정!$B$40)^4 | H8: =F8*G8 | I8: =MAX(0,E8-C8)
A9: 5 | B9: =가정!$B$37+(가정!$B$38-가정!$B$37)*(5-1)/(가정!$B$43-1) | C9: =C8*(1+B9) | D9: =B9/가정!$B$39 | E9: =C9*D9 | F9: =C9-E9 | G9: =1/(1+가정!$B$40)^5 | H9: =F9*G9 | I9: =MAX(0,E9-C9)
A10: 6 | B10: =가정!$B$37+(가정!$B$38-가정!$B$37)*(6-1)/(가정!$B$43-1) | C10: =C9*(1+B10) | D10: =B10/가정!$B$39 | E10: =C10*D10 | F10: =C10-E10 | G10: =1/(1+가정!$B$40)^6 | H10: =F10*G10 | I10: =MAX(0,E10-C10)
A11: 7 | B11: =가정!$B$37+(가정!$B$38-가정!$B$37)*(7-1)/(가정!$B$43-1) | C11: =C10*(1+B11) | D11: =B11/가정!$B$39 | E11: =C11*D11 | F11: =C11-E11 | G11: =1/(1+가정!$B$40)^7 | H11: =F11*G11 | I11: =MAX(0,E11-C11)
A12: 8 | B12: =가정!$B$37+(가정!$B$38-가정!$B$37)*(8-1)/(가정!$B$43-1) | C12: =C11*(1+B12) | D12: =B12/가정!$B$39 | E12: =C12*D12 | F12: =C12-E12 | G12: =1/(1+가정!$B$40)^8 | H12: =F12*G12 | I12: =MAX(0,E12-C12)
A13: 9 | B13: =가정!$B$37+(가정!$B$38-가정!$B$37)*(9-1)/(가정!$B$43-1) | C13: =C12*(1+B13) | D13: =B13/가정!$B$39 | E13: =C13*D13 | F13: =C13-E13 | G13: =1/(1+가정!$B$40)^9 | H13: =F13*G13 | I13: =MAX(0,E13-C13)
A14: 10 | B14: =가정!$B$37+(가정!$B$38-가정!$B$37)*(10-1)/(가정!$B$43-1) | C14: =C13*(1+B14) | D14: =B14/가정!$B$39 | E14: =C14*D14 | F14: =C14-E14 | G14: =1/(1+가정!$B$40)^10 | H14: =F14*G14 | I14: =MAX(0,E14-C14)
A15: 합계 | E15: =SUM(E5:E14) | F15: =SUM(F5:F14) | H15: =SUM(H5:H14) | I15: =SUM(I5:I14)
A17: 터미널 가치
A18: 11년차 NOPAT | B18: =C14*(1+가정!$B$41)
A19: 터미널 재투자율 = 영구성장률 ÷ 증분 ROIC | B19: =가정!$B$41/가정!$B$39
A20: 터미널 가치 = 11년차 FCF ÷ (할인율 − 영구성장률) | B20: =B18*(1-B19)/(가정!$B$40-가정!$B$41)
A21: 터미널 현재가치 | B21: =B20*G14
A23: 가치
A24: 예측기간 현재가치 | B24: =H15
A25: 터미널 현재가치 | B25: =B21
A26: 기업가치 (EV) | B26: =B24+B25
A27: + 순현금 | B27: =기준연도!$B$14
A28: 자기자본가치 | B28: =B26+B27
A29: 주당가치 (원) | B29: =B28*1000000000/가정!$B$7
A30: 시가총액 (십억원) | B30: =가정!$B$46/1000000000
A31: 시장가 대비 | B31: =(DCF_낙관!$B$28-B30)/B30
A32: 터미널 비중 | B32: =B21/B26
A34: 실현 가능성 점검
A35: 10년 누적 재투자 | B35: =E15
A36: 10년 누적 NOPAT | B36: =SUM(C5:C14)
A37: 재투자 ÷ NOPAT | B37: =B35/B36
A38: 1년차 재투자율 | B38: =D5
A39: 외부조달 필요액 (재투자율>100%인 해의 부족분 합계) | B39: =I15
A40: 10년 뒤 매출 (NOPAT 배율 × FY2025 매출) | B40: =C14/기준연도!$D$9*원자료!K$5
A41: 재투자율이 100%를 넘으면 그 차액은 증자나 차입으로 메워야 합니다. 이 계산은 그 희석과 이자를 기존 주주에게 청구하지 않으므로, 재투자율이 100%를 넘는 시나리오의 자기자본가치는 과대평가입니다.

Sheet 역산
A1: 기준 7 (3) — 지금 주가는 무엇을 가정하고 있는가
A2: 낙관 시나리오의 틀(증분 ROIC 26%, 할인율 9%, 영구성장률 3%, 기준연도는 현재 환율)을 고정하고 첫해 성장률만 바꿔가며 자기자본가치를 계산합니다. 시가총액과 교차하는 지점이 '시장이 이미 가정하고 있는 성장률'입니다. 단위: 십억원.
A4: 첫해 성장률 | B4: 1년차 재투자율 | C4: 자기자본가치 | D4: 주당가치 (원) | E4: 시가총액 대비 | F4: 비고
A5: 0.1 | B5: =A5/가정!$B$39 | C5: =기준연도!$D$9*(1+(A5+(가정!$B$38-A5)*(1-1)/(가정!$B$43-1)))*(1-(A5+(가정!$B$38-A5)*(1-1)/(가정!$B$43-1))/가정!$B$39)/(1+가정!$B$40)^1+기준연도!$D$9*(1+(A5+(가정!$B$38-A5)*(1-1)/(가정!$B$43-1)))*(1+(A5+(가정!$B$38-A5)*(2-1)/(가정!$B$43-1)))*(1-(A5+(가정!$B$38-A5)*(2-1)/(가정!$B$43-1))/가정!$B$39)/(1+가정!$B$40)^2+기준연도!$D$9*(1+(A5+(가정!$B$38-A5)*(1-1)/(가정!$B$43-1)))*(1+(A5+(가정!$B$38-A5)*(2-1)/(가정!$B$43-1)))*(1+(A5+(가정!$B$38-A5)*(3-1)/(가정!$B$43-1)))*(1-(A5+(가정!$B$38-A5)*(3-1)/(가정!$B$43-1))/가정!$B$39)/(1+가정!$B$40)^3+기준연도!$D$9*(1+(A5+(가정!$B$38-A5)*(1-1)/(가정!$B$43-1)))*(1+(A5+(가정!$B$38-A5)*(2-1)/(가정!$B$43-1)))*(1+(A5+(가정!$B$38-A5)*(3-1)/(가정!$B$43-1)))*(1+(A5+(가정!$B$38-A5)*(4-1)/(가정!$B$43-1)))*(1-(A5+(가정!$B$38-A5)*(4-1)/(가정!$B$43-1))/가정!$B$39)/(1+가정!$B$40)^4+기준연도!$D$9*(1+(A5+(가정!$B$38-A5)*(1-1)/(가정!$B$43-1)))*(1+(A5+(가정!$B$38-A5)*(2-1)/(가정!$B$43-1)))*(1+(A5+(가정!$B$38-A5)*(3-1)/(가정!$B$43-1)))*(1+(A5+(가정!$B$38-A5)*(4-1)/(가정!$B$43-1)))*(1+(A5+(가정!$B$38-A5)*(5-1)/(가정!$B$43-1)))*(1-(A5+(가정!$B$38-A5)*(5-1)/(가정!$B$43-1))/가정!$B$39)/(1+가정!$B$40)^5+기준연도!$D$9*(1+(A5+(가정!$B$38-A5)*(1-1)/(가정!$B$43-1)))*(1+(A5+(가정!$B$38-A5)*(2-1)/(가정!$B$43-1)))*(1+(A5+(가정!$B$38-A5)*(3-1)/(가정!$B$43-1)))*(1+(A5+(가정!$B$38-A5)*(4-1)/(가정!$B$43-1)))*(1+(A5+(가정!$B$38-A5)*(5-1)/(가정!$B$43-1)))*(1+(A5+(가정!$B$38-A5)*(6-1)/(가정!$B$43-1)))*(1-(A5+(가정!$B$38-A5)*(6-1)/(가정!$B$43-1))/가정!$B$39)/(1+가정!$B$40)^6+기준연도!$D$9*(1+(A5+(가정!$B$38-A5)*(1-1)/(가정!$B$43-1)))*(1+(A5+(가정!$B$38-A5)*(2-1)/(가정!$B$43-1)))*(1+(A5+(가정!$B$38-A5)*(3-1)/(가정!$B$43-1)))*(1+(A5+(가정!$B$38-A5)*(4-1)/(가정!$B$43-1)))*(1+(A5+(가정!$B$38-A5)*(5-1)/(가정!$B$43-1)))*(1+(A5+(가정!$B$38-A5)*(6-1)/(가정!$B$43-1)))*(1+(A5+(가정!$B$38-A5)*(7-1)/(가정!$B$43-1)))*(1-(A5+(가정!$B$38-A5)*(7-1)/(가정!$B$43-1))/가정!$B$39)/(1+가정!$B$40)^7+기준연도!$D$9*(1+(A5+(가정!$B$38-A5)*(1-1)/(가정!$B$43-1)))*(1+(A5+(가정!$B$38-A5)*(2-1)/(가정!$B$43-1)))*(1+(A5+(가정!$B$38-A5)*(3-1)/(가정!$B$43-1)))*(1+(A5+(가정!$B$38-A5)*(4-1)/(가정!$B$43-1)))*(1+(A5+(가정!$B$38-A5)*(5-1)/(가정!$B$43-1)))*(1+(A5+(가정!$B$38-A5)*(6-1)/(가정!$B$43-1)))*(1+(A5+(가정!$B$38-A5)*(7-1)/(가정!$B$43-1)))*(1+(A5+(가정!$B$38-A5)*(8-1)/(가정!$B$43-1)))*(1-(A5+(가정!$B$38-A5)*(8-1)/(가정!$B$43-1))/가정!$B$39)/(1+가정!$B$40)^8+기준연도!$D$9*(1+(A5+(가정!$B$38-A5)*(1-1)/(가정!$B$43-1)))*(1+(A5+(가정!$B$38-A5)*(2-1)/(가정!$B$43-1)))*(1+(A5+(가정!$B$38-A5)*(3-1)/(가정!$B$43-1)))*(1+(A5+(가정!$B$38-A5)*(4-1)/(가정!$B$43-1)))*(1+(A5+(가정!$B$38-A5)*(5-1)/(가정!$B$43-1)))*(1+(A5+(가정!$B$38-A5)*(6-1)/(가정!$B$43-1)))*(1+(A5+(가정!$B$38-A5)*(7-1)/(가정!$B$43-1)))*(1+(A5+(가정!$B$38-A5)*(8-1)/(가정!$B$43-1)))*(1+(A5+(가정!$B$38-A5)*(9-1)/(가정!$B$43-1)))*(1-(A5+(가정!$B$38-A5)*(9-1)/(가정!$B$43-1))/가정!$B$39)/(1+가정!$B$40)^9+기준연도!$D$9*(1+(A5+(가정!$B$38-A5)*(1-1)/(가정!$B$43-1)))*(1+(A5+(가정!$B$38-A5)*(2-1)/(가정!$B$43-1)))*(1+(A5+(가정!$B$38-A5)*(3-1)/(가정!$B$43-1)))*(1+(A5+(가정!$B$38-A5)*(4-1)/(가정!$B$43-1)))*(1+(A5+(가정!$B$38-A5)*(5-1)/(가정!$B$43-1)))*(1+(A5+(가정!$B$38-A5)*(6-1)/(가정!$B$43-1)))*(1+(A5+(가정!$B$38-A5)*(7-1)/(가정!$B$43-1)))*(1+(A5+(가정!$B$38-A5)*(8-1)/(가정!$B$43-1)))*(1+(A5+(가정!$B$38-A5)*(9-1)/(가정!$B$43-1)))*(1+(A5+(가정!$B$38-A5)*(10-1)/(가정!$B$43-1)))*(1-(A5+(가정!$B$38-A5)*(10-1)/(가정!$B$43-1))/가정!$B$39)/(1+가정!$B$40)^10+기준연도!$D$9*(1+(A5+(가정!$B$38-A5)*(1-1)/(가정!$B$43-1)))*(1+(A5+(가정!$B$38-A5)*(2-1)/(가정!$B$43-1)))*(1+(A5+(가정!$B$38-A5)*(3-1)/(가정!$B$43-1)))*(1+(A5+(가정!$B$38-A5)*(4-1)/(가정!$B$43-1)))*(1+(A5+(가정!$B$38-A5)*(5-1)/(가정!$B$43-1)))*(1+(A5+(가정!$B$38-A5)*(6-1)/(가정!$B$43-1)))*(1+(A5+(가정!$B$38-A5)*(7-1)/(가정!$B$43-1)))*(1+(A5+(가정!$B$38-A5)*(8-1)/(가정!$B$43-1)))*(1+(A5+(가정!$B$38-A5)*(9-1)/(가정!$B$43-1)))*(1+(A5+(가정!$B$38-A5)*(10-1)/(가정!$B$43-1)))*(1+가정!$B$41)*(1-가정!$B$41/가정!$B$39)/(가정!$B$40-가정!$B$41)/(1+가정!$B$40)^10+기준연도!$B$14 | D5: =C5*1000000000/가정!$B$7 | E5: =(C5-가정!$B$46/1000000000)/(가정!$B$46/1000000000) | F5: =IF(B5>1,"재투자율 100% 초과 — 외부조달 필요","자체조달 가능")
