Workbook

Sheet 가정
A1: 알파벳 (GOOG) — 주가 하락 원인과 투자기준 판정
A2: 자료 기준일 2026-10-30 · 10-Q 0001652044-26-000084 (2026-10-29 제출) · 8-K 0001652044-26-000080 (2026-10-28 제출)
A4: 바꿔 볼 수 있는 가정 (노란 칸을 고치면 전부 다시 계산됩니다)
A5: 항목 | B5: 값 | C5: 단위 | D5: 출처
A6: 자본비용 (WACC) | B6: 0.1 | C6: 비율 | D6: 프로젝트 기준. 50개사 조사와 같은 10%.
A7: 주가 | B7: 282.32001 | C7: 달러 | D7: 2026-10-29 종가. https://query1.finance.yahoo.com/v8/finance/chart/GOOG?range=6mo&interval=1d
A8: 발행주식수 | B8: 12294000000 | C8: 주 | D8: 10-Q 표지 보통주 합계 (Class A+B+C)
A9: TTM 실효세율 | B9: 0.19025028 | C9: 비율 | D9: 9개월 법인세 ÷ 9개월 세전이익. 평가이익이 섞여 있음
A10: 법정세율 (대안) | B10: 0.21 | C10: 비율 | D10: 연방 법정세율. 바꿔 보기용
A11: 노란 칸은 공시·시세에서 그대로 읽은 입력값입니다. 나머지 시트의 모든 수치는 이 칸들과 '공시원자료' 시트를 참조하는 수식이며, 값을 붙여넣은 셀은 없습니다.
A13: 결론 요약
A14: 기준 | B14: 수치 | C14: 판정 | D14: 근거
A15: ROIC (보고 기준) | B15: =ROIC!$B$10 -> 0.2913652 | C15: =IF(B15>가정!$B$6,"합격","불합격") -> 합격 | D15: 자기자본 + 차입 − 현금, 기초·기말 평균
A16: ROIC (가동자본) | B16: =ROIC!$B$12 -> 0.46470433 | C16: =IF(B16>가정!$B$6,"합격","불합격") -> 합격 | D16: 미가동 설비를 분모에서 제외
A17: 증분 ROIC (가동−지분) | B17: =ROIC!$C$21 -> 0.53189572 | C17: =IF(B17>가정!$B$6,"합격","불합격") -> 합격 | D17: FY2025 → TTM 의 ΔNOPAT ÷ Δ투하자본
A18: NOPAT 수익률 | B18: =가격!$B$11 -> 0.036622602 | C18: =IF(B18>가정!$B$6,"합격","불합격") -> 불합격 | D18: 성장이 없다고 볼 때의 수익률
A19: 주주이익 수익률 (하단) | B19: =가격!$C$19 -> 0.0056893973 | C19: =IF(B19>가정!$B$6,"합격","불합격") -> 불합격 | D19: capex 전액을 비용으로 (= 잉여현금흐름)
A20: 주주이익 수익률 (상단) | B20: =가격!$C$20 -> 0.043665483 | C20: =IF(B20>가정!$B$6,"합격","불합격") -> 불합격 | D20: 감가상각만 비용으로
A21: 요구 영구성장률 | B21: =가격!$B$26 -> 0.068799365 | C21: =IF(B21<가정!$B$6,"요구 조건","설명 불가") -> 요구 조건 | D21: 이 칸만 뜻이 반대입니다: 자본비용보다 낮아야 가격이 설명되며, 낮다는 것이 합격을 뜻하지는 않습니다
A22: 판정 열은 수식입니다 — 자본비용 칸을 8%나 12%로 바꾸면 합격·불합격이 그 자리에서 다시 계산됩니다.

Sheet 공시원자료
A1: 공시에서 읽은 원자료 — 값만 들어 있고 수식은 없습니다
A3: 손익계산서 (10-Q, 백만 달러)
A4: 항목 | B4: Q3 2026 | C4: Q3 2025 | D4: 9M 2026 | E4: 9M 2025
A5: 매출 | B5: 127577 | C5: 102346 | D5: 357269 | E5: 289007
A6: 영업이익 | B6: 40576 | C6: 31228 | D6: 121042 | E6: 93105
A7: 기타수익 (평가손익) | B7: -8221 | C7: 12759 | D7: 127478 | E7: 26604
A8: 세전이익 | D8: 248520 | E8: 119709
A9: 법인세 | D9: 47281
A10: 순이익 | B10: 26170 | C10: 34979 | D10: 201239 | E10: 97715
A11: 희석 EPS (달러) | B11: 2.12 | C11: 2.87 | D11: 16.33 | E11: 7.99
A13: FY2025 10-K (백만 달러)
A14: 항목 | B14: FY2025
A15: 영업이익 | B15: 129039
A16: 실효세율 | B16: 0.16783146
A17: 감가상각비 | B17: 21136
A19: 대차대조표 (10-Q, 백만 달러)
A20: 항목 | B20: 2026-09-30 | C20: 2025-12-31
A21: 자기자본 | B21: 677549 | C21: 415265
A22: 이자부 장기차입금 | B22: 125102 | C22: 46547
A23: 현금·단기투자 | B23: 265098 | C23: 126843
A24: 영업권 | B24: 58117 | C24: 33380
A25: 무형자산 | B25: 8817 | C25: 1283
A26: 비시장성 투자지분 | B26: 135230 | C26: 68687
A27: 미가동 설비 | B27: 145270 | C27: 78592
A28: 총자산 | B28: 1003312 | C28: 595281
A30: 현금흐름 (8-K 발표문 조정표, 백만 달러)
A31: 기간 | B31: 영업현금흐름 | C31: capex | D31: 잉여현금흐름 (수식)
A32: Q4 2025 | B32: 52402 | C32: -27851 | D32: =B32+C32 -> 24551
A33: Q1 2026 | B33: 45790 | C33: -35674 | D33: =B33+C33 -> 10116
A34: Q2 2026 | B34: 39069 | C34: -44924 | D34: =B34+C34 -> -5855
A35: Q3 2026 | B35: 42290 | C35: -51355 | D35: =B35+C35 -> -9065
A36: TTM Q3 2026 | B36: 179551 | C36: -159804 | D36: =B36+C36 -> 19747
A37: 검산: 네 분기 합 = TTM | B37: =B32+B33+B34+B35 -> 179551 | C37: =C32+C33+C34+C35 -> -159804 | D37: =IF(ROUND(B37-B36,0)=0,"일치","불일치") -> 일치
A38: 잉여현금흐름 열은 수식입니다. 회사 자신의 정의(영업현금흐름 − capex)이고, capex 는 음수로 입력돼 있으므로 더합니다. 마지막 줄은 네 분기 합이 TTM 과 맞는지 엑셀 안에서 다시 검산합니다.
A40: 재무활동 9개월 누적 (10-Q, 백만 달러)
A41: 항목 | B41: 2026 | C41: 2025
A42: 자사주 매입 | B42: 0 | C42: -39810
A43: 차입 조달 | B43: 85222 | C43: 38002
A44: 보통주 발행 (ATM) | B44: 42870 | C44: 0
A45: 우선주 발행 | B45: 19063 | C45: 0
...

Sheet ROIC
A1: 투하자본이익률 — 네 가지 분모
A3: TTM 영업이익 (= FY2025 − 9M2025 + 9M2026) | B3: =공시원자료!B15-공시원자료!E6+공시원자료!D6 -> 156976
A4: 실효세율 (가정 시트) | B4: =가정!$B$9 -> 0.19025028
A5: NOPAT = 영업이익 × (1 − 실효세율) | B5: =$B$3*(1-$B$4) -> 127111.27
A6: NOPAT (법정세율 21% 적용 시) | B6: =$B$3*(1-가정!$B$10) -> 124011.04
A8: 분모 네 가지와 ROIC
A9: 투하자본 기준 | B9: ROIC (TTM) | C9: 기초 | D9: 기말 | E9: 평균 (수식) | F9: 스프레드 (수식)
A10: 보고 기준 | B10: =$B$5/E10 -> 0.2913652 | C10: =공시원자료!C21+공시원자료!C22-공시원자료!C23 -> 334969 | D10: =공시원자료!B21+공시원자료!B22-공시원자료!B23 -> 537553 | E10: =AVERAGE(C10:D10) -> 436261 | F10: =B10-가정!$B$6 -> 0.1913652
A11: 영업 (−영업권·무형) | B11: =$B$5/E11 -> 0.329763 | C11: =공시원자료!C21+공시원자료!C22-공시원자료!C23-공시원자료!C24-공시원자료!C25 -> 300306 | D11: =공시원자료!B21+공시원자료!B22-공시원자료!B23-공시원자료!B24-공시원자료!B25 -> 470619 | E11: =AVERAGE(C11:D11) -> 385462.5 | F11: =B11-가정!$B$6 -> 0.229763
A12: 가동 (−미가동 설비) | B12: =$B$5/E12 -> 0.46470433 | C12: =공시원자료!C21+공시원자료!C22-공시원자료!C23-공시원자료!C24-공시원자료!C25-공시원자료!C27 -> 221714 | D12: =공시원자료!B21+공시원자료!B22-공시원자료!B23-공시원자료!B24-공시원자료!B25-공시원자료!B27 -> 325349 | E12: =AVERAGE(C12:D12) -> 273531.5 | F12: =B12-가정!$B$6 -> 0.36470433
A13: 가동 − 투자지분 | B13: =$B$5/E13 -> 0.74085825 | C13: =공시원자료!C21+공시원자료!C22-공시원자료!C23-공시원자료!C24-공시원자료!C25-공시원자료!C27-공시원자료!C26 -> 153027 | D13: =공시원자료!B21+공시원자료!B22-공시원자료!B23-공시원자료!B24-공시원자료!B25-공시원자료!B27-공시원자료!B26 -> 190119 | E13: =AVERAGE(C13:D13) -> 171573 | F13: =B13-가정!$B$6 -> 0.64085825
A14: 분모는 기초·기말 평균입니다(프로젝트 기준). 각 분모가 어떻게 쌓였는지는 수식 바에서 바로 보입니다: 보고 기준 = 자기자본 + 차입 − 현금 / 영업 (−영업권·무형) = 보고 − 영업권 − 무형자산 / 가동 (−미가동 설비) = 영업 − 미가동 설비 / 가동 − 투자지분 = 가동 − 비시장성 투자지분
A16: 증분 수익성 (FY2025 → TTM)
A17: 항목 | B17: 보고 기준 | C17: 가동 − 지분 기준
A18: FY2025 NOPAT | B18: =공시원자료!B15*(1-공시원자료!B16) -> 107382.2
A19: ΔNOPAT | B19: =$B$5-$B$18 -> 19729.076 | C19: =B19 -> 19729.076
A20: Δ투하자본 (기말 − 기초) | B20: =D10-C10 -> 202584 | C20: =D13-C13 -> 37092
A21: 증분 ROIC | B21: =B19/B20 -> 0.097387138 | C21: =C19/C20 -> 0.53189572
A22: FY2025 → TTM 2026-09. 보고 기준 분모에는 투자자산 평가이익이 자기자본으로 들어와 있어, 영업이익을 낼 수 없는 자본이 포함됩니다.

Sheet 가격
A1: 가격이 요구하는 것
A3: 항목 | B3: 값 | C3: 수식 / 근거
A4: 주가 | B4: =가정!$B$7 -> 282.32001 | C4: 2026-10-29 종가
A5: 발행주식수 | B5: =가정!$B$8 -> 12294000000 | C5: 10-Q 표지
A6: 시가총액 (백만 달러) | B6: =가정!$B$7*$B$5/1000000 -> 3470842.2
A7: TTM NOPAT (백만 달러) | B7: =ROIC!$B$5 -> 127111.27
A8: TTM 잉여현금흐름 (백만 달러) | B8: =공시원자료!D36 -> 19747
A9: TTM 영업현금흐름 (백만 달러) | B9: =공시원자료!B36 -> 179551
A10: TTM 감가상각비 (백만 달러) | B10: =공시원자료!B17-15096+21955 -> 27995
A11: NOPAT 수익률 | B11: =$B$7/$B$6 -> 0.036622602 | C11: TTM NOPAT ÷ 시가총액. 성장이 없다고 볼 때의 수익률
A12: 주가 ÷ NOPAT | B12: =$B$6/$B$7 -> 27.305542
A13: 주가 ÷ 잉여현금흐름 | B13: =$B$6/$B$8 -> 175.76554
A14: 10% 수익에 필요한 NOPAT | B14: =$B$6*가정!$B$6 -> 347084.22
A15: 현재 NOPAT의 몇 배 | B15: =B14/$B$7 -> 2.7305542
A17: 주주이익 밴드
A18: 기준 | B18: 금액 (백만) | C18: 함의 수익률
A19: 하단 — capex 전액을 비용으로 | B19: =$B$8 -> 19747 | C19: =B19/$B$6 -> 0.0056893973
A20: 상단 — 감가상각만 비용으로 | B20: =$B$9-$B$10 -> 151556 | C20: =B20/$B$6 -> 0.043665483
A21: 진실은 둘 사이에 있습니다. 지금 간격이 비정상적으로 넓은 것은 이미 쓴 미가동 설비가 감가상각에 아직 반영되지 않았기 때문입니다.
A23: 영구성장 모형 — 가격이 요구하는 성장률
A24: 기업가치 = NOPAT × (1 − g ÷ 증분ROIC) ÷ (WACC − g)
A25: 증분 ROIC (가동 기준 ROIC 적용) | B25: =ROIC!$B$12 -> 0.46470433
A26: 요구 영구성장률 (역산) | B26: =($B$6*가정!$B$6-$B$7)/($B$6-$B$7/$B$25) -> 0.068799365
A27: 검산: g 를 모형에 되넣으면 시가총액 | B27: =$B$7*(1-$B$26/$B$25)/(가정!$B$6-$B$26) -> 3470842.2 | C27: =IF(ROUND(B27-$B$6,0)=0,"일치","불일치") -> 일치
A28: 요구 성장률은 반복 계산이 아니라 닫힌 해입니다: g = (V·k − N) ÷ (V − N÷증분ROIC). 바로 아래 줄에서 그 g 를 모형에 되넣어 시가총액이 복원되는지 엑셀 안에서 검산합니다.
A30: 성장률 민감도 (할인율은 가정 시트 값)
A31: 영구 성장률 | B31: 기업가치 (백만) | C31: 주당 가치 | D31: 현재가 대비
A32: 0.03 | B32: =$B$7*(1-A32/$B$25)/(가정!$B$6-A32) -> 1698647.5 | C32: =B32*1000000/$B$5 -> 138.16882 | D32: =C32/가정!$B$7-1 -> -0.510595
A33: 0.04 | B33: =$B$7*(1-A33/$B$25)/(가정!$B$6-A33) -> 1936166.9 | C33: =B33*1000000/$B$5 -> 157.48876 | D33: =C33/가정!$B$7-1 -> -0.44216223
A34: 0.05 | B34: =$B$7*(1-A34/$B$25)/(가정!$B$6-A34) -> 2268693.9 | C34: =B34*1000000/$B$5 -> 184.53668 | D34: =C34/가정!$B$7-1 -> -0.34635635
A35: 0.06 | B35: =$B$7*(1-A35/$B$25)/(가정!$B$6-A35) -> 2767484.5 | C35: =B35*1000000/$B$5 -> 225.10855 | D35: =C35/가정!$B$7-1 -> -0.20264754
A36: 0.07 | B36: =$B$7*(1-A36/$B$25)/(가정!$B$6-A36) -> 3598802.2 | C36: =B36*1000000/$B$5 -> 292.72834 | D36: =C36/가정!$B$7-1 -> 0.036867149
A37: 0.08 | B37: =$B$7*(1-A37/$B$25)/(가정!$B$6-A37) -> 5261437.6 | C37: =B37*1000000/$B$5 -> 427.96792 | D37: =C37/가정!$B$7-1 -> 0.51589653
A38: 성장률 칸(노란색)을 고치면 세 열이 따라 움직입니다. 3%p 차이로 가치가 2배 넘게 벌어지는 것이 이 표의 요점입니다 — 성장률이 할인율에 가까워질수록 분모가 0 으로 가기 때문입니다. '적정주가'로 읽으면 안 됩니다.
A40: 가격별 요구 성장률 (같은 모형을 거꾸로)
A41: 주가 | B41: 시가총액 (백만) | C41: 요구 영구성장률
A42: 200 | B42: =A42*$B$5/1000000 -> 2458800 | C42: =(B42*가정!$B$6-$B$7)/(B42-$B$7/$B$25) -> 0.054349719
A43: 250 | B43: =A43*$B$5/1000000 -> 3073500 | C43: =(B43*가정!$B$6-$B$7)/(B43-$B$7/$B$25) -> 0.064371699
A44: 282.32001 | B44: =A44*$B$5/1000000 -> 3470842.2 | C44: =(B44*가정!$B$6-$B$7)/(B44-$B$7/$B$25) -> 0.068799365
A45: 300 | B45: =A45*$B$5/1000000 -> 3688200 | C45: =(B45*가정!$B$6-$B$7)/(B45-$B$7/$B$25) -> 0.070785415
...

Sheet 10년ROIC
A1: 10년 ROIC 기록 — 50개사 조사 (생성 2026-10-29)
A3: 회계연도 | B3: ROIC | C3: 영업이익 (백만) | D3: 투하자본 평균 (백만) | E3: 스프레드 (수식) | F3: 문턱 초과?
A4: FY2016 | B4: 0.35057615 | C4: 23716 | D4: 54561.5 | E4: =B4-가정!$B$6 -> 0.25057615 | F4: =IF(B4>가정!$B$6,1,0) -> 1
A5: FY2017 | B5: 0.28246592 | C5: 26178 | D5: 55606 | E5: =B5-가정!$B$6 -> 0.18246592 | F5: =IF(B5>가정!$B$6,1,0) -> 1
A6: FY2018 | B6: 0.38155484 | C6: 27524 | D6: 63506 | E6: =B6-가정!$B$6 -> 0.28155484 | F6: =IF(B6>가정!$B$6,1,0) -> 1
A7: FY2019 | B7: 0.37515751 | C7: 34231 | D7: 79081.5 | E7: =B7-가정!$B$6 -> 0.27515751 | F7: =IF(B7>가정!$B$6,1,0) -> 1
A8: FY2020 | B8: 0.37023344 | C8: 41224 | D8: 93253 | E8: =B8-가정!$B$6 -> 0.27023344 | F8: =IF(B8>가정!$B$6,1,0) -> 1
A9: FY2021 | B9: 0.57965865 | C9: 78714 | D9: 113792 | E9: =B9-가정!$B$6 -> 0.47965865 | F9: =IF(B9>가정!$B$6,1,0) -> 1
A10: FY2022 | B10: 0.44332262 | C10: 74842 | D10: 141943 | E10: =B10-가정!$B$6 -> 0.34332262 | F10: =IF(B10>가정!$B$6,1,0) -> 1
A11: FY2023 | B11: 0.42386488 | C11: 84293 | D11: 171208 | E11: =B11-가정!$B$6 -> 0.32386488 | F11: =IF(B11>가정!$B$6,1,0) -> 1
A12: FY2024 | B12: 0.437885 | C12: 112390 | D12: 214471 | E12: =B12-가정!$B$6 -> 0.337885 | F12: =IF(B12>가정!$B$6,1,0) -> 1
A13: FY2025 | B13: 0.36991734 | C13: 129039 | D13: 290287 | E13: =B13-가정!$B$6 -> 0.26991734 | F13: =IF(B13>가정!$B$6,1,0) -> 1
A14: TTM 2026-09 | B14: =ROIC!B10 -> 0.2913652 | C14: =ROIC!$B$3 -> 156976 | D14: =ROIC!E10 -> 436261 | E14: =B14-가정!$B$6 -> 0.1913652
A16: 중위 ROIC (10년) | B16: =MEDIAN(B4:B13) -> 0.37835618
A17: 최고 | B17: =MAX(B4:B13) -> 0.57965865
A18: 최저 | B18: =MIN(B4:B13) -> 0.28246592
A19: 문턱 초과 연수 | B19: =SUM(F4:F13) -> 10
A20: 고점 대비 현재 (TTM ÷ 최고) | B20: =B14/MAX(B4:B13) -> 0.50264961
A21: 영업이익 배수 (최근 ÷ 고점연도) | B21: =C13/C9 -> 1.6393399
A22: 투하자본 배수 (최근 ÷ 고점연도) | B22: =D13/D9 -> 2.5510317
A23: 마지막 두 줄이 ROIC 하락의 원인입니다. 영업이익은 늘었는데 투하자본이 더 많이 늘면 ROIC 는 떨어집니다. 고점연도는 FY2021입니다.
